Workbook
Name S_AK: Sheet2!$A$2:$A$31
Name S_AL: Sheet2!$A$32:$A$98
Name S_AR: Sheet2!$A$99:$A$173
Name S_AZ: Sheet2!$A$174:$A$188
Name S_CA: Sheet2!$A$189:$A$246
Name S_CO: Sheet2!$A$247:$A$310
Name S_CT: Sheet2!$A$311:$A$319
Name S_DC: Sheet2!$A$320:$A$320
Name S_DE: Sheet2!$A$321:$A$323
Name S_FL: Sheet2!$A$324:$A$390
Name S_GA: Sheet2!$A$391:$A$549
Name S_HI: Sheet2!$A$550:$A$554
Name S_IA: Sheet2!$A$555:$A$653
Name S_ID: Sheet2!$A$654:$A$697
Name S_IL: Sheet2!$A$698:$A$799
Name S_IN: Sheet2!$A$800:$A$891
Name S_KS: Sheet2!$A$892:$A$996
Name S_KY: Sheet2!$A$997:$A$1116
Name S_LA: Sheet2!$A$1117:$A$1180
Name S_MA: Sheet2!$A$1181:$A$1194
Name S_MD: Sheet2!$A$1195:$A$1218
Name S_ME: Sheet2!$A$1219:$A$1234
Name S_MI: Sheet2!$A$1235:$A$1317
Name S_MN: Sheet2!$A$1318:$A$1404
Name S_MO: Sheet2!$A$1405:$A$1519
Name S_MS: Sheet2!$A$1520:$A$1601
Name S_MT: Sheet2!$A$1602:$A$1657
Name S_NC: Sheet2!$A$1658:$A$1757
Name S_ND: Sheet2!$A$1758:$A$1810
Name S_NE: Sheet2!$A$1811:$A$1903
Name S_NH: Sheet2!$A$1904:$A$1913
Name S_NJ: Sheet2!$A$1914:$A$1934
Name S_NM: Sheet2!$A$1935:$A$1967
Name S_NV: Sheet2!$A$1968:$A$1984
Name S_NY: Sheet2!$A$1985:$A$2046
Name S_OH: Sheet2!$A$2047:$A$2134
Name S_OK: Sheet2!$A$2135:$A$2211
Name S_OR: Sheet2!$A$2212:$A$2247
Name S_PA: Sheet2!$A$2248:$A$2314
Name S_RI: Sheet2!$A$2315:$A$2319
Name S_SC: Sheet2!$A$2320:$A$2365
Name S_SD: Sheet2!$A$2366:$A$2431
Name S_TN: Sheet2!$A$2432:$A$2526
Name S_TX: Sheet2!$A$2527:$A$2780
Name S_UT: Sheet2!$A$2781:$A$2809
Name S_VA: Sheet2!$A$2810:$A$2942
Name S_VT: Sheet2!$A$2943:$A$2956
Name S_WA: Sheet2!$A$2957:$A$2995
Name S_WI: Sheet2!$A$2996:$A$3067
Name S_WV: Sheet2!$A$3068:$A$3122
Name S_WY: Sheet2!$A$3123:$A$3145

Sheet Member Report
A1: First Name | B1: Last Name | C1: State | D1: Contact Member # | E1: Email | F1: Contact Membership Type | G1: Gen 1: Birth Date | H1: City, County, State | I1: State | J1: County | K1: Coordinates | L1: State | M1: County | N1: Coordinates | O1: Coordinate | P1: Race | Q1: Ethnicity | R1: Military Service | S1: Branch | T1: War | U1: Gen 1: Death Date | V1: City, County, State | W1: State | X1: County | Y1: Coordinates | Z1: State | AB1: Coordinates | AD1: Coordinate | AE1: Documentation | AF1: Gen 1: Marriage Date | AG1: City, County, State | AH1: State | AI1: County | AJ1: Coordinates | AK1: Coordinate | AL1: Gen 1: Spouse First Name | AM1: Gen 1: Spouse Surname/Maiden Name | AN1: Spouse Gen 1: Birth Date | AO1: City, County, State | AP1: State | AQ1: County | AR1: Coordinates | AS1: Race | AT1: Ethnicity | AU1: Coordinate | AV1: Spouse Gen 1: Death Date | AW1: City, County, State | AX1: State | AY1: County | AZ1: Coordinates | BA1: Coordinate | BB1: Race | BC1: Ethnicity | BD1: Gen 2: Father's: First Name | BE1: Gen 2: Father's Surname | BF1: Gen 2: Father's Birth Date | BG1: City, County, State | BH1: State | BI1: County | BJ1: Coordinates | BK1: Coordinate | BL1: Race | BM1: Ethnicity | BO1: Military Service | BP1: Branch | BQ1: War | BR1: Gen 2: Father's Death Date | BS1: City, County, State | BT1: State | BU1: County | BV1: Coordinates | BW1: Coordinate | BX1: Gen 2: Father, Mother's Marriage Date | BY1: City, County, State | BZ1: State | CA1: County | CB1: Coordinates | CC1: Coordinate | CD1: Gen 2: Mother's First Name | CE1: Gen 2: Mother's Surname/Maiden Name | CF1: Gen 2: Mother's Birth Date | CG1: City, County, State | CH1: State | CI1: County | CJ1: Coordinates | CK1: Coordinate | CL1: Gen 2: Mother's Death Date | CM1: City, County, State | CN1: State | CO1: County | CP1: Coordinates | CQ1: Coordinate | CR1: Race | CS1: Documentation | CT1: Gen 3 Father: First Name | CU1: Gen 3: Father Surname | CV1: Gen 3: Father's Birth Date | CW1: City, County, State | CX1: State | CY1: County | CZ1: Coordinates | DA1: Coordinate | DB1: Race | DC1: Ethnicity | DD1: Military Service | DE1: Branch | DF1: War | DG1: Gen 3: Father's Death Date | DH1: City, County, State | DI1: State | DJ1: County | DK1: Coordinates | DL1: Coordinate | DM1: Gen 3: Father, Mother's Marriage Date | DN1: City, County, State | DO1: State | DP1: County | DQ1: Coordinates | DR1: Coordinate | DS1: Race | DT1: Ethnicity | DU1: Military Service | DV1: Branch | DW1: War | DX1: Gen 3: Mother's First Name | DY1: Gen 3: Mother's Surname/Maiden Name | DZ1: Alias Name | EA1: Gen 3: Mother's Birth Date | EB1: City, County, State | EC1: State | ED1: County | EE1: Coordinates | EF1: Gen 3: Mother's Death Date | EG1: City, County, State | EH1: State | EI1: County | EJ1: Coordinates | EK1: Coordinate | EL1: Race | EM1: Ethnicity | EN1: Documentation | EO1: Gen 4 Father: First Name | EP1: Gen 4: Father Surname | EQ1: Gen 4: Father's Birth Date | ER1: City, County, State | ES1: State | ET1: County | EU1: Coordinates | EV1: Coordinate | EW1: Race | EX1: Ethnicity | EY1: Military Service | EZ1: Branch | FA1: War | FB1: Gen 4: Father's Death Date | FC1: City, County, State | FD1: State | FE1: County | FF1: Coordinates | FG1: Coordinate | FH1: Gen 4: Father, Mother's Marriage Date | FI1: City, County, State | FJ1: State | FK1: County | FL1: Coordinates | FM1: Coordinate | FN1: Gen 4: Mother's First Name | FO1: Gen 4: Mother's Surname/Maiden Name | FP1: Gen 4: Mother's Birth Date | FQ1: City, County, State | FR1: State | FS1: County | FT1: Coordinates | FU1: Coordinate | FV1: Gen 4: Mother's Death Date | FW1: City, County, State | FX1: State | FY1: County | FZ1: Coordinates | GA1: Coordinate | GB1: Race | GC1: Ethnicity | GD1: Documentation | GE1: Gen 5 Father: First Name | GF1: Gen 5: Father Surname | GG1: Gen 5: Father's Birth Date | GH1: City, County, State | GI1: State | GJ1: County | GK1: Coordinates | GL1: Coordinate | GM1: Race | GN1: Ethnicity | GO1: Military Service | GP1: Branch | GQ1: War | GR1: Gen 5: Father's Death Date | GS1: City, County, State | GT1: State | GU1: County | GV1: Coordinates | GW1: Coordinate | GX1: Gen 5: Father, Mother's Marriage Date | GY1: City, County, State | GZ1: State | HA1: County | HB1: Coordinates | HC1: Coordinate | HD1: Gen 5: Mother's First Name | HE1: Gen 5: Mother's Surname/Maiden Name | HF1: Alias Name | HG1: Gen 5: Mother's Birth Date | HH1: City, County, State | HI1: State | HJ1: County | HK1: Coordinates | HL1: Coordinate | HM1: Gen 5: Mother's Death Date | HN1: City, County, State | HO1: State | HP1: County | HQ1: Coordinates | HR1: Coordinate | HS1: Race | HT1: Ethnicity | HU1: Documentation | HV1: Gen 6 Father: First Name | HW1: Gen 6: Father Surname | HX1: Alias Name | HY1: Gen 6: Father's Birth Date | HZ1: City, County, State | IA1: State | IB1: County | IC1: Coordinates | ID1: Coordinate | IE1: Race | IF1: Ethnicity | IG1: Gen 6: Father's Death Date | IH1: City, County, State | II1: State | IJ1: County | IK1: Coordinates | IL1: Coordinate | IM1: Gen 6: Father, Mother's Marriage Date | IN1: City, County, State | IO1: State | IP1: County | IQ1: Coordinates | IR1: Coordinate | IS1: Gen 6: Mother's First Name | IT1: Gen 6: Mother's Surname/Maiden Name | IU1: Alias Name | IV1: Gen 6: Mother's Birth Date | IW1: City, County, State | IX1: State | IY1: County | IZ1: Coordinates | JA1: Coordinate | JB1: Gen 6: Mother's Death Date | JC1: City, County, State | JD1: State | JE1: County | JF1: Coordinates | JG1: Coordinate | JH1: Race | JI1: Ethnicty | JJ1: Documentation | JK1: Gen 7 Father: First Name | JL1: Gen 7: Father Surname | JM1: Alias Name | JN1: Gen 7: Father's Birth Date | JO1: City, County, State | JP1: State | JQ1: County | JR1: Coordinates | JS1: Coordinate | JT1: Race | JU1: Ethnicity | JV1: Gen 7: Father's Death Date | JW1: City, County, State | JX1: State | JY1: County | JZ1: Coordinates | KA1: Coordinate | KB1: Race | KC1: Ethnicity | KD1: Gen 7: Father, Mother's Marriage Date | KE1: City, County, State | KF1: State | KG1: County | KH1: Coordinates | KI1: Coordinate | KJ1: Gen 7: Mother's First Name | KK1: Gen 7: Mother's Surname/Maiden Name | KL1: Alias Name | KM1: Gen 7: Mother's Birth Date | KN1: City, County, State | KO1: State | KP1: County | KQ1: Coordinates | KR1: Coordinate | KS1: Gen 7: Mother's Death Date | KT1: City, County, State | KU1: State | KV1: County | KW1: Coordinates | KX1: Coordinate | KY1: Documentation | KZ1: Gen 8 Father: First Name | LA1: Gen 8: Father Surname | LB1: Alias Name | LC1: Gen 8: Father's Birth Date | LD1: City, County, State | LE1: State | LF1: County | LG1: Coordinates | LH1: Coordinate | LI1: Race | LJ1: Ethnicity | LK1: Military Service | LL1: Branch | LM1: War | LN1: Gen 8: Father's Death Date | LO1: City, County, State | LP1: State | LQ1: County | LR1: Coordinates | LS1: Coordinate | LT1: Gen 8: Father, Mother's Marriage Date | LU1: City, County, State | LV1: State | LW1: County | LX1: Coordinates | LY1: Coordinate | LZ1: Gen 8: Mother's First Name | MA1: Gen 8: Mother's Surname/Maiden Name | MB1: Alias Name | MC1: Gen 8: Mother's Birth Date | MD1: City, County, State | ME1: State | MF1: County | MG1: Coordinates | MH1: Coordinate | MI1: Gen 8: Mother's Death Date | MJ1: City, County, State | MK1: State | ML1: County | MM1: Coordinates | MN1: Coordinate | MO1: Documentation | MP1: Gen 9 Father: First Name | MQ1: Gen 9: Father Surname | MR1: Alias Name | MS1: Gen 9: Father's Birth Date | MT1: City, County, State | MU1: State | MV1: County | MW1: Coordinates | MX1: Coordinate | MY1: Race | MZ1: Ethnicity | NA1: Military Service | NB1: Branch | NC1: War | ND1: Gen 9: Father's Death Date | NE1: City, County, State | NF1: State | NG1: County | NH1: Coordinates | NI1: Coordinate | NJ1: Gen 9: Father, Mother's Marriage Date | NK1: City, County, State | NL1: State | NM1: County | NN1: Coordinates | NO1: Coordinate | NP1: Gen 9: Mother's First Name | NQ1: Gen 9: Mother's Surname/Maiden Name | NR1: Alias Name | NS1: Gen 9: Mother's Birth Date | NT1: City, County, State | NU1: State | NV1: County | NW1: Coordinates | NX1: Coordinate | NY1: Gen 9: Mother's Death Date | NZ1: City, County, State | OA1: State | OB1: County | OC1: Coordinates | OD1: Coordinate | OE1: Documentation | OF1: Gen 10 Father: First Name | OG1: Gen 10: Father Surname | OH1: Alias Name | OI1: Gen 10: Father's Birth Date | OJ1: City, County, State | OK1: State | OL1: County | OM1: Coordinates | ON1: Coordinate | OO1: Race | OP1: Ethnicity | OQ1: Military Service | OR1: Branch | OS1: War | OT1: Gen 10: Father's Death Date | OU1: City, County, State | OV1: State | OW1: County | OX1: Coordinates | OY1: Coordinate | OZ1: Gen 10: Father, Mother's Marriage Date | PA1: City, County, State | PB1: State | PC1: County | PD1: Coordinates | PE1: Coordinate | PF1: Gen 10: Mother's First Name | PG1: Gen 10: Mother's Surname/Maiden Name | PH1: Alias Name | PI1: Gen 10: Mother's Birth Date | PJ1: City, County, State | PK1: State | PL1: County | PM1: Coordinates | PN1: Coordinate | PO1: Gen 10: Mother's Death Date | PP1: City, County, State | PQ1: State | PR1: County | PS1: Coordinates | PT1: Coordinate | PU1: Documentation
A2: Ric | B2: Murphy | C2: VA | D2: 100001 | E2: ricmurphy1@aol.com | F2: Founding Member | G2: 22479 | H2: Boston, Suffolk, MA | K2: =IFERROR(VLOOKUP(I2&"-"&J2, Sheet2!$E:$F, 2, FALSE), "") | L2: AR | M2: Norfolk | N2: =IFERROR(VLOOKUP(L2&"-"&M2, Sheet2!$E:$F, 2, FALSE), "") | O2: 42_21_37_N_71_3_28_W | P2: Black | Q2: Afrrican American | R2: No | T2: - | Y2: =IFERROR(VLOOKUP(W2&"-"&X2, Sheet2!$E:$F, 2, FALSE), "") | Z2: MA | AA2: Norfolk | AB2: =IFERROR(VLOOKUP(Z2&"-"&X2, Sheet2!$E:$F, 2, FALSE), "") | AJ2: =IFERROR(VLOOKUP(AH2&"-"&AI2, Sheet2!$E:$F, 2, FALSE), "") | AR2: =IFERROR(VLOOKUP(AP2&"-"&AQ2, Sheet2!$E:$F, 2, FALSE), "") | AZ2: =IFERROR(VLOOKUP(AX2&"-"&AY2, Sheet2!$E:$F, 2, FALSE), "") | BB2: Record Copy NSSAR #165111, Add ACN 51405 and Record Copy NSDAR # 672791, Add. Vol. 1043 | BC2: Robert | BD2: Murphy | BE2: 9951 | BF2: Boston, Suffolk, MA | BG2: 42_21_37_N_71_3_28_W | BJ2: =IFERROR(VLOOKUP(BH2&"-"&BI2, Sheet2!$E:$F, 2, FALSE), "") | BN2: No | BP2: - | BQ2: 3, 3, 1966 | BR2: Milton, Norfolk, MA | BS2: 42°15′00″N 71°04′00″W | BV2: =IFERROR(VLOOKUP(BT2&"-"&BU2, Sheet2!$E:$F, 2, FALSE), "") | BW2: 18635 | BX2: Brockton, Plymouth, MA | BY2: 42°05′00″N 71°01′08″W | CB2: =IFERROR(VLOOKUP(BZ2&"-"&CA2, Sheet2!$E:$F, 2, FALSE), "") | CC2: Joan | CD2: Cornwall | CE2: 3, 3, 1929 | CF2: Brockton, Plymouth, MA | CG2: 42°05′00″N 71°01′08″W | CJ2: =IFERROR(VLOOKUP(CH2&"-"&CI2, Sheet2!$E:$F, 2, FALSE), "") | CP2: =IFERROR(VLOOKUP(CN2&"-"&CO2, Sheet2!$E:$F, 2, FALSE), "") | CR2: Record Copy NSSAR #165111, Add ACN 51405 and Record Copy NSDAR # 672791, Add. Vol. 1043 | CS2: Harold | CT2: Cornwall | CU2: 1, 1, 1901 | CV2: Brockton, Plymouth, MA | CZ2: =IFERROR(VLOOKUP(CX2&"-"&CY2, Sheet2!$E:$F, 2, FALSE), "") | DC2: No | DE2: - | DF2: 11, 8, 1991 | DG2: Brockton, Plymouth, MA | DH2: 42°05′00″N 71°01′08″W | DK2: =IFERROR(VLOOKUP(DI2&"-"&DJ2, Sheet2!$E:$F, 2, FALSE), "") | DL2: 7, 11, 1924 | DM2: Brockton, Plymouth, MA | DN2: 42°05′00″N 71°01′08″W | DQ2: =IFERROR(VLOOKUP(DO2&"-"&DP2, Sheet2!$E:$F, 2, FALSE), "") | DT2: No | DV2: - | DW2: Marie | DX2: Howell | DZ2: 2577 | EA2: Brockton, Plymouth, MA | EB2: 3, 1, 2022 | EE2: =IFERROR(VLOOKUP(EC2&"-"&ED2, Sheet2!$E:$F, 2, FALSE), "") | EF2: Brockton, Plymouth, MA | EG2: 42°05′00″N 71°01′08″W | EJ2: =IFERROR(VLOOKUP(EH2&"-"&EI2, Sheet2!$E:$F, 2, FALSE), "") | EM2: Record Copy NSSAR #165111, Add ACN 51405 and Record Copy NSDAR # 672791, Add. Vol. 1043 | EN2: Benjamin | EO2: CORNWALL | EP2: 06 Oct 1869 | EQ2: Boston, Suffolk, MA | ER2: 42_21_37_N_71_3_28_W | EU2: =IFERROR(VLOOKUP(ES2&"-"&ET2, Sheet2!$E:$F, 2, FALSE), "") | EX2: No | EZ2: - | FA2: 6680 | FB2: Brockton, Plymouth, MA | FC2: 42°05′00″N 71°01′08″W | FF2: =IFERROR(VLOOKUP(FD2&"-"&FE2, Sheet2!$E:$F, 2, FALSE), "") | FG2: 2, 18, 1901 | FH2: Brockton, Plymouth, MA | FI2: 42°05′00″N 71°01′08″W | FL2: =IFERROR(VLOOKUP(FJ2&"-"&FK2, Sheet2!$E:$F, 2, FALSE), "") | FM2: Grace | FN2: Jackson | FO2: 25 Mar 1877 | FP2: Huntington, Suffolk, NY | FQ2: 40°51′36″N 73°21′8″W | FT2: =IFERROR(VLOOKUP(FR2&"-"&FS2, Sheet2!$E:$F, 2, FALSE), "") | FU2: 2, 24, 1946 | FV2: Brockton, Plymouth, MA | FW2: 42°05′00″N 71°01′08″W | FZ2: =IFERROR(VLOOKUP(FX2&"-"&FY2, Sheet2!$E:$F, 2, FALSE), "") | GC2: Record Copy NSSAR #165111, Add ACN 51405 and Record Copy NSDAR # 672791, Add. Vol. 1043 | GD2: William | GE2: Cornwall | GF2: 12 Nov 1844 | GG2: Brockton, Plymouth, MA | GH2: 42°05′00″N 71°01′08″W | GK2: =IFERROR(VLOOKUP(GI2&"-"&GJ2, Sheet2!$E:$F, 2, FALSE), "") | GN2: No | GP2: - | GQ2: 8, 21, 1926 | GR2: Bridgewater, Plymouth, MA | GS2: 41_59_25_N_70_58_32_W | GV2: =IFERROR(VLOOKUP(GT2&"-"&GU2, Sheet2!$E:$F, 2, FALSE), "") | GW2: 22 Nov 1866 | GX2: Taunton, Bristol, MA | HB2: =IFERROR(VLOOKUP(GZ2&"-"&HA2, Sheet2!$E:$F, 2, FALSE), "") | HC2: Martha | HD2: Hill | HF2: ---- 1842 | HG2: Cambridge, Middlesex, MA | HK2: =IFERROR(VLOOKUP(HI2&"-"&HJ2, Sheet2!$E:$F, 2, FALSE), "") | HL2: 2823 | HM2: Bridgewater, Plymouth, MA | HN2: 41_59_25_N_70_58_32_W | HQ2: =IFERROR(VLOOKUP(HO2&"-"&HP2, Sheet2!$E:$F, 2, FALSE), "") | HT2: Record Copy NSSAR #165111, Add ACN 51405 and Record Copy NSDAR # 672791, Add. Vol. 1043 | HU2: Flushing | HV2: Cornwall | HX2: 25 Dec 1801 | HY2: St. Johns Parish, News Bruniswick, Canada | IC2: =IFERROR(VLOOKUP(IA2&"-"&IB2, Sheet2!$E:$F, 2, FALSE), "") | IF2: 19 Aug 1888 | IG2: Bridgewater, Plymouth, MA | IH2: 41_59_25_N_70_58_32_W | IK2: =IFERROR(VLOOKUP(II2&"-"&IJ2, Sheet2!$E:$F, 2, FALSE), "") | IL2: 10 May 1817 | IM2: Bridgewater, Plymouth, MA | IN2: 41_59_25_N_70_58_32_W | IQ2: =IFERROR(VLOOKUP(IO2&"-"&IP2, Sheet2!$E:$F, 2, FALSE), "") | IR2: Harriet | IS2: BROOKER | IU2: 586 | IV2: Bridgewater, Plymouth, MA | IW2: 41_59_25_N_70_58_32_W | IZ2: =IFERROR(VLOOKUP(IX2&"-"&IY2, Sheet2!$E:$F, 2, FALSE), "") | JA2: 19 Apr 1840 | JB2: Brockton, Plymouth, MA | JF2: =IFERROR(VLOOKUP(JD2&"-"&JE2, Sheet2!$E:$F, 2, FALSE), "") | JI2: Record Copy NSSAR #165111, Add ACN 51405 and Record Copy NSDAR # 672791, Add. Vol. 1043 | JJ2: Samuel Stanley | JK2: Brooker | JL2: Bruker | JM2: 12 May 1795 | JN2: Bridgewater, Plymouth, MA | JR2: =IFERROR(VLOOKUP(JP2&"-"&JQ2, Sheet2!$E:$F, 2, FALSE), "") | JU2: 26 Feb 1838 | JV2: Boston, Suffolk, MA | JW2: 42_21_37_N_71_3_28_W | JZ2: =IFERROR(VLOOKUP(JX2&"-"&JY2, Sheet2!$E:$F, 2, FALSE), "") | KA2: Black | KB2: African American | KC2: 18 Oct 1818 | KD2: Boston, Suffolk, MA | KE2: 42_21_37_N_71_3_28_W | KH2: =IFERROR(VLOOKUP(KF2&"-"&KG2, Sheet2!$E:$F, 2, FALSE), "") | KI2: Philinda | KJ2: Russell | KK2: Lender | KL2: 21 Jan 1799 | KM2: Beverly, Essex, MA | KQ2: =IFERROR(VLOOKUP(KO2&"-"&KP2, Sheet2!$E:$F, 2, FALSE), "") | KR2: 23 Apr 1848 | KS2: Tauton, Bristol, MA | KW2: =IFERROR(VLOOKUP(KU2&"-"&KV2, Sheet2!$E:$F, 2, FALSE), "") | KX2: Record Copy NSSAR #165111, Add ACN 51405 and Record Copy NSDAR # 672791, Add. Vol. 1043 | KY2: Caesar | KZ2: Russell | LB2: 1756 | LG2: =IFERROR(VLOOKUP(LE2&"-"&LF2, Sheet2!$E:$F, 2, FALSE), "") | LJ2: No | LL2: - | LM2: 20 Oct 1861 | LN2: Tauton, Bristol, MA | LR2: =IFERROR(VLOOKUP(LP2&"-"&LQ2, Sheet2!$E:$F, 2, FALSE), "") | LX2: =IFERROR(VLOOKUP(LV2&"-"&LW2, Sheet2!$E:$F, 2, FALSE), "") | LY2: Sally | LZ2: Richardson | MG2: =IFERROR(VLOOKUP(ME2&"-"&MF2, Sheet2!$E:$F, 2, FALSE), "") | MM2: =IFERROR(VLOOKUP(MK2&"-"&ML2, Sheet2!$E:$F, 2, FALSE), "") | MN2: Record Copy NSSAR #165111, Add ACN 51405 and Record Copy NSDAR # 672791, Add. Vol. 1043 | MW2: =IFERROR(VLOOKUP(MU2&"-"&MV2, Sheet2!$E:$F, 2, FALSE), "") | MZ2: No | NB2: - | NH2: =IFERROR(VLOOKUP(NF2&"-"&NG2, Sheet2!$E:$F, 2, FALSE), "") | NN2: =IFERROR(VLOOKUP(NL2&"-"&NM2, Sheet2!$E:$F, 2, FALSE), "") | NW2: =IFERROR(VLOOKUP(NU2&"-"&NV2, Sheet2!$E:$F, 2, FALSE), "") | OC2: =IFERROR(VLOOKUP(OA2&"-"&OB2, Sheet2!$E:$F, 2, FALSE), "") | OD2: Record Copy NSSAR #165111, Add ACN 51405 and Record Copy NSDAR # 672791, Add. Vol. 1043 | OM2: =IFERROR(VLOOKUP(OK2&"-"&OL2, Sheet2!$E:$F, 2, FALSE), "") | OP2: No | OR2: - | OX2: =IFERROR(VLOOKUP(OV2&"-"&OW2, Sheet2!$E:$F, 2, FALSE), "") | PD2: =IFERROR(VLOOKUP(PB2&"-"&PC2, Sheet2!$E:$F, 2, FALSE), "") | PM2: =IFERROR(VLOOKUP(PK2&"-"&PL2, Sheet2!$E:$F, 2, FALSE), "") | PS2: =IFERROR(VLOOKUP(PQ2&"-"&PR2, Sheet2!$E:$F, 2, FALSE), "") | PT2: Record Copy NSSAR #165111, Add ACN 51405 and Record Copy NSDAR # 672791, Add. Vol. 1043
A3: Douglas | B3: Cornwall | C3: CA | D3: 100002 | E3: dcornwall@outlook.com | F3: Founding Member | K3: =IFERROR(VLOOKUP(I3&"-"&J3, Sheet2!$E:$F, 2, FALSE), "") | L3: CA | M3: Norfolk | N3: =IFERROR(VLOOKUP(L3&"-"&M3, Sheet2!$E:$F, 2, FALSE), "") | R3: No | T3: - | Y3: =IFERROR(VLOOKUP(W3&"-"&X3, Sheet2!$E:$F, 2, FALSE), "") | Z3: MA | AA3: Norfolk | AB3: =IFERROR(VLOOKUP(Z3&"-"&X3, Sheet2!$E:$F, 2, FALSE), "") | AC3: Norfolk | AJ3: =IFERROR(VLOOKUP(AH3&"-"&AI3, Sheet2!$E:$F, 2, FALSE), "") | AR3: =IFERROR(VLOOKUP(AP3&"-"&AQ3, Sheet2!$E:$F, 2, FALSE), "") | AZ3: =IFERROR(VLOOKUP(AX3&"-"&AY3, Sheet2!$E:$F, 2, FALSE), "") | BJ3: =IFERROR(VLOOKUP(BH3&"-"&BI3, Sheet2!$E:$F, 2, FALSE), "") | BN3: No | BP3: - | BV3: =IFERROR(VLOOKUP(BT3&"-"&BU3, Sheet2!$E:$F, 2, FALSE), "") | CB3: =IFERROR(VLOOKUP(BZ3&"-"&CA3, Sheet2!$E:$F, 2, FALSE), "") | CJ3: =IFERROR(VLOOKUP(CH3&"-"&CI3, Sheet2!$E:$F, 2, FALSE), "") | CP3: =IFERROR(VLOOKUP(CN3&"-"&CO3, Sheet2!$E:$F, 2, FALSE), "") | CZ3: =IFERROR(VLOOKUP(CX3&"-"&CY3, Sheet2!$E:$F, 2, FALSE), "") | DC3: No | DE3: - | DK3: =IFERROR(VLOOKUP(DI3&"-"&DJ3, Sheet2!$E:$F, 2, FALSE), "") | DQ3: =IFERROR(VLOOKUP(DO3&"-"&DP3, Sheet2!$E:$F, 2, FALSE), "") | DT3: No | DV3: - | EE3: =IFERROR(VLOOKUP(EC3&"-"&ED3, Sheet2!$E:$F, 2, FALSE), "") | EJ3: =IFERROR(VLOOKUP(EH3&"-"&EI3, Sheet2!$E:$F, 2, FALSE), "") | EU3: =IFERROR(VLOOKUP(ES3&"-"&ET3, Sheet2!$E:$F, 2, FALSE), "") | EX3: No | EZ3: - | FF3: =IFERROR(VLOOKUP(FD3&"-"&FE3, Sheet2!$E:$F, 2, FALSE), "") | FL3: =IFERROR(VLOOKUP(FJ3&"-"&FK3, Sheet2!$E:$F, 2, FALSE), "") | FT3: =IFERROR(VLOOKUP(FR3&"-"&FS3, Sheet2!$E:$F, 2, FALSE), "") | FZ3: =IFERROR(VLOOKUP(FX3&"-"&FY3, Sheet2!$E:$F, 2, FALSE), "") | GK3: =IFERROR(VLOOKUP(GI3&"-"&GJ3, Sheet2!$E:$F, 2, FALSE), "") | GN3: No | GP3: - | GV3: =IFERROR(VLOOKUP(GT3&"-"&GU3, Sheet2!$E:$F, 2, FALSE), "") | HB3: =IFERROR(VLOOKUP(GZ3&"-"&HA3, Sheet2!$E:$F, 2, FALSE), "") | HK3: =IFERROR(VLOOKUP(HI3&"-"&HJ3, Sheet2!$E:$F, 2, FALSE), "") | HQ3: =IFERROR(VLOOKUP(HO3&"-"&HP3, Sheet2!$E:$F, 2, FALSE), "") | IC3: =IFERROR(VLOOKUP(IA3&"-"&IB3, Sheet2!$E:$F, 2, FALSE), "") | IK3: =IFERROR(VLOOKUP(II3&"-"&IJ3, Sheet2!$E:$F, 2, FALSE), "") | IQ3: =IFERROR(VLOOKUP(IO3&"-"&IP3, Sheet2!$E:$F, 2, FALSE), "") | IZ3: =IFERROR(VLOOKUP(IX3&"-"&IY3, Sheet2!$E:$F, 2, FALSE), "") | JF3: =IFERROR(VLOOKUP(JD3&"-"&JE3, Sheet2!$E:$F, 2, FALSE), "") | JR3: =IFERROR(VLOOKUP(JP3&"-"&JQ3, Sheet2!$E:$F, 2, FALSE), "") | JZ3: =IFERROR(VLOOKUP(JX3&"-"&JY3, Sheet2!$E:$F, 2, FALSE), "") | KH3: =IFERROR(VLOOKUP(KF3&"-"&KG3, Sheet2!$E:$F, 2, FALSE), "") | KQ3: =IFERROR(VLOOKUP(KO3&"-"&KP3, Sheet2!$E:$F, 2, FALSE), "") | KW3: =IFERROR(VLOOKUP(KU3&"-"&KV3, Sheet2!$E:$F, 2, FALSE), "") | LG3: =IFERROR(VLOOKUP(LE3&"-"&LF3, Sheet2!$E:$F, 2, FALSE), "") | LJ3: No | LL3: - | LR3: =IFERROR(VLOOKUP(LP3&"-"&LQ3, Sheet2!$E:$F, 2, FALSE), "") | LX3: =IFERROR(VLOOKUP(LV3&"-"&LW3, Sheet2!$E:$F, 2, FALSE), "") | MG3: =IFERROR(VLOOKUP(ME3&"-"&MF3, Sheet2!$E:$F, 2, FALSE), "") | MM3: =IFERROR(VLOOKUP(MK3&"-"&ML3, Sheet2!$E:$F, 2, FALSE), "") | MW3: =IFERROR(VLOOKUP(MU3&"-"&MV3, Sheet2!$E:$F, 2, FALSE), "") | MZ3: No | NB3: - | NH3: =IFERROR(VLOOKUP(NF3&"-"&NG3, Sheet2!$E:$F, 2, FALSE), "") | NN3: =IFERROR(VLOOKUP(NL3&"-"&NM3, Sheet2!$E:$F, 2, FALSE), "") | NW3: =IFERROR(VLOOKUP(NU3&"-"&NV3, Sheet2!$E:$F, 2, FALSE), "") | OC3: =IFERROR(VLOOKUP(OA3&"-"&OB3, Sheet2!$E:$F, 2, FALSE), "") | OM3: =IFERROR(VLOOKUP(OK3&"-"&OL3, Sheet2!$E:$F, 2, FALSE), "") | OP3: No | OR3: - | OX3: =IFERROR(VLOOKUP(OV3&"-"&OW3, Sheet2!$E:$F, 2, FALSE), "") | PD3: =IFERROR(VLOOKUP(PB3&"-"&PC3, Sheet2!$E:$F, 2, FALSE), "") | PM3: =IFERROR(VLOOKUP(PK3&"-"&PL3, Sheet2!$E:$F, 2, FALSE), "") | PS3: =IFERROR(VLOOKUP(PQ3&"-"&PR3, Sheet2!$E:$F, 2, FALSE), "")
A4: Shelley | B4: Murphy | C4: VA | D4: 100003 | E4: shelleyviola@gmail.com | F4: Founding Member | K4: =IFERROR(VLOOKUP(I4&"-"&J4, Sheet2!$E:$F, 2, FALSE), "") | L4: AZ | M4: Norfolk | N4: =IFERROR(VLOOKUP(L4&"-"&M4, Sheet2!$E:$F, 2, FALSE), "") | R4: No | T4: - | Y4: =IFERROR(VLOOKUP(W4&"-"&X4, Sheet2!$E:$F, 2, FALSE), "") | Z4: MA | AA4: Suffolk | AB4: =IFERROR(VLOOKUP(Z4&"-"&X4, Sheet2!$E:$F, 2, FALSE), "") | AJ4: =IFERROR(VLOOKUP(AH4&"-"&AI4, Sheet2!$E:$F, 2, FALSE), "") | AR4: =IFERROR(VLOOKUP(AP4&"-"&AQ4, Sheet2!$E:$F, 2, FALSE), "") | AZ4: =IFERROR(VLOOKUP(AX4&"-"&AY4, Sheet2!$E:$F, 2, FALSE), "") | BJ4: =IFERROR(VLOOKUP(BH4&"-"&BI4, Sheet2!$E:$F, 2, FALSE), "") | BN4: No | BP4: - | BV4: =IFERROR(VLOOKUP(BT4&"-"&BU4, Sheet2!$E:$F, 2, FALSE), "") | CB4: =IFERROR(VLOOKUP(BZ4&"-"&CA4, Sheet2!$E:$F, 2, FALSE), "") | CJ4: =IFERROR(VLOOKUP(CH4&"-"&CI4, Sheet2!$E:$F, 2, FALSE), "") | CP4: =IFERROR(VLOOKUP(CN4&"-"&CO4, Sheet2!$E:$F, 2, FALSE), "") | CZ4: =IFERROR(VLOOKUP(CX4&"-"&CY4, Sheet2!$E:$F, 2, FALSE), "") | DC4: No | DE4: - | DK4: =IFERROR(VLOOKUP(DI4&"-"&DJ4, Sheet2!$E:$F, 2, FALSE), "") | DQ4: =IFERROR(VLOOKUP(DO4&"-"&DP4, Sheet2!$E:$F, 2, FALSE), "") | DT4: No | DV4: - | EE4: =IFERROR(VLOOKUP(EC4&"-"&ED4, Sheet2!$E:$F, 2, FALSE), "") | EJ4: =IFERROR(VLOOKUP(EH4&"-"&EI4, Sheet2!$E:$F, 2, FALSE), "") | EU4: =IFERROR(VLOOKUP(ES4&"-"&ET4, Sheet2!$E:$F, 2, FALSE), "") | EX4: No | EZ4: - | FF4: =IFERROR(VLOOKUP(FD4&"-"&FE4, Sheet2!$E:$F, 2, FALSE), "") | FL4: =IFERROR(VLOOKUP(FJ4&"-"&FK4, Sheet2!$E:$F, 2, FALSE), "") | FT4: =IFERROR(VLOOKUP(FR4&"-"&FS4, Sheet2!$E:$F, 2, FALSE), "") | FZ4: =IFERROR(VLOOKUP(FX4&"-"&FY4, Sheet2!$E:$F, 2, FALSE), "") | GK4: =IFERROR(VLOOKUP(GI4&"-"&GJ4, Sheet2!$E:$F, 2, FALSE), "") | GN4: No | GP4: - | GV4: =IFERROR(VLOOKUP(GT4&"-"&GU4, Sheet2!$E:$F, 2, FALSE), "") | HB4: =IFERROR(VLOOKUP(GZ4&"-"&HA4, Sheet2!$E:$F, 2, FALSE), "") | HK4: =IFERROR(VLOOKUP(HI4&"-"&HJ4, Sheet2!$E:$F, 2, FALSE), "") | HQ4: =IFERROR(VLOOKUP(HO4&"-"&HP4, Sheet2!$E:$F, 2, FALSE), "") | IC4: =IFERROR(VLOOKUP(IA4&"-"&IB4, Sheet2!$E:$F, 2, FALSE), "") | IK4: =IFERROR(VLOOKUP(II4&"-"&IJ4, Sheet2!$E:$F, 2, FALSE), "") | IQ4: =IFERROR(VLOOKUP(IO4&"-"&IP4, Sheet2!$E:$F, 2, FALSE), "") | IZ4: =IFERROR(VLOOKUP(IX4&"-"&IY4, Sheet2!$E:$F, 2, FALSE), "") | JF4: =IFERROR(VLOOKUP(JD4&"-"&JE4, Sheet2!$E:$F, 2, FALSE), "") | JR4: =IFERROR(VLOOKUP(JP4&"-"&JQ4, Sheet2!$E:$F, 2, FALSE), "") | JZ4: =IFERROR(VLOOKUP(JX4&"-"&JY4, Sheet2!$E:$F, 2, FALSE), "") | KH4: =IFERROR(VLOOKUP(KF4&"-"&KG4, Sheet2!$E:$F, 2, FALSE), "") | KQ4: =IFERROR(VLOOKUP(KO4&"-"&KP4, Sheet2!$E:$F, 2, FALSE), "") | KW4: =IFERROR(VLOOKUP(KU4&"-"&KV4, Sheet2!$E:$F, 2, FALSE), "") | LG4: =IFERROR(VLOOKUP(LE4&"-"&LF4, Sheet2!$E:$F, 2, FALSE), "") | LJ4: No | LL4: - | LR4: =IFERROR(VLOOKUP(LP4&"-"&LQ4, Sheet2!$E:$F, 2, FALSE), "") | LX4: =IFERROR(VLOOKUP(LV4&"-"&LW4, Sheet2!$E:$F, 2, FALSE), "") | MG4: =IFERROR(VLOOKUP(ME4&"-"&MF4, Sheet2!$E:$F, 2, FALSE), "") | MM4: =IFERROR(VLOOKUP(MK4&"-"&ML4, Sheet2!$E:$F, 2, FALSE), "") | MW4: =IFERROR(VLOOKUP(MU4&"-"&MV4, Sheet2!$E:$F, 2, FALSE), "") | MZ4: No | NB4: - | NH4: =IFERROR(VLOOKUP(NF4&"-"&NG4, Sheet2!$E:$F, 2, FALSE), "") | NN4: =IFERROR(VLOOKUP(NL4&"-"&NM4, Sheet2!$E:$F, 2, FALSE), "") | NW4: =IFERROR(VLOOKUP(NU4&"-"&NV4, Sheet2!$E:$F, 2, FALSE), "") | OC4: =IFERROR(VLOOKUP(OA4&"-"&OB4, Sheet2!$E:$F, 2, FALSE), "") | OM4: =IFERROR(VLOOKUP(OK4&"-"&OL4, Sheet2!$E:$F, 2, FALSE), "") | OP4: No | OR4: - | OX4: =IFERROR(VLOOKUP(OV4&"-"&OW4, Sheet2!$E:$F, 2, FALSE), "") | PD4: =IFERROR(VLOOKUP(PB4&"-"&PC4, Sheet2!$E:$F, 2, FALSE), "") | PM4: =IFERROR(VLOOKUP(PK4&"-"&PL4, Sheet2!$E:$F, 2, FALSE), "") | PS4: =IFERROR(VLOOKUP(PQ4&"-"&PR4, Sheet2!$E:$F, 2, FALSE), "")
A5: Joyce | B5: Mosley | C5: PA | D5: 100005 | E5: joycemos355@gmail.com | F5: Founding Member | K5: =IFERROR(VLOOKUP(I5&"-"&J5, Sheet2!$E:$F, 2, FALSE), "") | L5: IL | M5: Norfolk | N5: =IFERROR(VLOOKUP(L5&"-"&M5, Sheet2!$E:$F, 2, FALSE), "") | R5: No | T5: - | Y5: =IFERROR(VLOOKUP(W5&"-"&X5, Sheet2!$E:$F, 2, FALSE), "") | Z5: MA | AB5: =IFERROR(VLOOKUP(Z5&"-"&X5, Sheet2!$E:$F, 2, FALSE), "") | AJ5: =IFERROR(VLOOKUP(AH5&"-"&AI5, Sheet2!$E:$F, 2, FALSE), "") | AR5: =IFERROR(VLOOKUP(AP5&"-"&AQ5, Sheet2!$E:$F, 2, FALSE), "") | AZ5: =IFERROR(VLOOKUP(AX5&"-"&AY5, Sheet2!$E:$F, 2, FALSE), "") | BJ5: =IFERROR(VLOOKUP(BH5&"-"&BI5, Sheet2!$E:$F, 2, FALSE), "") | BN5: No | BP5: - | BV5: =IFERROR(VLOOKUP(BT5&"-"&BU5, Sheet2!$E:$F, 2, FALSE), "") | CB5: =IFERROR(VLOOKUP(BZ5&"-"&CA5, Sheet2!$E:$F, 2, FALSE), "") | CJ5: =IFERROR(VLOOKUP(CH5&"-"&CI5, Sheet2!$E:$F, 2, FALSE), "") | CP5: =IFERROR(VLOOKUP(CN5&"-"&CO5, Sheet2!$E:$F, 2, FALSE), "") | CZ5: =IFERROR(VLOOKUP(CX5&"-"&CY5, Sheet2!$E:$F, 2, FALSE), "") | DC5: No | DE5: - | DK5: =IFERROR(VLOOKUP(DI5&"-"&DJ5, Sheet2!$E:$F, 2, FALSE), "") | DQ5: =IFERROR(VLOOKUP(DO5&"-"&DP5, Sheet2!$E:$F, 2, FALSE), "") | DT5: No | DV5: - | EE5: =IFERROR(VLOOKUP(EC5&"-"&ED5, Sheet2!$E:$F, 2, FALSE), "") | EJ5: =IFERROR(VLOOKUP(EH5&"-"&EI5, Sheet2!$E:$F, 2, FALSE), "") | EU5: =IFERROR(VLOOKUP(ES5&"-"&ET5, Sheet2!$E:$F, 2, FALSE), "") | EX5: No | EZ5: - | FF5: =IFERROR(VLOOKUP(FD5&"-"&FE5, Sheet2!$E:$F, 2, FALSE), "") | FL5: =IFERROR(VLOOKUP(FJ5&"-"&FK5, Sheet2!$E:$F, 2, FALSE), "") | FT5: =IFERROR(VLOOKUP(FR5&"-"&FS5, Sheet2!$E:$F, 2, FALSE), "") | FZ5: =IFERROR(VLOOKUP(FX5&"-"&FY5, Sheet2!$E:$F, 2, FALSE), "") | GK5: =IFERROR(VLOOKUP(GI5&"-"&GJ5, Sheet2!$E:$F, 2, FALSE), "") | GN5: No | GP5: - | GV5: =IFERROR(VLOOKUP(GT5&"-"&GU5, Sheet2!$E:$F, 2, FALSE), "") | HB5: =IFERROR(VLOOKUP(GZ5&"-"&HA5, Sheet2!$E:$F, 2, FALSE), "") | HK5: =IFERROR(VLOOKUP(HI5&"-"&HJ5, Sheet2!$E:$F, 2, FALSE), "") | HQ5: =IFERROR(VLOOKUP(HO5&"-"&HP5, Sheet2!$E:$F, 2, FALSE), "") | IC5: =IFERROR(VLOOKUP(IA5&"-"&IB5, Sheet2!$E:$F, 2, FALSE), "") | IK5: =IFERROR(VLOOKUP(II5&"-"&IJ5, Sheet2!$E:$F, 2, FALSE), "") | IQ5: =IFERROR(VLOOKUP(IO5&"-"&IP5, Sheet2!$E:$F, 2, FALSE), "") | IZ5: =IFERROR(VLOOKUP(IX5&"-"&IY5, Sheet2!$E:$F, 2, FALSE), "") | JF5: =IFERROR(VLOOKUP(JD5&"-"&JE5, Sheet2!$E:$F, 2, FALSE), "") | JR5: =IFERROR(VLOOKUP(JP5&"-"&JQ5, Sheet2!$E:$F, 2, FALSE), "") | JZ5: =IFERROR(VLOOKUP(JX5&"-"&JY5, Sheet2!$E:$F, 2, FALSE), "") | KH5: =IFERROR(VLOOKUP(KF5&"-"&KG5, Sheet2!$E:$F, 2, FALSE), "") | KQ5: =IFERROR(VLOOKUP(KO5&"-"&KP5, Sheet2!$E:$F, 2, FALSE), "") | KW5: =IFERROR(VLOOKUP(KU5&"-"&KV5, Sheet2!$E:$F, 2, FALSE), "") | LG5: =IFERROR(VLOOKUP(LE5&"-"&LF5, Sheet2!$E:$F, 2, FALSE), "") | LJ5: No | LL5: - | LR5: =IFERROR(VLOOKUP(LP5&"-"&LQ5, Sheet2!$E:$F, 2, FALSE), "") | LX5: =IFERROR(VLOOKUP(LV5&"-"&LW5, Sheet2!$E:$F, 2, FALSE), "") | MG5: =IFERROR(VLOOKUP(ME5&"-"&MF5, Sheet2!$E:$F, 2, FALSE), "") | MM5: =IFERROR(VLOOKUP(MK5&"-"&ML5, Sheet2!$E:$F, 2, FALSE), "") | MW5: =IFERROR(VLOOKUP(MU5&"-"&MV5, Sheet2!$E:$F, 2, FALSE), "") | MZ5: No | NB5: - | NH5: =IFERROR(VLOOKUP(NF5&"-"&NG5, Sheet2!$E:$F, 2, FALSE), "") | NN5: =IFERROR(VLOOKUP(NL5&"-"&NM5, Sheet2!$E:$F, 2, FALSE), "") | NW5: =IFERROR(VLOOKUP(NU5&"-"&NV5, Sheet2!$E:$F, 2, FALSE), "") | OC5: =IFERROR(VLOOKUP(OA5&"-"&OB5, Sheet2!$E:$F, 2, FALSE), "") | OM5: =IFERROR(VLOOKUP(OK5&"-"&OL5, Sheet2!$E:$F, 2, FALSE), "") | OP5: No | OR5: - | OX5: =IFERROR(VLOOKUP(OV5&"-"&OW5, Sheet2!$E:$F, 2, FALSE), "") | PD5: =IFERROR(VLOOKUP(PB5&"-"&PC5, Sheet2!$E:$F, 2, FALSE), "") | PM5: =IFERROR(VLOOKUP(PK5&"-"&PL5, Sheet2!$E:$F, 2, FALSE), "") | PS5: =IFERROR(VLOOKUP(PQ5&"-"&PR5, Sheet2!$E:$F, 2, FALSE), "")
A6: Dean | B6: Henry | C6: PA | D6: 100006 | E6: deanhenry@comcast.net | F6: Founding Member | K6: =IFERROR(VLOOKUP(I6&"-"&J6, Sheet2!$E:$F, 2, FALSE), "") | L6: IL | M6: Norfolk | N6: =IFERROR(VLOOKUP(L6&"-"&M6, Sheet2!$E:$F, 2, FALSE), "") | R6: No | T6: - | Y6: =IFERROR(VLOOKUP(W6&"-"&X6, Sheet2!$E:$F, 2, FALSE), "") | Z6: MA | AB6: =IFERROR(VLOOKUP(Z6&"-"&X6, Sheet2!$E:$F, 2, FALSE), "") | AJ6: =IFERROR(VLOOKUP(AH6&"-"&AI6, Sheet2!$E:$F, 2, FALSE), "") | AR6: =IFERROR(VLOOKUP(AP6&"-"&AQ6, Sheet2!$E:$F, 2, FALSE), "") | AZ6: =IFERROR(VLOOKUP(AX6&"-"&AY6, Sheet2!$E:$F, 2, FALSE), "") | BJ6: =IFERROR(VLOOKUP(BH6&"-"&BI6, Sheet2!$E:$F, 2, FALSE), "") | BN6: No | BP6: - | BV6: =IFERROR(VLOOKUP(BT6&"-"&BU6, Sheet2!$E:$F, 2, FALSE), "") | CB6: =IFERROR(VLOOKUP(BZ6&"-"&CA6, Sheet2!$E:$F, 2, FALSE), "") | CJ6: =IFERROR(VLOOKUP(CH6&"-"&CI6, Sheet2!$E:$F, 2, FALSE), "") | CP6: =IFERROR(VLOOKUP(CN6&"-"&CO6, Sheet2!$E:$F, 2, FALSE), "") | CZ6: =IFERROR(VLOOKUP(CX6&"-"&CY6, Sheet2!$E:$F, 2, FALSE), "") | DC6: No | DE6: - | DK6: =IFERROR(VLOOKUP(DI6&"-"&DJ6, Sheet2!$E:$F, 2, FALSE), "") | DQ6: =IFERROR(VLOOKUP(DO6&"-"&DP6, Sheet2!$E:$F, 2, FALSE), "") | DT6: No | DV6: - | EE6: =IFERROR(VLOOKUP(EC6&"-"&ED6, Sheet2!$E:$F, 2, FALSE), "") | EJ6: =IFERROR(VLOOKUP(EH6&"-"&EI6, Sheet2!$E:$F, 2, FALSE), "") | EU6: =IFERROR(VLOOKUP(ES6&"-"&ET6, Sheet2!$E:$F, 2, FALSE), "") | EX6: No | EZ6: - | FF6: =IFERROR(VLOOKUP(FD6&"-"&FE6, Sheet2!$E:$F, 2, FALSE), "") | FL6: =IFERROR(VLOOKUP(FJ6&"-"&FK6, Sheet2!$E:$F, 2, FALSE), "") | FT6: =IFERROR(VLOOKUP(FR6&"-"&FS6, Sheet2!$E:$F, 2, FALSE), "") | FZ6: =IFERROR(VLOOKUP(FX6&"-"&FY6, Sheet2!$E:$F, 2, FALSE), "") | GK6: =IFERROR(VLOOKUP(GI6&"-"&GJ6, Sheet2!$E:$F, 2, FALSE), "") | GN6: No | GP6: - | GV6: =IFERROR(VLOOKUP(GT6&"-"&GU6, Sheet2!$E:$F, 2, FALSE), "") | HB6: =IFERROR(VLOOKUP(GZ6&"-"&HA6, Sheet2!$E:$F, 2, FALSE), "") | HK6: =IFERROR(VLOOKUP(HI6&"-"&HJ6, Sheet2!$E:$F, 2, FALSE), "") | HQ6: =IFERROR(VLOOKUP(HO6&"-"&HP6, Sheet2!$E:$F, 2, FALSE), "") | IC6: =IFERROR(VLOOKUP(IA6&"-"&IB6, Sheet2!$E:$F, 2, FALSE), "") | IK6: =IFERROR(VLOOKUP(II6&"-"&IJ6, Sheet2!$E:$F, 2, FALSE), "") | IQ6: =IFERROR(VLOOKUP(IO6&"-"&IP6, Sheet2!$E:$F, 2, FALSE), "") | IZ6: =IFERROR(VLOOKUP(IX6&"-"&IY6, Sheet2!$E:$F, 2, FALSE), "") | JF6: =IFERROR(VLOOKUP(JD6&"-"&JE6, Sheet2!$E:$F, 2, FALSE), "") | JR6: =IFERROR(VLOOKUP(JP6&"-"&JQ6, Sheet2!$E:$F, 2, FALSE), "") | JZ6: =IFERROR(VLOOKUP(JX6&"-"&JY6, Sheet2!$E:$F, 2, FALSE), "") | KH6: =IFERROR(VLOOKUP(KF6&"-"&KG6, Sheet2!$E:$F, 2, FALSE), "") | KQ6: =IFERROR(VLOOKUP(KO6&"-"&KP6, Sheet2!$E:$F, 2, FALSE), "") | KW6: =IFERROR(VLOOKUP(KU6&"-"&KV6, Sheet2!$E:$F, 2, FALSE), "") | LG6: =IFERROR(VLOOKUP(LE6&"-"&LF6, Sheet2!$E:$F, 2, FALSE), "") | LJ6: No | LL6: - | LR6: =IFERROR(VLOOKUP(LP6&"-"&LQ6, Sheet2!$E:$F, 2, FALSE), "") | LX6: =IFERROR(VLOOKUP(LV6&"-"&LW6, Sheet2!$E:$F, 2, FALSE), "") | MG6: =IFERROR(VLOOKUP(ME6&"-"&MF6, Sheet2!$E:$F, 2, FALSE), "") | MM6: =IFERROR(VLOOKUP(MK6&"-"&ML6, Sheet2!$E:$F, 2, FALSE), "") | MW6: =IFERROR(VLOOKUP(MU6&"-"&MV6, Sheet2!$E:$F, 2, FALSE), "") | MZ6: No | NB6: - | NH6: =IFERROR(VLOOKUP(NF6&"-"&NG6, Sheet2!$E:$F, 2, FALSE), "") | NN6: =IFERROR(VLOOKUP(NL6&"-"&NM6, Sheet2!$E:$F, 2, FALSE), "") | NW6: =IFERROR(VLOOKUP(NU6&"-"&NV6, Sheet2!$E:$F, 2, FALSE), "") | OC6: =IFERROR(VLOOKUP(OA6&"-"&OB6, Sheet2!$E:$F, 2, FALSE), "") | OM6: =IFERROR(VLOOKUP(OK6&"-"&OL6, Sheet2!$E:$F, 2, FALSE), "") | OP6: No | OR6: - | OX6: =IFERROR(VLOOKUP(OV6&"-"&OW6, Sheet2!$E:$F, 2, FALSE), "") | PD6: =IFERROR(VLOOKUP(PB6&"-"&PC6, Sheet2!$E:$F, 2, FALSE), "") | PM6: =IFERROR(VLOOKUP(PK6&"-"&PL6, Sheet2!$E:$F, 2, FALSE), "") | PS6: =IFERROR(VLOOKUP(PQ6&"-"&PR6, Sheet2!$E:$F, 2, FALSE), "")
A7: Cynthia | B7: Goins-Hoelscher | C7: TX | D7: 100007 | E7: Cynditha@hotmail.com | F7: Founding Member | K7: =IFERROR(VLOOKUP(I7&"-"&J7, Sheet2!$E:$F, 2, FALSE), "") | L7: IL | M7: Norfolk | N7: =IFERROR(VLOOKUP(L7&"-"&M7, Sheet2!$E:$F, 2, FALSE), "") | R7: No | Y7: =IFERROR(VLOOKUP(W7&"-"&X7, Sheet2!$E:$F, 2, FALSE), "") | Z7: MA | AB7: =IFERROR(VLOOKUP(Z7&"-"&X7, Sheet2!$E:$F, 2, FALSE), "") | AJ7: =IFERROR(VLOOKUP(AH7&"-"&AI7, Sheet2!$E:$F, 2, FALSE), "") | AR7: =IFERROR(VLOOKUP(AP7&"-"&AQ7, Sheet2!$E:$F, 2, FALSE), "") | AZ7: =IFERROR(VLOOKUP(AX7&"-"&AY7, Sheet2!$E:$F, 2, FALSE), "") | BJ7: =IFERROR(VLOOKUP(BH7&"-"&BI7, Sheet2!$E:$F, 2, FALSE), "") | BN7: No | BV7: =IFERROR(VLOOKUP(BT7&"-"&BU7, Sheet2!$E:$F, 2, FALSE), "") | CB7: =IFERROR(VLOOKUP(BZ7&"-"&CA7, Sheet2!$E:$F, 2, FALSE), "") | CJ7: =IFERROR(VLOOKUP(CH7&"-"&CI7, Sheet2!$E:$F, 2, FALSE), "") | CP7: =IFERROR(VLOOKUP(CN7&"-"&CO7, Sheet2!$E:$F, 2, FALSE), "") | CZ7: =IFERROR(VLOOKUP(CX7&"-"&CY7, Sheet2!$E:$F, 2, FALSE), "") | DC7: No | DK7: =IFERROR(VLOOKUP(DI7&"-"&DJ7, Sheet2!$E:$F, 2, FALSE), "") | DQ7: =IFERROR(VLOOKUP(DO7&"-"&DP7, Sheet2!$E:$F, 2, FALSE), "") | DT7: No | EE7: =IFERROR(VLOOKUP(EC7&"-"&ED7, Sheet2!$E:$F, 2, FALSE), "") | EJ7: =IFERROR(VLOOKUP(EH7&"-"&EI7, Sheet2!$E:$F, 2, FALSE), "") | EU7: =IFERROR(VLOOKUP(ES7&"-"&ET7, Sheet2!$E:$F, 2, FALSE), "") | EX7: No | FF7: =IFERROR(VLOOKUP(FD7&"-"&FE7, Sheet2!$E:$F, 2, FALSE), "") | FL7: =IFERROR(VLOOKUP(FJ7&"-"&FK7, Sheet2!$E:$F, 2, FALSE), "") | FT7: =IFERROR(VLOOKUP(FR7&"-"&FS7, Sheet2!$E:$F, 2, FALSE), "") | FZ7: =IFERROR(VLOOKUP(FX7&"-"&FY7, Sheet2!$E:$F, 2, FALSE), "") | GK7: =IFERROR(VLOOKUP(GI7&"-"&GJ7, Sheet2!$E:$F, 2, FALSE), "") | GN7: No | GV7: =IFERROR(VLOOKUP(GT7&"-"&GU7, Sheet2!$E:$F, 2, FALSE), "") | HB7: =IFERROR(VLOOKUP(GZ7&"-"&HA7, Sheet2!$E:$F, 2, FALSE), "") | HK7: =IFERROR(VLOOKUP(HI7&"-"&HJ7, Sheet2!$E:$F, 2, FALSE), "") | HQ7: =IFERROR(VLOOKUP(HO7&"-"&HP7, Sheet2!$E:$F, 2, FALSE), "") | IC7: =IFERROR(VLOOKUP(IA7&"-"&IB7, Sheet2!$E:$F, 2, FALSE), "") | IK7: =IFERROR(VLOOKUP(II7&"-"&IJ7, Sheet2!$E:$F, 2, FALSE), "") | IQ7: =IFERROR(VLOOKUP(IO7&"-"&IP7, Sheet2!$E:$F, 2, FALSE), "") | IZ7: =IFERROR(VLOOKUP(IX7&"-"&IY7, Sheet2!$E:$F, 2, FALSE), "") | JF7: =IFERROR(VLOOKUP(JD7&"-"&JE7, Sheet2!$E:$F, 2, FALSE), "") | JR7: =IFERROR(VLOOKUP(JP7&"-"&JQ7, Sheet2!$E:$F, 2, FALSE), "") | JZ7: =IFERROR(VLOOKUP(JX7&"-"&JY7, Sheet2!$E:$F, 2, FALSE), "") | KH7: =IFERROR(VLOOKUP(KF7&"-"&KG7, Sheet2!$E:$F, 2, FALSE), "") | KQ7: =IFERROR(VLOOKUP(KO7&"-"&KP7, Sheet2!$E:$F, 2, FALSE), "") | KW7: =IFERROR(VLOOKUP(KU7&"-"&KV7, Sheet2!$E:$F, 2, FALSE), "") | LG7: =IFERROR(VLOOKUP(LE7&"-"&LF7, Sheet2!$E:$F, 2, FALSE), "") | LJ7: No | LR7: =IFERROR(VLOOKUP(LP7&"-"&LQ7, Sheet2!$E:$F, 2, FALSE), "") | LX7: =IFERROR(VLOOKUP(LV7&"-"&LW7, Sheet2!$E:$F, 2, FALSE), "") | MG7: =IFERROR(VLOOKUP(ME7&"-"&MF7, Sheet2!$E:$F, 2, FALSE), "") | MM7: =IFERROR(VLOOKUP(MK7&"-"&ML7, Sheet2!$E:$F, 2, FALSE), "") | MW7: =IFERROR(VLOOKUP(MU7&"-"&MV7, Sheet2!$E:$F, 2, FALSE), "") | MZ7: No | NH7: =IFERROR(VLOOKUP(NF7&"-"&NG7, Sheet2!$E:$F, 2, FALSE), "") | NN7: =IFERROR(VLOOKUP(NL7&"-"&NM7, Sheet2!$E:$F, 2, FALSE), "") | NW7: =IFERROR(VLOOKUP(NU7&"-"&NV7, Sheet2!$E:$F, 2, FALSE), "") | OC7: =IFERROR(VLOOKUP(OA7&"-"&OB7, Sheet2!$E:$F, 2, FALSE), "") | OM7: =IFERROR(VLOOKUP(OK7&"-"&OL7, Sheet2!$E:$F, 2, FALSE), "") | OP7: No | OX7: =IFERROR(VLOOKUP(OV7&"-"&OW7, Sheet2!$E:$F, 2, FALSE), "") | PD7: =IFERROR(VLOOKUP(PB7&"-"&PC7, Sheet2!$E:$F, 2, FALSE), "") | PM7: =IFERROR(VLOOKUP(PK7&"-"&PL7, Sheet2!$E:$F, 2, FALSE), "") | PS7: =IFERROR(VLOOKUP(PQ7&"-"&PR7, Sheet2!$E:$F, 2, FALSE), "")
A8: Andre | B8: Kearns | C8: DC | D8: 100008 | E8: andrekearnsdc@gmail.com | F8: Founding Member | K8: =IFERROR(VLOOKUP(I8&"-"&J8, Sheet2!$E:$F, 2, FALSE), "") | L8: IL | M8: Norfolk | N8: =IFERROR(VLOOKUP(L8&"-"&M8, Sheet2!$E:$F, 2, FALSE), "") | R8: No | Y8: =IFERROR(VLOOKUP(W8&"-"&X8, Sheet2!$E:$F, 2, FALSE), "") | Z8: MA | AB8: =IFERROR(VLOOKUP(Z8&"-"&X8, Sheet2!$E:$F, 2, FALSE), "") | AJ8: =IFERROR(VLOOKUP(AH8&"-"&AI8, Sheet2!$E:$F, 2, FALSE), "") | AR8: =IFERROR(VLOOKUP(AP8&"-"&AQ8, Sheet2!$E:$F, 2, FALSE), "") | AZ8: =IFERROR(VLOOKUP(AX8&"-"&AY8, Sheet2!$E:$F, 2, FALSE), "") | BJ8: =IFERROR(VLOOKUP(BH8&"-"&BI8, Sheet2!$E:$F, 2, FALSE), "") | BN8: No | BV8: =IFERROR(VLOOKUP(BT8&"-"&BU8, Sheet2!$E:$F, 2, FALSE), "") | CB8: =IFERROR(VLOOKUP(BZ8&"-"&CA8, Sheet2!$E:$F, 2, FALSE), "") | CJ8: =IFERROR(VLOOKUP(CH8&"-"&CI8, Sheet2!$E:$F, 2, FALSE), "") | CP8: =IFERROR(VLOOKUP(CN8&"-"&CO8, Sheet2!$E:$F, 2, FALSE), "") | CZ8: =IFERROR(VLOOKUP(CX8&"-"&CY8, Sheet2!$E:$F, 2, FALSE), "") | DC8: No | DK8: =IFERROR(VLOOKUP(DI8&"-"&DJ8, Sheet2!$E:$F, 2, FALSE), "") | DQ8: =IFERROR(VLOOKUP(DO8&"-"&DP8, Sheet2!$E:$F, 2, FALSE), "") | DT8: No | EE8: =IFERROR(VLOOKUP(EC8&"-"&ED8, Sheet2!$E:$F, 2, FALSE), "") | EJ8: =IFERROR(VLOOKUP(EH8&"-"&EI8, Sheet2!$E:$F, 2, FALSE), "") | EU8: =IFERROR(VLOOKUP(ES8&"-"&ET8, Sheet2!$E:$F, 2, FALSE), "") | EX8: No | FF8: =IFERROR(VLOOKUP(FD8&"-"&FE8, Sheet2!$E:$F, 2, FALSE), "") | FL8: =IFERROR(VLOOKUP(FJ8&"-"&FK8, Sheet2!$E:$F, 2, FALSE), "") | FT8: =IFERROR(VLOOKUP(FR8&"-"&FS8, Sheet2!$E:$F, 2, FALSE), "") | FZ8: =IFERROR(VLOOKUP(FX8&"-"&FY8, Sheet2!$E:$F, 2, FALSE), "") | GK8: =IFERROR(VLOOKUP(GI8&"-"&GJ8, Sheet2!$E:$F, 2, FALSE), "") | GN8: No | GV8: =IFERROR(VLOOKUP(GT8&"-"&GU8, Sheet2!$E:$F, 2, FALSE), "") | HB8: =IFERROR(VLOOKUP(GZ8&"-"&HA8, Sheet2!$E:$F, 2, FALSE), "") | HK8: =IFERROR(VLOOKUP(HI8&"-"&HJ8, Sheet2!$E:$F, 2, FALSE), "") | HQ8: =IFERROR(VLOOKUP(HO8&"-"&HP8, Sheet2!$E:$F, 2, FALSE), "") | IC8: =IFERROR(VLOOKUP(IA8&"-"&IB8, Sheet2!$E:$F, 2, FALSE), "") | IK8: =IFERROR(VLOOKUP(II8&"-"&IJ8, Sheet2!$E:$F, 2, FALSE), "") | IQ8: =IFERROR(VLOOKUP(IO8&"-"&IP8, Sheet2!$E:$F, 2, FALSE), "") | IZ8: =IFERROR(VLOOKUP(IX8&"-"&IY8, Sheet2!$E:$F, 2, FALSE), "") | JF8: =IFERROR(VLOOKUP(JD8&"-"&JE8, Sheet2!$E:$F, 2, FALSE), "") | JR8: =IFERROR(VLOOKUP(JP8&"-"&JQ8, Sheet2!$E:$F, 2, FALSE), "") | JZ8: =IFERROR(VLOOKUP(JX8&"-"&JY8, Sheet2!$E:$F, 2, FALSE), "") | KH8: =IFERROR(VLOOKUP(KF8&"-"&KG8, Sheet2!$E:$F, 2, FALSE), "") | KQ8: =IFERROR(VLOOKUP(KO8&"-"&KP8, Sheet2!$E:$F, 2, FALSE), "") | KW8: =IFERROR(VLOOKUP(KU8&"-"&KV8, Sheet2!$E:$F, 2, FALSE), "") | LG8: =IFERROR(VLOOKUP(LE8&"-"&LF8, Sheet2!$E:$F, 2, FALSE), "") | LJ8: No | LR8: =IFERROR(VLOOKUP(LP8&"-"&LQ8, Sheet2!$E:$F, 2, FALSE), "") | LX8: =IFERROR(VLOOKUP(LV8&"-"&LW8, Sheet2!$E:$F, 2, FALSE), "") | MG8: =IFERROR(VLOOKUP(ME8&"-"&MF8, Sheet2!$E:$F, 2, FALSE), "") | MM8: =IFERROR(VLOOKUP(MK8&"-"&ML8, Sheet2!$E:$F, 2, FALSE), "") | MW8: =IFERROR(VLOOKUP(MU8&"-"&MV8, Sheet2!$E:$F, 2, FALSE), "") | MZ8: No | NH8: =IFERROR(VLOOKUP(NF8&"-"&NG8, Sheet2!$E:$F, 2, FALSE), "") | NN8: =IFERROR(VLOOKUP(NL8&"-"&NM8, Sheet2!$E:$F, 2, FALSE), "") | NW8: =IFERROR(VLOOKUP(NU8&"-"&NV8, Sheet2!$E:$F, 2, FALSE), "") | OC8: =IFERROR(VLOOKUP(OA8&"-"&OB8, Sheet2!$E:$F, 2, FALSE), "") | OM8: =IFERROR(VLOOKUP(OK8&"-"&OL8, Sheet2!$E:$F, 2, FALSE), "") | OP8: No | OX8: =IFERROR(VLOOKUP(OV8&"-"&OW8, Sheet2!$E:$F, 2, FALSE), "") | PD8: =IFERROR(VLOOKUP(PB8&"-"&PC8, Sheet2!$E:$F, 2, FALSE), "") | PM8: =IFERROR(VLOOKUP(PK8&"-"&PL8, Sheet2!$E:$F, 2, FALSE), "") | PS8: =IFERROR(VLOOKUP(PQ8&"-"&PR8, Sheet2!$E:$F, 2, FALSE), "")
A9: Stephani | B9: Miller | C9: FL | D9: 100009 | E9: dsmillertime84@aol.com | F9: Founding Member | K9: =IFERROR(VLOOKUP(I9&"-"&J9, Sheet2!$E:$F, 2, FALSE), "") | L9: IL | M9: Norfolk | N9: =IFERROR(VLOOKUP(L9&"-"&M9, Sheet2!$E:$F, 2, FALSE), "") | R9: No | Y9: =IFERROR(VLOOKUP(W9&"-"&X9, Sheet2!$E:$F, 2, FALSE), "") | Z9: MA | AB9: =IFERROR(VLOOKUP(Z9&"-"&X9, Sheet2!$E:$F, 2, FALSE), "") | AJ9: =IFERROR(VLOOKUP(AH9&"-"&AI9, Sheet2!$E:$F, 2, FALSE), "") | AR9: =IFERROR(VLOOKUP(AP9&"-"&AQ9, Sheet2!$E:$F, 2, FALSE), "") | AZ9: =IFERROR(VLOOKUP(AX9&"-"&AY9, Sheet2!$E:$F, 2, FALSE), "") | BJ9: =IFERROR(VLOOKUP(BH9&"-"&BI9, Sheet2!$E:$F, 2, FALSE), "") | BN9: No | BV9: =IFERROR(VLOOKUP(BT9&"-"&BU9, Sheet2!$E:$F, 2, FALSE), "") | CB9: =IFERROR(VLOOKUP(BZ9&"-"&CA9, Sheet2!$E:$F, 2, FALSE), "") | CJ9: =IFERROR(VLOOKUP(CH9&"-"&CI9, Sheet2!$E:$F, 2, FALSE), "") | CP9: =IFERROR(VLOOKUP(CN9&"-"&CO9, Sheet2!$E:$F, 2, FALSE), "") | CZ9: =IFERROR(VLOOKUP(CX9&"-"&CY9, Sheet2!$E:$F, 2, FALSE), "") | DC9: No | DK9: =IFERROR(VLOOKUP(DI9&"-"&DJ9, Sheet2!$E:$F, 2, FALSE), "") | DQ9: =IFERROR(VLOOKUP(DO9&"-"&DP9, Sheet2!$E:$F, 2, FALSE), "") | DT9: No | EE9: =IFERROR(VLOOKUP(EC9&"-"&ED9, Sheet2!$E:$F, 2, FALSE), "") | EJ9: =IFERROR(VLOOKUP(EH9&"-"&EI9, Sheet2!$E:$F, 2, FALSE), "") | EU9: =IFERROR(VLOOKUP(ES9&"-"&ET9, Sheet2!$E:$F, 2, FALSE), "") | EX9: No | FF9: =IFERROR(VLOOKUP(FD9&"-"&FE9, Sheet2!$E:$F, 2, FALSE), "") | FL9: =IFERROR(VLOOKUP(FJ9&"-"&FK9, Sheet2!$E:$F, 2, FALSE), "") | FT9: =IFERROR(VLOOKUP(FR9&"-"&FS9, Sheet2!$E:$F, 2, FALSE), "") | FZ9: =IFERROR(VLOOKUP(FX9&"-"&FY9, Sheet2!$E:$F, 2, FALSE), "") | GK9: =IFERROR(VLOOKUP(GI9&"-"&GJ9, Sheet2!$E:$F, 2, FALSE), "") | GN9: No | GV9: =IFERROR(VLOOKUP(GT9&"-"&GU9, Sheet2!$E:$F, 2, FALSE), "") | HB9: =IFERROR(VLOOKUP(GZ9&"-"&HA9, Sheet2!$E:$F, 2, FALSE), "") | HK9: =IFERROR(VLOOKUP(HI9&"-"&HJ9, Sheet2!$E:$F, 2, FALSE), "") | HQ9: =IFERROR(VLOOKUP(HO9&"-"&HP9, Sheet2!$E:$F, 2, FALSE), "") | IC9: =IFERROR(VLOOKUP(IA9&"-"&IB9, Sheet2!$E:$F, 2, FALSE), "") | IK9: =IFERROR(VLOOKUP(II9&"-"&IJ9, Sheet2!$E:$F, 2, FALSE), "") | IQ9: =IFERROR(VLOOKUP(IO9&"-"&IP9, Sheet2!$E:$F, 2, FALSE), "") | IZ9: =IFERROR(VLOOKUP(IX9&"-"&IY9, Sheet2!$E:$F, 2, FALSE), "") | JF9: =IFERROR(VLOOKUP(JD9&"-"&JE9, Sheet2!$E:$F, 2, FALSE), "") | JR9: =IFERROR(VLOOKUP(JP9&"-"&JQ9, Sheet2!$E:$F, 2, FALSE), "") | JZ9: =IFERROR(VLOOKUP(JX9&"-"&JY9, Sheet2!$E:$F, 2, FALSE), "") | KH9: =IFERROR(VLOOKUP(KF9&"-"&KG9, Sheet2!$E:$F, 2, FALSE), "") | KQ9: =IFERROR(VLOOKUP(KO9&"-"&KP9, Sheet2!$E:$F, 2, FALSE), "") | KW9: =IFERROR(VLOOKUP(KU9&"-"&KV9, Sheet2!$E:$F, 2, FALSE), "") | LG9: =IFERROR(VLOOKUP(LE9&"-"&LF9, Sheet2!$E:$F, 2, FALSE), "") | LJ9: No | LR9: =IFERROR(VLOOKUP(LP9&"-"&LQ9, Sheet2!$E:$F, 2, FALSE), "") | LX9: =IFERROR(VLOOKUP(LV9&"-"&LW9, Sheet2!$E:$F, 2, FALSE), "") | MG9: =IFERROR(VLOOKUP(ME9&"-"&MF9, Sheet2!$E:$F, 2, FALSE), "") | MM9: =IFERROR(VLOOKUP(MK9&"-"&ML9, Sheet2!$E:$F, 2, FALSE), "") | MW9: =IFERROR(VLOOKUP(MU9&"-"&MV9, Sheet2!$E:$F, 2, FALSE), "") | MZ9: No | NH9: =IFERROR(VLOOKUP(NF9&"-"&NG9, Sheet2!$E:$F, 2, FALSE), "") | NN9: =IFERROR(VLOOKUP(NL9&"-"&NM9, Sheet2!$E:$F, 2, FALSE), "") | NW9: =IFERROR(VLOOKUP(NU9&"-"&NV9, Sheet2!$E:$F, 2, FALSE), "") | OC9: =IFERROR(VLOOKUP(OA9&"-"&OB9, Sheet2!$E:$F, 2, FALSE), "") | OM9: =IFERROR(VLOOKUP(OK9&"-"&OL9, Sheet2!$E:$F, 2, FALSE), "") | OP9: No | OX9: =IFERROR(VLOOKUP(OV9&"-"&OW9, Sheet2!$E:$F, 2, FALSE), "") | PD9: =IFERROR(VLOOKUP(PB9&"-"&PC9, Sheet2!$E:$F, 2, FALSE), "") | PM9: =IFERROR(VLOOKUP(PK9&"-"&PL9, Sheet2!$E:$F, 2, FALSE), "") | PS9: =IFERROR(VLOOKUP(PQ9&"-"&PR9, Sheet2!$E:$F, 2, FALSE), "")
A10: Laurie | B10: Constantino | C10: WA | D10: 100010 | E10: lhconstantino@gmail.com | F10: Founding Member | K10: =IFERROR(VLOOKUP(I10&"-"&J10, Sheet2!$E:$F, 2, FALSE), "") | L10: IL | M10: Norfolk | N10: =IFERROR(VLOOKUP(L10&"-"&M10, Sheet2!$E:$F, 2, FALSE), "") | R10: No | Y10: =IFERROR(VLOOKUP(W10&"-"&X10, Sheet2!$E:$F, 2, FALSE), "") | Z10: MA | AB10: =IFERROR(VLOOKUP(Z10&"-"&X10, Sheet2!$E:$F, 2, FALSE), "") | AJ10: =IFERROR(VLOOKUP(AH10&"-"&AI10, Sheet2!$E:$F, 2, FALSE), "") | AR10: =IFERROR(VLOOKUP(AP10&"-"&AQ10, Sheet2!$E:$F, 2, FALSE), "") | AZ10: =IFERROR(VLOOKUP(AX10&"-"&AY10, Sheet2!$E:$F, 2, FALSE), "") | BJ10: =IFERROR(VLOOKUP(BH10&"-"&BI10, Sheet2!$E:$F, 2, FALSE), "") | BN10: No | BV10: =IFERROR(VLOOKUP(BT10&"-"&BU10, Sheet2!$E:$F, 2, FALSE), "") | CB10: =IFERROR(VLOOKUP(BZ10&"-"&CA10, Sheet2!$E:$F, 2, FALSE), "") | CJ10: =IFERROR(VLOOKUP(CH10&"-"&CI10, Sheet2!$E:$F, 2, FALSE), "") | CP10: =IFERROR(VLOOKUP(CN10&"-"&CO10, Sheet2!$E:$F, 2, FALSE), "") | CZ10: =IFERROR(VLOOKUP(CX10&"-"&CY10, Sheet2!$E:$F, 2, FALSE), "") | DC10: No | DK10: =IFERROR(VLOOKUP(DI10&"-"&DJ10, Sheet2!$E:$F, 2, FALSE), "") | DQ10: =IFERROR(VLOOKUP(DO10&"-"&DP10, Sheet2!$E:$F, 2, FALSE), "") | DT10: No | EE10: =IFERROR(VLOOKUP(EC10&"-"&ED10, Sheet2!$E:$F, 2, FALSE), "") | EJ10: =IFERROR(VLOOKUP(EH10&"-"&EI10, Sheet2!$E:$F, 2, FALSE), "") | EU10: =IFERROR(VLOOKUP(ES10&"-"&ET10, Sheet2!$E:$F, 2, FALSE), "") | EX10: No | FF10: =IFERROR(VLOOKUP(FD10&"-"&FE10, Sheet2!$E:$F, 2, FALSE), "") | FL10: =IFERROR(VLOOKUP(FJ10&"-"&FK10, Sheet2!$E:$F, 2, FALSE), "") | FT10: =IFERROR(VLOOKUP(FR10&"-"&FS10, Sheet2!$E:$F, 2, FALSE), "") | FZ10: =IFERROR(VLOOKUP(FX10&"-"&FY10, Sheet2!$E:$F, 2, FALSE), "") | GK10: =IFERROR(VLOOKUP(GI10&"-"&GJ10, Sheet2!$E:$F, 2, FALSE), "") | GN10: No | GV10: =IFERROR(VLOOKUP(GT10&"-"&GU10, Sheet2!$E:$F, 2, FALSE), "") | HB10: =IFERROR(VLOOKUP(GZ10&"-"&HA10, Sheet2!$E:$F, 2, FALSE), "") | HK10: =IFERROR(VLOOKUP(HI10&"-"&HJ10, Sheet2!$E:$F, 2, FALSE), "") | HQ10: =IFERROR(VLOOKUP(HO10&"-"&HP10, Sheet2!$E:$F, 2, FALSE), "") | IC10: =IFERROR(VLOOKUP(IA10&"-"&IB10, Sheet2!$E:$F, 2, FALSE), "") | IK10: =IFERROR(VLOOKUP(II10&"-"&IJ10, Sheet2!$E:$F, 2, FALSE), "") | IQ10: =IFERROR(VLOOKUP(IO10&"-"&IP10, Sheet2!$E:$F, 2, FALSE), "") | IZ10: =IFERROR(VLOOKUP(IX10&"-"&IY10, Sheet2!$E:$F, 2, FALSE), "") | JF10: =IFERROR(VLOOKUP(JD10&"-"&JE10, Sheet2!$E:$F, 2, FALSE), "") | JR10: =IFERROR(VLOOKUP(JP10&"-"&JQ10, Sheet2!$E:$F, 2, FALSE), "") | JZ10: =IFERROR(VLOOKUP(JX10&"-"&JY10, Sheet2!$E:$F, 2, FALSE), "") | KH10: =IFERROR(VLOOKUP(KF10&"-"&KG10, Sheet2!$E:$F, 2, FALSE), "") | KQ10: =IFERROR(VLOOKUP(KO10&"-"&KP10, Sheet2!$E:$F, 2, FALSE), "") | KW10: =IFERROR(VLOOKUP(KU10&"-"&KV10, Sheet2!$E:$F, 2, FALSE), "") | LG10: =IFERROR(VLOOKUP(LE10&"-"&LF10, Sheet2!$E:$F, 2, FALSE), "") | LJ10: No | LR10: =IFERROR(VLOOKUP(LP10&"-"&LQ10, Sheet2!$E:$F, 2, FALSE), "") | LX10: =IFERROR(VLOOKUP(LV10&"-"&LW10, Sheet2!$E:$F, 2, FALSE), "") | MG10: =IFERROR(VLOOKUP(ME10&"-"&MF10, Sheet2!$E:$F, 2, FALSE), "") | MM10: =IFERROR(VLOOKUP(MK10&"-"&ML10, Sheet2!$E:$F, 2, FALSE), "") | MW10: =IFERROR(VLOOKUP(MU10&"-"&MV10, Sheet2!$E:$F, 2, FALSE), "") | MZ10: No | NH10: =IFERROR(VLOOKUP(NF10&"-"&NG10, Sheet2!$E:$F, 2, FALSE), "") | NN10: =IFERROR(VLOOKUP(NL10&"-"&NM10, Sheet2!$E:$F, 2, FALSE), "") | NW10: =IFERROR(VLOOKUP(NU10&"-"&NV10, Sheet2!$E:$F, 2, FALSE), "") | OC10: =IFERROR(VLOOKUP(OA10&"-"&OB10, Sheet2!$E:$F, 2, FALSE), "") | OM10: =IFERROR(VLOOKUP(OK10&"-"&OL10, Sheet2!$E:$F, 2, FALSE), "") | OP10: No | OX10: =IFERROR(VLOOKUP(OV10&"-"&OW10, Sheet2!$E:$F, 2, FALSE), "") | PD10: =IFERROR(VLOOKUP(PB10&"-"&PC10, Sheet2!$E:$F, 2, FALSE), "") | PM10: =IFERROR(VLOOKUP(PK10&"-"&PL10, Sheet2!$E:$F, 2, FALSE), "") | PS10: =IFERROR(VLOOKUP(PQ10&"-"&PR10, Sheet2!$E:$F, 2, FALSE), "")
A11: Gigi | B11: Best-Richardson | C11: FL | D11: 100011 | E11: bradlcmuseum@gmail.com | F11: Founding Member | K11: =IFERROR(VLOOKUP(I11&"-"&J11, Sheet2!$E:$F, 2, FALSE), "") | L11: IL | M11: Norfolk | N11: =IFERROR(VLOOKUP(L11&"-"&M11, Sheet2!$E:$F, 2, FALSE), "") | R11: No | Y11: =IFERROR(VLOOKUP(W11&"-"&X11, Sheet2!$E:$F, 2, FALSE), "") | Z11: MA | AB11: =IFERROR(VLOOKUP(Z11&"-"&X11, Sheet2!$E:$F, 2, FALSE), "") | AJ11: =IFERROR(VLOOKUP(AH11&"-"&AI11, Sheet2!$E:$F, 2, FALSE), "") | AR11: =IFERROR(VLOOKUP(AP11&"-"&AQ11, Sheet2!$E:$F, 2, FALSE), "") | AZ11: =IFERROR(VLOOKUP(AX11&"-"&AY11, Sheet2!$E:$F, 2, FALSE), "") | BJ11: =IFERROR(VLOOKUP(BH11&"-"&BI11, Sheet2!$E:$F, 2, FALSE), "") | BN11: No | BV11: =IFERROR(VLOOKUP(BT11&"-"&BU11, Sheet2!$E:$F, 2, FALSE), "") | CB11: =IFERROR(VLOOKUP(BZ11&"-"&CA11, Sheet2!$E:$F, 2, FALSE), "") | CJ11: =IFERROR(VLOOKUP(CH11&"-"&CI11, Sheet2!$E:$F, 2, FALSE), "") | CP11: =IFERROR(VLOOKUP(CN11&"-"&CO11, Sheet2!$E:$F, 2, FALSE), "") | CZ11: =IFERROR(VLOOKUP(CX11&"-"&CY11, Sheet2!$E:$F, 2, FALSE), "") | DC11: No | DK11: =IFERROR(VLOOKUP(DI11&"-"&DJ11, Sheet2!$E:$F, 2, FALSE), "") | DQ11: =IFERROR(VLOOKUP(DO11&"-"&DP11, Sheet2!$E:$F, 2, FALSE), "") | DT11: No | EE11: =IFERROR(VLOOKUP(EC11&"-"&ED11, Sheet2!$E:$F, 2, FALSE), "") | EJ11: =IFERROR(VLOOKUP(EH11&"-"&EI11, Sheet2!$E:$F, 2, FALSE), "") | EU11: =IFERROR(VLOOKUP(ES11&"-"&ET11, Sheet2!$E:$F, 2, FALSE), "") | EX11: No | FF11: =IFERROR(VLOOKUP(FD11&"-"&FE11, Sheet2!$E:$F, 2, FALSE), "") | FL11: =IFERROR(VLOOKUP(FJ11&"-"&FK11, Sheet2!$E:$F, 2, FALSE), "") | FT11: =IFERROR(VLOOKUP(FR11&"-"&FS11, Sheet2!$E:$F, 2, FALSE), "") | FZ11: =IFERROR(VLOOKUP(FX11&"-"&FY11, Sheet2!$E:$F, 2, FALSE), "") | GK11: =IFERROR(VLOOKUP(GI11&"-"&GJ11, Sheet2!$E:$F, 2, FALSE), "") | GN11: No | GV11: =IFERROR(VLOOKUP(GT11&"-"&GU11, Sheet2!$E:$F, 2, FALSE), "") | HB11: =IFERROR(VLOOKUP(GZ11&"-"&HA11, Sheet2!$E:$F, 2, FALSE), "") | HK11: =IFERROR(VLOOKUP(HI11&"-"&HJ11, Sheet2!$E:$F, 2, FALSE), "") | HQ11: =IFERROR(VLOOKUP(HO11&"-"&HP11, Sheet2!$E:$F, 2, FALSE), "") | IC11: =IFERROR(VLOOKUP(IA11&"-"&IB11, Sheet2!$E:$F, 2, FALSE), "") | IK11: =IFERROR(VLOOKUP(II11&"-"&IJ11, Sheet2!$E:$F, 2, FALSE), "") | IQ11: =IFERROR(VLOOKUP(IO11&"-"&IP11, Sheet2!$E:$F, 2, FALSE), "") | IZ11: =IFERROR(VLOOKUP(IX11&"-"&IY11, Sheet2!$E:$F, 2, FALSE), "") | JF11: =IFERROR(VLOOKUP(JD11&"-"&JE11, Sheet2!$E:$F, 2, FALSE), "") | JR11: =IFERROR(VLOOKUP(JP11&"-"&JQ11, Sheet2!$E:$F, 2, FALSE), "") | JZ11: =IFERROR(VLOOKUP(JX11&"-"&JY11, Sheet2!$E:$F, 2, FALSE), "") | KH11: =IFERROR(VLOOKUP(KF11&"-"&KG11, Sheet2!$E:$F, 2, FALSE), "") | KQ11: =IFERROR(VLOOKUP(KO11&"-"&KP11, Sheet2!$E:$F, 2, FALSE), "") | KW11: =IFERROR(VLOOKUP(KU11&"-"&KV11, Sheet2!$E:$F, 2, FALSE), "") | LG11: =IFERROR(VLOOKUP(LE11&"-"&LF11, Sheet2!$E:$F, 2, FALSE), "") | LJ11: No | LR11: =IFERROR(VLOOKUP(LP11&"-"&LQ11, Sheet2!$E:$F, 2, FALSE), "") | LX11: =IFERROR(VLOOKUP(LV11&"-"&LW11, Sheet2!$E:$F, 2, FALSE), "") | MG11: =IFERROR(VLOOKUP(ME11&"-"&MF11, Sheet2!$E:$F, 2, FALSE), "") | MM11: =IFERROR(VLOOKUP(MK11&"-"&ML11, Sheet2!$E:$F, 2, FALSE), "") | MW11: =IFERROR(VLOOKUP(MU11&"-"&MV11, Sheet2!$E:$F, 2, FALSE), "") | MZ11: No | NH11: =IFERROR(VLOOKUP(NF11&"-"&NG11, Sheet2!$E:$F, 2, FALSE), "") | NN11: =IFERROR(VLOOKUP(NL11&"-"&NM11, Sheet2!$E:$F, 2, FALSE), "") | NW11: =IFERROR(VLOOKUP(NU11&"-"&NV11, Sheet2!$E:$F, 2, FALSE), "") | OC11: =IFERROR(VLOOKUP(OA11&"-"&OB11, Sheet2!$E:$F, 2, FALSE), "") | OM11: =IFERROR(VLOOKUP(OK11&"-"&OL11, Sheet2!$E:$F, 2, FALSE), "") | OP11: No | OX11: =IFERROR(VLOOKUP(OV11&"-"&OW11, Sheet2!$E:$F, 2, FALSE), "") | PD11: =IFERROR(VLOOKUP(PB11&"-"&PC11, Sheet2!$E:$F, 2, FALSE), "") | PM11: =IFERROR(VLOOKUP(PK11&"-"&PL11, Sheet2!$E:$F, 2, FALSE), "") | PS11: =IFERROR(VLOOKUP(PQ11&"-"&PR11, Sheet2!$E:$F, 2, FALSE), "")
A12: John | B12: Carter | C12: FL | D12: 100012 | E12: spacemanspiff@tampabay.rr.com | F12: Founding Member | G12: 21485 | H12: Dover, Kent, DE | K12: =IFERROR(VLOOKUP(I12&"-"&J12, Sheet2!$E:$F, 2, FALSE), "") | L12: IL | M12: Norfolk | N12: =IFERROR(VLOOKUP(L12&"-"&M12, Sheet2!$E:$F, 2, FALSE), "") | R12: Yes | Y12: =IFERROR(VLOOKUP(W12&"-"&X12, Sheet2!$E:$F, 2, FALSE), "") | Z12: MA | AB12: =IFERROR(VLOOKUP(Z12&"-"&X12, Sheet2!$E:$F, 2, FALSE), "") | AJ12: =IFERROR(VLOOKUP(AH12&"-"&AI12, Sheet2!$E:$F, 2, FALSE), "") | AR12: =IFERROR(VLOOKUP(AP12&"-"&AQ12, Sheet2!$E:$F, 2, FALSE), "") | AZ12: =IFERROR(VLOOKUP(AX12&"-"&AY12, Sheet2!$E:$F, 2, FALSE), "") | BB12: Record copy, National Society Sons of the America Revolution application of John Cyrus Carter (National member #132102), showing descent from John Durham, Sr (SAR Patriot #P-151685; DAR Patriot #208659). | BC12: John Clayton | BD12: Carter | BE12: 11999 | BF12: Greenwich, Cumberland, NJ | BJ12: =IFERROR(VLOOKUP(BH12&"-"&BI12, Sheet2!$E:$F, 2, FALSE), "") | BN12: Yes | BQ12: 36601 | BR12: Colorado Springs, El Paso, CO | BV12: =IFERROR(VLOOKUP(BT12&"-"&BU12, Sheet2!$E:$F, 2, FALSE), "") | BW12: 21196 | BX12: Bridgeton, Cumberland, NJ | CB12: =IFERROR(VLOOKUP(BZ12&"-"&CA12, Sheet2!$E:$F, 2, FALSE), "") | CC12: Christine | CD12: Harris | CE12: 11172 | CF12: Coxton, Harlan Ce, KY | CJ12: =IFERROR(VLOOKUP(CH12&"-"&CI12, Sheet2!$E:$F, 2, FALSE), "") | CK12: 35402 | CL12: Madison, Boone Co, WV | CP12: =IFERROR(VLOOKUP(CN12&"-"&CO12, Sheet2!$E:$F, 2, FALSE), "") | CR12: Record copy, National Society Sons of the America Revolution application of John Cyrus Carter (National member #132102), showing descent from John Durham, Sr (SAR Patriot #P-151685; DAR Patriot #208659). | CS12: Hopewell | CT12: Carter | CU12: 3031 | CV12: Cheswold, Kent, DE | CZ12: =IFERROR(VLOOKUP(CX12&"-"&CY12, Sheet2!$E:$F, 2, FALSE), "") | DC12: Yes | DF12: 24775 | DG12: Winslow, Camden Co, NJ | DK12: =IFERROR(VLOOKUP(DI12&"-"&DJ12, Sheet2!$E:$F, 2, FALSE), "") | DL12: 10740 | DM12: Bridgeton, Cumberland Co, NJ | DQ12: =IFERROR(VLOOKUP(DO12&"-"&DP12, Sheet2!$E:$F, 2, FALSE), "") | DT12: Yes | DW12: Lethia Harriett | DX12: Coker | DZ12: 4597 | EA12: Dover, Kent Ca, DE | EB12: 31721 | EE12: =IFERROR(VLOOKUP(EC12&"-"&ED12, Sheet2!$E:$F, 2, FALSE), "") | EF12: Bridgeton,C umberlandC o,N | EJ12: =IFERROR(VLOOKUP(EH12&"-"&EI12, Sheet2!$E:$F, 2, FALSE), "") | EM12: Record copy, National Society Sons of the America Revolution application of John Cyrus Carter (National member #132102), showing descent from John Durham, Sr (SAR Patriot #P-151685; DAR Patriot #208659). | EN12: John Clayton | EO12: Carter | EP12: 23 Apr 1884 | EQ12: DE | EU12: =IFERROR(VLOOKUP(ES12&"-"&ET12, Sheet2!$E:$F, 2, FALSE), "") | EX12: Yes | FA12: 5522 | FB12: Cheswotd, Kent Ce, DE | FF12: =IFERROR(VLOOKUP(FD12&"-"&FE12, Sheet2!$E:$F, 2, FALSE), "") | FG12: 2965 | FH12: Kent Ce, DE | FL12: =IFERROR(VLOOKUP(FJ12&"-"&FK12, Sheet2!$E:$F, 2, FALSE), "") | FM12: Phebe | FN12: Carney | FO12: 14 Den 1889 | FP12: Cheswdd, Kent Ce, DE | FT12: =IFERROR(VLOOKUP(FR12&"-"&FS12, Sheet2!$E:$F, 2, FALSE), "") | FU12: 24241 | FV12: FairfietdTownship, Cumberland Co, NJ | FZ12: =IFERROR(VLOOKUP(FX12&"-"&FY12, Sheet2!$E:$F, 2, FALSE), "") | GC12: Record copy, National Society Sons of the America Revolution application of John Cyrus Carter (National member #132102), showing descent from John Durham, Sr (SAR Patriot #P-151685; DAR Patriot #208659). | GD12: James Perry | GE12: Carter | GF12: 21 Jul 1847 | GG12: Kent County, DE | GK12: =IFERROR(VLOOKUP(GI12&"-"&GJ12, Sheet2!$E:$F, 2, FALSE), "") | GN12: Yes | GQ12: 12654 | GR12: Kent County, DE | GV12: =IFERROR(VLOOKUP(GT12&"-"&GU12, Sheet2!$E:$F, 2, FALSE), "") | HB12: =IFERROR(VLOOKUP(GZ12&"-"&HA12, Sheet2!$E:$F, 2, FALSE), "") | HC12: Harriet | HD12: Durham | HF12: 20 May 1851 | HG12: Kent County, DE | HK12: =IFERROR(VLOOKUP(HI12&"-"&HJ12, Sheet2!$E:$F, 2, FALSE), "") | HL12: 7662 | HM12: Kent County, DE | HQ12: =IFERROR(VLOOKUP(HO12&"-"&HP12, Sheet2!$E:$F, 2, FALSE), "") | HT12: Record copy, National Society Sons of the America Revolution application of John Cyrus Carter (National member #132102), showing descent from John Durham, Sr (SAR Patriot #P-151685; DAR Patriot #208659). | HU12: Joel | HV12: Durham | HX12: Jul 1819 | HY12: Dover, Kent Co, De | IC12: =IFERROR(VLOOKUP(IA12&"-"&IB12, Sheet2!$E:$F, 2, FALSE), "") | IF12: 2970 | IG12: Dover, Kent Co, DE | IK12: =IFERROR(VLOOKUP(II12&"-"&IJ12, Sheet2!$E:$F, 2, FALSE), "") | IL12: 1838 | IQ12: =IFERROR(VLOOKUP(IO12&"-"&IP12, Sheet2!$E:$F, 2, FALSE), "") | IR12: Margaret | IS12: Munce | IT12: Muntz | IU12: 1817 | IV12: DE | IZ12: =IFERROR(VLOOKUP(IX12&"-"&IY12, Sheet2!$E:$F, 2, FALSE), "") | JA12: 14 Apr 1895 | JB12: Dover, Kent Co, DE | JF12: =IFERROR(VLOOKUP(JD12&"-"&JE12, Sheet2!$E:$F, 2, FALSE), "") | JJ12: Elisha | JK12: Durham Sr. | JL12: Elijah | JM12: Feb 1794 | JN12: Dover, Kent Co, DE | JR12: =IFERROR(VLOOKUP(JP12&"-"&JQ12, Sheet2!$E:$F, 2, FALSE), "") | JU12: 15 May 1864 | JV12: Dover, Kent Co, DE | JZ12: =IFERROR(VLOOKUP(JX12&"-"&JY12, Sheet2!$E:$F, 2, FALSE), "") | KC12: 1819 | KD12: Kent Co, DE | KH12: =IFERROR(VLOOKUP(KF12&"-"&KG12, Sheet2!$E:$F, 2, FALSE), "") | KI12: Hester | KJ12: Conselor | KK12: Concealler | KL12: 1787 | KM12: Kent Co, DE | KQ12: =IFERROR(VLOOKUP(KO12&"-"&KP12, Sheet2!$E:$F, 2, FALSE), "") | KR12: 1845 | KS12: Kent Co, DE | KW12: =IFERROR(VLOOKUP(KU12&"-"&KV12, Sheet2!$E:$F, 2, FALSE), "") | KX12: Record copy, National Society Sons of the America Revolution application of John Cyrus Carter (National member #132102), showing descent from John Durham, Sr (SAR Patriot #P-151685; DAR Patriot #208659). | KY12: Jeremiah | KZ12: Conselor | LA12: Concealler | LB12: 1779 | LG12: =IFERROR(VLOOKUP(LE12&"-"&LF12, Sheet2!$E:$F, 2, FALSE), "") | LJ12: Yes | LN12: Kent Co, DE | LR12: =IFERROR(VLOOKUP(LP12&"-"&LQ12, Sheet2!$E:$F, 2, FALSE), "") | LX12: =IFERROR(VLOOKUP(LV12&"-"&LW12, Sheet2!$E:$F, 2, FALSE), "") | LY12: Elizabeth | MG12: =IFERROR(VLOOKUP(ME12&"-"&MF12, Sheet2!$E:$F, 2, FALSE), "") | MM12: =IFERROR(VLOOKUP(MK12&"-"&ML12, Sheet2!$E:$F, 2, FALSE), "") | MN12: Record copy, National Society Sons of the America Revolution application of John Cyrus Carter (National member #132102), showing descent from John Durham, Sr (SAR Patriot #P-151685; DAR Patriot #208659). | MO12: Elijah | MP12: Conselor | MQ12: Concealler | MR12: 1762 | MW12: =IFERROR(VLOOKUP(MU12&"-"&MV12, Sheet2!$E:$F, 2, FALSE), "") | MZ12: Yes | NC12: 29 Dec 1801 | ND12: Kent Co, DE | NH12: =IFERROR(VLOOKUP(NF12&"-"&NG12, Sheet2!$E:$F, 2, FALSE), "") | NJ12: Kent Co, DE | NN12: =IFERROR(VLOOKUP(NL12&"-"&NM12, Sheet2!$E:$F, 2, FALSE), "") | NO12: Hannah | NP12: Durham | NS12: Kent Co, DE | NW12: =IFERROR(VLOOKUP(NU12&"-"&NV12, Sheet2!$E:$F, 2, FALSE), "") | NX12: 29 Jun 1841 | NY12: Kent Co, DE | OC12: =IFERROR(VLOOKUP(OA12&"-"&OB12, Sheet2!$E:$F, 2, FALSE), "") | OD12: Record copy, National Society Sons of the America Revolution application of John Cyrus Carter (National member #132102), showing descent from John Durham, Sr (SAR Patriot #P-151685; DAR Patriot #208659). | OE12: John | OF12: Durham Sr. | OH12: 1720 | OM12: =IFERROR(VLOOKUP(OK12&"-"&OL12, Sheet2!$E:$F, 2, FALSE), "") | OP12: Yes | OS12: 13 May 1788 | OT12: Little Creek Hundred, Kent Co, DE | OX12: =IFERROR(VLOOKUP(OV12&"-"&OW12, Sheet2!$E:$F, 2, FALSE), "") | PD12: =IFERROR(VLOOKUP(PB12&"-"&PC12, Sheet2!$E:$F, 2, FALSE), "") | PM12: =IFERROR(VLOOKUP(PK12&"-"&PL12, Sheet2!$E:$F, 2, FALSE), "") | PS12: =IFERROR(VLOOKUP(PQ12&"-"&PR12, Sheet2!$E:$F, 2, FALSE), "") | PT12: Record copy, National Society Sons of the America Revolution application of John Cyrus Carter (National member #132102), showing descent from John Durham, Sr (SAR Patriot #P-151685; DAR Patriot #208659).
