Workbook

Sheet Main
A1: Ship_Name | B1: Notes | C1: Ship_Notes | D1: First_Name | E1: Surname | F1: Birthdate | G1: ID | H1: Ref_Page | I1: Book | J1: Commander | K1: Father_FirstName | L1: Father_Surname | M1: Mother_FirstName | N1: Mother_Surname | O1: Gender | P1: Race | Q1: Ethnicity | R1: Origination_Port | S1: Origination_State | T1: Departure_Port | U1: Departure_Date | V1: Arrival_Port_City | W1: Primary_Source_1 | X1: Primary_Source_2 | Y1: Enslaver | Z1: Origin | AA1: Extracted_City | AB1: Extracted_County | AC1: Extracted_State | AD1: Country | AE1: State | AF1: County | AG1: Departure_Coordinates
A2: 3 Friends | B2: William Johnson, 21, stout likely fellow, (Lt. Richard Holland). Formerly slave to John Chapman of Princess Ann County, Virginia; left him 4 years. | C2: Sloop 3 Friends bound for River St. John's John Stewart, Master | D2: William | E2: Johnson | F2: 1762 | G2: 744 | H2: - | I2: Book One Part One | J2: John Stewart | K2: - | L2: - | M2: - | N2: - | O2: Male | P2: Black | Q2: African American | R2: Formerly slave to John Chapman of Princess Ann County | S2: Virginia | T2: - | U2: - | V2: River St. John's | W2: - | X2: - | Y2: Lt. Richard Holland | Z2: Black | AA2: - | AB2: - | AC2: Virginia | AD2: United States | AG2: =IF(AD2="United States", IFERROR(INDEX(Sheet2!$C:$C, MATCH(AE2&AF2, Sheet2!$E:$E, 0)) & ", " & INDEX(Sheet2!$D:$D, MATCH(AE2&AF2, Sheet2!$E:$E, 0)), ""), "-")
A3: 3 Friends | B3: Sally her child, 8 mo. | C3: Sloop 3 Friends bound for River St. John's John Stewart, Master | D3: Sally | E3: her child | F3: 1775 | G3: 746 | H3: - | I3: Book One Part One | J3: John Stewart | K3: - | L3: - | M3: Elizabeth | N3: Merrick | O3: Child Male | P3: Black | Q3: African American | R3: - | S3: - | T3: - | U3: - | V3: River St. John's | W3: - | X3: - | Y3: - | Z3: Black | AA3: - | AB3: - | AC3: mo | AD3: United States | AG3: =IF(AD3="United States", IFERROR(INDEX(Sheet2!$C:$C, MATCH(AE3&AF3, Sheet2!$E:$E, 0)) & ", " & INDEX(Sheet2!$D:$D, MATCH(AE3&AF3, Sheet2!$E:$E, 0)), ""), "-")
A4: 3 Friends | B4: Elizabeth Merrick, 27, stout wench, M, (Luther Hatheway). Born free; served her time with Lambert Woodward of Newtown, Long Island. | C4: Sloop 3 Friends bound for River St. John's John Stewart, Master | D4: Elizabeth | E4: Merrick | F4: 1756 | G4: 743 | H4: - | I4: Book One Part One | J4: John Stewart | K4: - | L4: - | M4: - | N4: - | O4: Female | P4: Black | Q4: African American | R4: - | S4: - | T4: - | U4: - | V4: River St. John's | W4: - | X4: - | Y4: Luther Hatheway | Z4: Black | AA4: Newtown | AB4: - | AC4: Long Island | AD4: United States | AG4: =IF(AD4="United States", IFERROR(INDEX(Sheet2!$C:$C, MATCH(AE4&AF4, Sheet2!$E:$E, 0)) & ", " & INDEX(Sheet2!$D:$D, MATCH(AE4&AF4, Sheet2!$E:$E, 0)), ""), "-")
A5: 3 Friends | B5: Richard Merrick, 32, stout likely fellow, (Sam Wilson). Formerly slave to Samuel Merrick of Springfield, Massachusetts, who gave him his freedom & produced a Certificate dated 4 November 74, signed by Merrick, Philips & Dr. White. | C5: Sloop 3 Friends bound for River St. John's John Stewart, Master | D5: Richard | E5: Merrick | F5: 1751 | G5: 742 | H5: - | I5: Book One Part One | J5: John Stewart | K5: Tom | L5: Gunn | M5: - | N5: - | O5: Male | P5: Black | Q5: African American | R5: - | S5: - | T5: - | U5: - | V5: River St. John's | W5: - | X5: - | Y5: Sam Wilson | Z5: Black | AA5: Springfield | AB5: - | AC5: Massachusetts | AD5: United States | AG5: =IF(AD5="United States", IFERROR(INDEX(Sheet2!$C:$C, MATCH(AE5&AF5, Sheet2!$E:$E, 0)) & ", " & INDEX(Sheet2!$D:$D, MATCH(AE5&AF5, Sheet2!$E:$E, 0)), ""), "-")
A6: 3 Friends | B6: Tom Gunn, 43, stout, pockmarked, (Sam Wilson). Formerly slave to Enos Gunn of Waterbury, Connecticut. | C6: Sloop 3 Friends bound for River St. John's John Stewart, Master | D6: Tom | E6: Gunn | F6: 1740 | G6: 741 | H6: - | I6: Book One Part One | J6: John Stewart | K6: - | L6: - | M6: - | N6: - | O6: Male | P6: Black | Q6: African American | R6: - | S6: - | T6: - | U6: - | V6: River St. John's | W6: - | X6: - | Y6: Sam Wilson | Z6: Black | AA6: Waterbury | AB6: - | AC6: Connecticut | AD6: United States | AG6: =IF(AD6="United States", IFERROR(INDEX(Sheet2!$C:$C, MATCH(AE6&AF6, Sheet2!$E:$E, 0)) & ", " & INDEX(Sheet2!$D:$D, MATCH(AE6&AF6, Sheet2!$E:$E, 0)), ""), "-")
A7: 3 Friends | B7: Hannah and, 16, stout wench, (Lt. Richard Holland). Born free in Cow Neck, Long Island, lived with Caleb Merrill till within this last year. | C7: Sloop 3 Friends bound for River St. John's John Stewart, Master | D7: Hannah | E7: and | F7: 1767 | G7: 745 | H7: - | I7: Book One Part One | J7: John Stewart | K7: - | L7: - | M7: - | N7: - | O7: Child Female | P7: Black | Q7: African American | R7: - | S7: - | T7: - | U7: - | V7: River St. John's | W7: - | X7: - | Y7: Lt. Richard Holland | Z7: Black | AA7: - | AB7: - | AC7: Long Island | AD7: United States | AG7: =IF(AD7="United States", IFERROR(INDEX(Sheet2!$C:$C, MATCH(AE7&AF7, Sheet2!$E:$E, 0)) & ", " & INDEX(Sheet2!$D:$D, MATCH(AE7&AF7, Sheet2!$E:$E, 0)), ""), "-")
A8: 3 Sisters | B8: 18 September | C8: 3 Sisters bound for Quebec John Wardell | D8: 18 | E8: September | F8: 1765 | G8: 2716 | I8: Book One Part Two | J8: - | O8: Male | P8: Black | Q8: African American | V8: Quebec John Wardell | Y8: - | Z8: Black | AA8: - | AB8: - | AC8: - | AD8: United States | AG8: =IF(AD8="United States", IFERROR(INDEX(Sheet2!$C:$C, MATCH(AE8&AF8, Sheet2!$E:$E, 0)) & ", " & INDEX(Sheet2!$D:$D, MATCH(AE8&AF8, Sheet2!$E:$E, 0)), ""), "-")
A9: Alexander | B9: Cairo, 20, stout wench, (James Peters). Property of James Petes. | C9: Alexander bound for St. John's Roger Alderson | D9: Cairo | E9: - | F9: 1763 | G9: 2254 | H9: 70 | I9: Book Two | J9: Roger Alderson | K9: - | L9: - | M9: - | N9: - | O9: Female | P9: Black | Q9: African American | R9: New York | S9: - | T9: New York | U9: Fall 1783 | V9: St. John's | W9: Book of Negroes, British Headquarters Papers PRO 30/55/100; Loyalist evacuation shipping lists (1782–1784) | X9: Loyalist evacuation lists | Y9: James Peters | Z9: Black | AA9: - | AB9: - | AC9: Cairo | AD9: United States | AG9: =IF(AD9="United States", IFERROR(INDEX(Sheet2!$C:$C, MATCH(AE9&AF9, Sheet2!$E:$E, 0)) & ", " & INDEX(Sheet2!$D:$D, MATCH(AE9&AF9, Sheet2!$E:$E, 0)), ""), "-")
A10: Alexander | B10: Bella, 14, stout wench, (James Peters). Property of James Peters. | C10: Alexander bound for St. John's Roger Alderson | D10: Bella | E10: - | F10: 1769 | G10: 2255 | H10: 70 | I10: Book Two | J10: Roger Alderson | K10: - | L10: - | M10: - | N10: - | O10: Child Female | P10: Black | Q10: African American | R10: New York | S10: - | T10: New York | U10: Fall 1783 | V10: St. John's | W10: Book of Negroes, British Headquarters Papers PRO 30/55/100; Loyalist evacuation shipping lists (1782–1784) | X10: Loyalist evacuation lists | Y10: James Peters | Z10: Black | AA10: - | AB10: - | AC10: - | AD10: United States | AG10: =IF(AD10="United States", IFERROR(INDEX(Sheet2!$C:$C, MATCH(AE10&AF10, Sheet2!$E:$E, 0)) & ", " & INDEX(Sheet2!$D:$D, MATCH(AE10&AF10, Sheet2!$E:$E, 0)), ""), "-")
A11: Alexander | B11: Esther, 18, stout wench, M, (Bartholomew Cranell). Property of Bartholomew Crannell. | C11: Alexander bound for St. John's Roger Alderson | D11: Esther | E11: - | F11: 1765 | G11: 2256 | H11: 70 | I11: Book Two | J11: Roger Alderson | K11: - | L11: - | M11: - | N11: - | O11: Female | P11: Black | Q11: African American | R11: New York | S11: - | T11: New York | U11: Fall 1783 | V11: St. John's | W11: Book of Negroes, British Headquarters Papers PRO 30/55/100; Loyalist evacuation shipping lists (1782–1784) | X11: Loyalist evacuation lists | Y11: Bartholomew Cranell | Z11: Black | AA11: - | AB11: - | AC11: - | AD11: United States | AG11: =IF(AD11="United States", IFERROR(INDEX(Sheet2!$C:$C, MATCH(AE11&AF11, Sheet2!$E:$E, 0)) & ", " & INDEX(Sheet2!$D:$D, MATCH(AE11&AF11, Sheet2!$E:$E, 0)), ""), "-")
A12: Alexander | B12: Robert, 36, stout fellow, (Bartholomew Crannell). Formerly slave to Isaac Conklin, 9 Partners; left him 2 years ago. | C12: Alexander bound for St. John's Roger Alderson | D12: Robert | E12: - | F12: 1747 | G12: 2258 | H12: 70 | I12: Book Two | J12: Roger Alderson | K12: - | L12: - | M12: - | N12: - | O12: Male | P12: Black | Q12: African American | R12: New York | S12: - | T12: New York | U12: Fall 1783 | V12: St. John's | W12: Book of Negroes, British Headquarters Papers PRO 30/55/100; Loyalist evacuation shipping lists (1782–1784) | X12: Loyalist evacuation lists | Y12: Bartholomew Crannell | Z12: Black | AA12: - | AB12: - | AC12: - | AD12: United States | AG12: =IF(AD12="United States", IFERROR(INDEX(Sheet2!$C:$C, MATCH(AE12&AF12, Sheet2!$E:$E, 0)) & ", " & INDEX(Sheet2!$D:$D, MATCH(AE12&AF12, Sheet2!$E:$E, 0)), ""), "-")
A13: Alexander | B13: Pompey, 25, stout fellow, on his own bottom. Born free. | C13: Alexander bound for St. John's Roger Alderson | D13: Pompey | E13: - | F13: 1758 | G13: 2259 | H13: 70 | I13: Book Two | J13: Roger Alderson | K13: - | L13: - | M13: - | N13: - | O13: Male | P13: Black | Q13: African American | R13: New York | S13: - | T13: New York | U13: Fall 1783 | V13: St. John's | W13: Book of Negroes, British Headquarters Papers PRO 30/55/100; Loyalist evacuation shipping lists (1782–1784) | X13: Loyalist evacuation lists | Y13: - | Z13: Black | AA13: - | AB13: - | AC13: Pompey | AD13: United States | AG13: =IF(AD13="United States", IFERROR(INDEX(Sheet2!$C:$C, MATCH(AE13&AF13, Sheet2!$E:$E, 0)) & ", " & INDEX(Sheet2!$D:$D, MATCH(AE13&AF13, Sheet2!$E:$E, 0)), ""), "-")
A14: Alexander | B14: Sam, 35, (Bartholomew Cranell). Property of Bartholomew Crannell. | C14: Alexander bound for St. John's Roger Alderson | D14: Sam | E14: - | F14: 1748 | G14: 2257 | H14: 70 | I14: Book Two | J14: Roger Alderson | K14: - | L14: - | M14: - | N14: - | O14: Male | P14: Black | Q14: African American | R14: New York | S14: - | T14: New York | U14: Fall 1783 | V14: St. John's | W14: Book of Negroes, British Headquarters Papers PRO 30/55/100; Loyalist evacuation shipping lists (1782–1784) | X14: Loyalist evacuation lists | Y14: Bartholomew Cranell | Z14: Black | AA14: - | AB14: - | AC14: - | AD14: United States | AG14: =IF(AD14="United States", IFERROR(INDEX(Sheet2!$C:$C, MATCH(AE14&AF14, Sheet2!$E:$E, 0)) & ", " & INDEX(Sheet2!$D:$D, MATCH(AE14&AF14, Sheet2!$E:$E, 0)), ""), "-")
A15: Amities Production | D15: Job | E15: State | F15: 1759 | G15: 742 | H15: 35 | J15: Thomas Reid | O15: Male | R15: New York | T15: New York | U15: 16 Jun 1783 | V15: St. Johns | W15: Book of Negroes, British Headquarters Papers PRO 30/55/100; Loyalist evacuation shipping lists (1782–1784) | X15: Loyalist evacuation lists | Y15: - | AA15: - | AB15: - | AC15: - | AD15: United States | AG15: =IF(AD15="United States", IFERROR(INDEX(Sheet2!$C:$C, MATCH(AE15&AF15, Sheet2!$E:$E, 0)) & ", " & INDEX(Sheet2!$D:$D, MATCH(AE15&AF15, Sheet2!$E:$E, 0)), ""), "-")
A16: Amities Production | D16: William | E16: Holchapan | F16: 1743 | G16: 743 | H16: 35 | J16: Thomas Reid | O16: Male | R16: New York | T16: New York | U16: 16 Jun 1783 | V16: St. Johns | W16: Book of Negroes, British Headquarters Papers PRO 30/55/100; Loyalist evacuation shipping lists (1782–1784) | X16: Loyalist evacuation lists | Y16: - | AA16: - | AB16: - | AC16: - | AD16: United States | AG16: =IF(AD16="United States", IFERROR(INDEX(Sheet2!$C:$C, MATCH(AE16&AF16, Sheet2!$E:$E, 0)) & ", " & INDEX(Sheet2!$D:$D, MATCH(AE16&AF16, Sheet2!$E:$E, 0)), ""), "-")
A17: Amities Production | D17: George | E17: State | F17: 1758 | G17: 740 | H17: 35 | J17: Thomas Reid | O17: Male | R17: New York | T17: New York | U17: 16 Jun 1783 | V17: St. Johns | W17: Book of Negroes, British Headquarters Papers PRO 30/55/100; Loyalist evacuation shipping lists (1782–1784) | X17: Loyalist evacuation lists | Y17: - | AA17: - | AB17: - | AC17: - | AD17: United States | AG17: =IF(AD17="United States", IFERROR(INDEX(Sheet2!$C:$C, MATCH(AE17&AF17, Sheet2!$E:$E, 0)) & ", " & INDEX(Sheet2!$D:$D, MATCH(AE17&AF17, Sheet2!$E:$E, 0)), ""), "-")
A18: Amities Production | D18: Mary | E18: State | F18: 1762 | G18: 741 | H18: 35 | J18: Thomas Reid | O18: Female | R18: New York | T18: New York | U18: 16 Jun 1783 | V18: St. Johns | W18: Book of Negroes, British Headquarters Papers PRO 30/55/100; Loyalist evacuation shipping lists (1782–1784) | X18: Loyalist evacuation lists | Y18: - | AA18: - | AB18: - | AC18: - | AD18: United States | AG18: =IF(AD18="United States", IFERROR(INDEX(Sheet2!$C:$C, MATCH(AE18&AF18, Sheet2!$E:$E, 0)) & ", " & INDEX(Sheet2!$D:$D, MATCH(AE18&AF18, Sheet2!$E:$E, 0)), ""), "-")
A19: Amities Production | D19: William | E19: Stepney | F19: 1759 | G19: 739 | H19: 35 | J19: Thomas Reid | O19: Male | R19: New York | T19: New York | U19: 16 Jun 1783 | V19: St. Johns | W19: Book of Negroes, British Headquarters Papers PRO 30/55/100; Loyalist evacuation shipping lists (1782–1784) | X19: Loyalist evacuation lists | Y19: - | AA19: - | AB19: - | AC19: - | AD19: United States | AG19: =IF(AD19="United States", IFERROR(INDEX(Sheet2!$C:$C, MATCH(AE19&AF19, Sheet2!$E:$E, 0)) & ", " & INDEX(Sheet2!$D:$D, MATCH(AE19&AF19, Sheet2!$E:$E, 0)), ""), "-")
A20: Amity's Production | B20: William Holchapan, 40, stout fellow, M, (on his own bottom). Born free and baptized in the year 1779 in the Parish of St. Paul's, London. | C20: Amity's Production bound for St. John's Thomas Reid, Master | D20: William | E20: Holchapan | F20: 1743 | G20: 678 | H20: - | I20: Book One Part One | J20: Thomas Reid | K20: - | L20: - | M20: - | N20: - | O20: Male | P20: Black | Q20: African American | R20: - | S20: - | T20: - | U20: - | V20: St. John's | W20: - | X20: - | Y20: - | Z20: Black | AA20: - | AB20: St | AC20: London | AD20: United States | AG20: =IF(AD20="United States", IFERROR(INDEX(Sheet2!$C:$C, MATCH(AE20&AF20, Sheet2!$E:$E, 0)) & ", " & INDEX(Sheet2!$D:$D, MATCH(AE20&AF20, Sheet2!$E:$E, 0)), ""), "-")
A21: Amity's Production | B21: Job State, 24, stout fellow, M, (on his own bottom). Born free at New York. | C21: Amity's Production bound for St. John's Thomas Reid, Master | D21: Job | E21: State | F21: 1759 | G21: 677 | H21: - | I21: Book One Part One | J21: Thomas Reid | K21: - | L21: - | M21: - | N21: - | O21: Male | P21: Black | Q21: African American | R21: - | S21: New York | T21: - | U21: - | V21: St. John's | W21: - | X21: - | Y21: - | Z21: Black | AA21: - | AB21: - | AC21: New York | AD21: United States | AG21: =IF(AD21="United States", IFERROR(INDEX(Sheet2!$C:$C, MATCH(AE21&AF21, Sheet2!$E:$E, 0)) & ", " & INDEX(Sheet2!$D:$D, MATCH(AE21&AF21, Sheet2!$E:$E, 0)), ""), "-")
A22: Amity's Production | B22: Mary State, 21, half Indian, (on her own bottom). Born free on Long Island. | C22: Amity's Production bound for St. John's Thomas Reid, Master | D22: Mary | E22: State | F22: 1762 | G22: 676 | H22: - | I22: Book One Part One | J22: Thomas Reid | K22: - | L22: - | M22: - | N22: - | O22: Male | P22: Half Indian | Q22: Mixed Race | R22: - | S22: - | T22: - | U22: - | V22: St. John's | W22: - | X22: - | Y22: - | Z22: Mulatto | AA22: - | AB22: - | AC22: Long Island | AD22: United States | AG22: =IF(AD22="United States", IFERROR(INDEX(Sheet2!$C:$C, MATCH(AE22&AF22, Sheet2!$E:$E, 0)) & ", " & INDEX(Sheet2!$D:$D, MATCH(AE22&AF22, Sheet2!$E:$E, 0)), ""), "-")
A23: Amity's Production | B23: George State, 25, stout fellow, M, (on his own bottom). Born free at New York. | C23: Amity's Production bound for St. John's Thomas Reid, Master | D23: George | E23: State | F23: 1758 | G23: 675 | H23: - | I23: Book One Part One | J23: Thomas Reid | K23: - | L23: - | M23: - | N23: - | O23: Male | P23: Black | Q23: African American | R23: - | S23: New York | T23: - | U23: - | V23: St. John's | W23: - | X23: - | Y23: - | Z23: Black | AA23: - | AB23: - | AC23: New York | AD23: United States | AG23: =IF(AD23="United States", IFERROR(INDEX(Sheet2!$C:$C, MATCH(AE23&AF23, Sheet2!$E:$E, 0)) & ", " & INDEX(Sheet2!$D:$D, MATCH(AE23&AF23, Sheet2!$E:$E, 0)), ""), "-")
A24: Amity's Production | B24: William Stepney, 24, stout fellow, B, (on his own bottom). Born free at St. Augustine. | C24: Amity's Production bound for St. John's Thomas Reid, Master | D24: William | E24: Stepney | F24: 1759 | G24: 674 | H24: - | I24: Book One Part One | J24: Thomas Reid | K24: - | L24: - | M24: - | N24: - | O24: Male | P24: Black | Q24: African American | R24: - | S24: - | T24: - | U24: - | V24: St. John's | W24: - | X24: - | Y24: - | Z24: Black | AA24: - | AB24: - | AC24: St. Augustine | AD24: United States | AG24: =IF(AD24="United States", IFERROR(INDEX(Sheet2!$C:$C, MATCH(AE24&AF24, Sheet2!$E:$E, 0)) & ", " & INDEX(Sheet2!$D:$D, MATCH(AE24&AF24, Sheet2!$E:$E, 0)), ""), "-")
A25: Ann | B25: James Robertson, 2½, small boy, (Capt. Mowat). | C25: Ship Ann bound for Port Roseway Joseph Clark, Master | D25: James | E25: Robertson | F25: - | G25: 209 | H25: 22 | I25: Book One Part One | J25: Joseph Clark | K25: - | L25: - | M25: - | N25: - | O25: Child Male | P25: Black | Q25: African American | R25: New York | S25: - | T25: New York | U25: 8 Jul 1783 | V25: Port Roseway | W25: Book of Negroes, British Headquarters Papers PRO 30/55/100; Loyalist evacuation shipping lists (1782–1784) | X25: Loyalist evacuation lists | Y25: Capt. Mowat | Z25: Black | AA25: - | AB25: - | AC25: - | AD25: United States | AG25: =IF(AD25="United States", IFERROR(INDEX(Sheet2!$C:$C, MATCH(AE25&AF25, Sheet2!$E:$E, 0)) & ", " & INDEX(Sheet2!$D:$D, MATCH(AE25&AF25, Sheet2!$E:$E, 0)), ""), "-")
A26: Ann | B26: Betsey Robertson, 46, thin wench, (Capt. Mowat). Formerly slave to Captain Paul Layon, Portsmouth, Virginia; left him with her husband. | C26: Ship Ann bound for Port Roseway Joseph Clark, Master | D26: Betsey | E26: Robertson | F26: 1737 | G26: 208 | H26: 22 | I26: Book One Part One | J26: Joseph Clark | K26: - | L26: - | M26: Barbara | N26: Ogden | O26: Female | P26: Black | Q26: African American | R26: New York | S26: Virginia | T26: New York | U26: Fall 1783 | V26: Port Roseway | W26: Book of Negroes, British Headquarters Papers PRO 30/55/100; Loyalist evacuation shipping lists (1782–1784) | X26: Loyalist evacuation lists | Y26: Capt. Mowat | Z26: Black | AA26: Portsmouth | AB26: - | AC26: Virginia | AD26: United States | AG26: =IF(AD26="United States", IFERROR(INDEX(Sheet2!$C:$C, MATCH(AE26&AF26, Sheet2!$E:$E, 0)) & ", " & INDEX(Sheet2!$D:$D, MATCH(AE26&AF26, Sheet2!$E:$E, 0)), ""), "-")
A27: Ann | B27: James Robertson, 49, thin, pilot by order, (Capt. Mowat). Formerly slave to Captain Paul Layon, Portsmouth, Virginia; left him 4 years ago, employed as a pilot. | C27: Ship Ann bound for Port Roseway Joseph Clark, Master | D27: James | E27: Robertson | F27: 1734 | G27: 207 | H27: 22 | I27: Book One Part One | J27: Joseph Clark | K27: - | L27: - | M27: - | N27: - | O27: Male | P27: Black | Q27: African American | R27: New York | S27: Virginia | T27: New York | U27: 8 Jul 1783 | V27: Port Roseway | W27: Book of Negroes, British Headquarters Papers PRO 30/55/100; Loyalist evacuation shipping lists (1782–1784) | X27: Loyalist evacuation lists | Y27: Capt. Mowat | Z27: Black | AA27: Portsmouth | AB27: - | AC27: Virginia | AD27: United States | AG27: =IF(AD27="United States", IFERROR(INDEX(Sheet2!$C:$C, MATCH(AE27&AF27, Sheet2!$E:$E, 0)) & ", " & INDEX(Sheet2!$D:$D, MATCH(AE27&AF27, Sheet2!$E:$E, 0)), ""), "-")
A28: Ann | B28: William, 14, fine boy. (John Anderson of Port Roseway, claimant.) John Anderson purchased from Hugh Dunn, New York; born nigh Stoney Point. Formerly the property of Edison, taken with a guard of the enemy by a party from the Garrison, 1779. | C28: Ship Ann bound for Port Roseway Joseph Clark, Master | D28: William | E28: - | F28: 1769 | G28: 239 | H28: 22 | I28: Book One Part One | J28: Joseph Clark | K28: - | L28: - | M28: - | N28: - | O28: Child Male | P28: Black | Q28: African American | R28: New York | S28: New York | T28: New York | U28: Fall 1783 | V28: Port Roseway | W28: Book of Negroes, British Headquarters Papers PRO 30/55/100; Loyalist evacuation shipping lists (1782–1784) | X28: Loyalist evacuation lists | Y28: John Anderson of Port Roseway, claimant. | Z28: Black | AA28: New York | AB28: Edison | AC28: Garrison | AD28: United States | AG28: =IF(AD28="United States", IFERROR(INDEX(Sheet2!$C:$C, MATCH(AE28&AF28, Sheet2!$E:$E, 0)) & ", " & INDEX(Sheet2!$D:$D, MATCH(AE28&AF28, Sheet2!$E:$E, 0)), ""), "-")
A29: Ann | B29: Joe Gold, 30, stout black, (Robert Turnbull). Formerly slave to Daniel Descan , about 14 miles from Charlestown, South Carolina; left him 4 years ago. | C29: Ship Ann bound for Port Roseway Joseph Clark, Master | D29: Joe | E29: Gold | F29: 1753 | G29: 240 | H29: 23 | I29: Book One Part One | J29: Joseph Clark | K29: - | L29: - | M29: - | N29: - | O29: Male | P29: Black | Q29: African American | R29: New York | S29: South Carolina | T29: New York | U29: Fall 1783 | V29: Port Roseway | W29: Book of Negroes, British Headquarters Papers PRO 30/55/100; Loyalist evacuation shipping lists (1782–1784) | X29: Loyalist evacuation lists | Y29: Robert Turnbull | Z29: Black | AA29: Charlestown | AB29: - | AC29: South Carolina | AD29: United States | AG29: =IF(AD29="United States", IFERROR(INDEX(Sheet2!$C:$C, MATCH(AE29&AF29, Sheet2!$E:$E, 0)) & ", " & INDEX(Sheet2!$D:$D, MATCH(AE29&AF29, Sheet2!$E:$E, 0)), ""), "-")
A30: Ann | B30: Effie Warner, 33, stout wench & boy 2 yrs, old, (William Hill). Formerly slave to John Matthews, Princess Ann, Virginia; left him 5 years ago. GBC. | C30: Ship Ann bound for Port Roseway Joseph Clark, Master | D30: Effie | E30: Warner | F30: 1750 | G30: 236 | H30: - | I30: Book One Part One | J30: Joseph Clark | K30: - | L30: - | M30: - | N30: - | O30: Child Female | P30: Black | Q30: African American | R30: Princess Ann | S30: Virginia | T30: - | U30: - | V30: Port Roseway | W30: - | X30: - | Y30: William Hill | Z30: Black | AA30: - | AB30: - | AC30: Virginia | AD30: United States | AG30: =IF(AD30="United States", IFERROR(INDEX(Sheet2!$C:$C, MATCH(AE30&AF30, Sheet2!$E:$E, 0)) & ", " & INDEX(Sheet2!$D:$D, MATCH(AE30&AF30, Sheet2!$E:$E, 0)), ""), "-")
A31: Ann | B31: Sukey her daughter, 12, thin mulatto girl, (Robert Turnbull). Formerly slave to Mrs. Harriet Crook, Savannah, Georgia; left that place 5 years ago. | C31: Ship Ann bound for Port Roseway Joseph Clark, Master | D31: Sukey | E31: her daughter | F31: 1771 | G31: 242 | H31: 23 | I31: Book One Part One | J31: Joseph Clark | K31: - | L31: - | M31: Betsey | N31: his wife | O31: Child Female | P31: Mulatto | Q31: Mixed Race | R31: New York | S31: Georgia | T31: New York | U31: Fall 1783 | V31: Port Roseway | W31: Book of Negroes, British Headquarters Papers PRO 30/55/100; Loyalist evacuation shipping lists (1782–1784) | X31: Loyalist evacuation lists | Y31: Robert Turnbull | Z31: Mulatto | AA31: Savannah | AB31: - | AC31: Georgia | AD31: United States | AG31: =IF(AD31="United States", IFERROR(INDEX(Sheet2!$C:$C, MATCH(AE31&AF31, Sheet2!$E:$E, 0)) & ", " & INDEX(Sheet2!$D:$D, MATCH(AE31&AF31, Sheet2!$E:$E, 0)), ""), "-")
A32: Ann | B32: James Jackson 50, thin, goes as pilot (Capt. Mowat). Formerly slave to late Robert Tucker, Norfolk, Virginia; left him with Lord Dunmore when he left that country & was employed as a pilot. | C32: Ship Ann bound for Port Roseway Joseph Clark, Master | D32: James | E32: Jackson 50 | F32: 1733 | G32: 210 | H32: 22 | I32: Book One Part One | J32: Joseph Clark | K32: - | L32: - | M32: - | N32: - | O32: Male | P32: Black | Q32: African American | R32: New York | S32: Virginia | T32: New York | U32: 8 Jul 1783 | V32: Port Roseway | W32: Book of Negroes, British Headquarters Papers PRO 30/55/100; Loyalist evacuation shipping lists (1782–1784) | X32: Loyalist evacuation lists | Y32: Capt. Mowat | Z32: Black | AA32: Norfolk | AB32: - | AC32: Virginia | AD32: United States | AG32: =IF(AD32="United States", IFERROR(INDEX(Sheet2!$C:$C, MATCH(AE32&AF32, Sheet2!$E:$E, 0)) & ", " & INDEX(Sheet2!$D:$D, MATCH(AE32&AF32, Sheet2!$E:$E, 0)), ""), "-")
A33: Ann | B33: Elizabeth Mitchell, 13, stout girl, (Lt. Clows, Guides & Pioneers). Says she was born free near Charlestown, South Carolina; joined the Army in 1780. | C33: Ann bound for St. John's Clark | D33: Elizabeth | E33: Mitchell | F33: 1770 | G33: 1946 | H33: 61 | I33: Book One Part Two | J33: Clark | K33: - | L33: - | M33: - | N33: - | O33: Child Female | P33: Black | Q33: African American | R33: New York | S33: South Carolina | T33: New York | U33: Fall 1783 | V33: St. John's | W33: Book of Negroes, British Headquarters Papers PRO 30/55/100; Loyalist evacuation shipping lists (1782–1784) | X33: Loyalist evacuation lists | Y33: Lt. Clows, Guides & Pioneers | Z33: Black | AA33: Charlestown | AB33: - | AC33: South Carolina | AD33: United States | AG33: =IF(AD33="United States", IFERROR(INDEX(Sheet2!$C:$C, MATCH(AE33&AF33, Sheet2!$E:$E, 0)) & ", " & INDEX(Sheet2!$D:$D, MATCH(AE33&AF33, Sheet2!$E:$E, 0)), ""), "-")
A34: Ann | B34: Dick Vincent, 10, stout boy, (Ens. Vincent). Formerly slave to Charles Vincent, East Chester, grandfather to the Ensign who has delivered the boy to the said Ensign. | C34: Ann bound for St. John's Clark | D34: Dick | E34: Vincent | F34: 1773 | G34: 1947 | H34: 22 | I34: Book One Part Two | J34: Clark | K34: - | L34: - | M34: - | N34: - | O34: Child Male | P34: Black | Q34: African American | R34: New York | S34: - | T34: New York | U34: Fall 1783 | V34: St. John's | W34: Book of Negroes, British Headquarters Papers PRO 30/55/100; Loyalist evacuation shipping lists (1782–1784) | X34: Loyalist evacuation lists | Y34: Ens. Vincent | Z34: Black | AA34: - | AB34: - | AC34: East Chester | AD34: United States | AG34: =IF(AD34="United States", IFERROR(INDEX(Sheet2!$C:$C, MATCH(AE34&AF34, Sheet2!$E:$E, 0)) & ", " & INDEX(Sheet2!$D:$D, MATCH(AE34&AF34, Sheet2!$E:$E, 0)), ""), "-")
A35: Ann | D35: child of | E35: Abigail | F35: - | G35: 250 | H35: 22 | J35: Joseph Clark | O35: c | R35: New York | T35: New York | U35: Fall 1783 | V35: Port Roseway | W35: Book of Negroes, British Headquarters Papers PRO 30/55/100; Loyalist evacuation shipping lists (1782–1784) | X35: Loyalist evacuation lists | Y35: - | AA35: - | AB35: - | AC35: - | AD35: United States | AG35: =IF(AD35="United States", IFERROR(INDEX(Sheet2!$C:$C, MATCH(AE35&AF35, Sheet2!$E:$E, 0)) & ", " & INDEX(Sheet2!$D:$D, MATCH(AE35&AF35, Sheet2!$E:$E, 0)), ""), "-")
A36: Ann | D36: Betsey his | E36: wife | F36: 1750 | G36: 263 | H36: 23 | J36: Joseph Clark | O36: Female | R36: New York | T36: New York | U36: Fall 1783 | V36: Port Roseway | W36: Book of Negroes, British Headquarters Papers PRO 30/55/100; Loyalist evacuation shipping lists (1782–1784) | X36: Loyalist evacuation lists | Y36: - | AA36: - | AB36: - | AC36: - | AD36: United States | AG36: =IF(AD36="United States", IFERROR(INDEX(Sheet2!$C:$C, MATCH(AE36&AF36, Sheet2!$E:$E, 0)) & ", " & INDEX(Sheet2!$D:$D, MATCH(AE36&AF36, Sheet2!$E:$E, 0)), ""), "-")
A37: Ann | D37: Sukey her | E37: daughter | F37: 1771 | G37: 264 | H37: 23 | J37: Joseph Clark | O37: Child Female | R37: New York | T37: New York | U37: Fall 1783 | V37: Port Roseway | W37: Book of Negroes, British Headquarters Papers PRO 30/55/100; Loyalist evacuation shipping lists (1782–1784) | X37: Loyalist evacuation lists | Y37: - | AA37: - | AB37: - | AC37: - | AD37: United States | AG37: =IF(AD37="United States", IFERROR(INDEX(Sheet2!$C:$C, MATCH(AE37&AF37, Sheet2!$E:$E, 0)) & ", " & INDEX(Sheet2!$D:$D, MATCH(AE37&AF37, Sheet2!$E:$E, 0)), ""), "-")
A38: Ann | B38: Betsey his wife, 33, stout mulatto wench, (Robert Turnbull). Formerly slave to Mrs. Harriet Crook, Savannah, Georgia; left that place 5 years ago. | C38: Ship Ann bound for Port Roseway Joseph Clark, Master | D38: Betsey | E38: his wife | F38: 1750 | G38: 241 | H38: 22 | I38: Book One Part One | J38: Joseph Clark | K38: - | L38: - | M38: - | N38: - | O38: Female | P38: Mulatto | Q38: Mixed Race | R38: New York | S38: Georgia | T38: New York | U38: Fall 1783 | V38: Port Roseway | W38: Book of Negroes, British Headquarters Papers PRO 30/55/100; Loyalist evacuation shipping lists (1782–1784) | X38: Loyalist evacuation lists | Y38: Robert Turnbull | Z38: Mulatto | AA38: Savannah | AB38: - | AC38: Georgia | AD38: United States | AG38: =IF(AD38="United States", IFERROR(INDEX(Sheet2!$C:$C, MATCH(AE38&AF38, Sheet2!$E:$E, 0)) & ", " & INDEX(Sheet2!$D:$D, MATCH(AE38&AF38, Sheet2!$E:$E, 0)), ""), "-")
A39: Ann | B39: Judith Jackson, 24, thin wench, mulatto, (Capt. Mowat). Says she served her time to John Bell at Cape Fear and left that with the army of Sir H. Clinton in 1776. | C39: Ship Ann bound for Port Roseway Joseph Clark, Master | D39: Judith | E39: Jackson | F39: 1759 | G39: 211 | H39: 22 | I39: Book One Part One | J39: Joseph Clark | K39: - | L39: - | M39: Betsey | N39: Robertson | O39: Female | P39: Mulatto | Q39: Mixed Race | R39: New York | S39: - | T39: New York | U39: Fall 1783 | V39: Port Roseway | W39: Book of Negroes, British Headquarters Papers PRO 30/55/100; Loyalist evacuation shipping lists (1782–1784) | X39: Loyalist evacuation lists | Y39: Capt. Mowat | Z39: Mulatto | AA39: - | AB39: - | AC39: - | AD39: United States | AG39: =IF(AD39="United States", IFERROR(INDEX(Sheet2!$C:$C, MATCH(AE39&AF39, Sheet2!$E:$E, 0)) & ", " & INDEX(Sheet2!$D:$D, MATCH(AE39&AF39, Sheet2!$E:$E, 0)), ""), "-")
A40: Ann | B40: Harry Jackson, 8, good L boy, (Capt. Mowat). | C40: Ship Ann bound for Port Roseway Joseph Clark, Master | D40: Harry | E40: Jackson | F40: 1775 | G40: 212 | H40: 22 | I40: Book One Part One | J40: Joseph Clark | K40: - | L40: - | M40: - | N40: - | O40: Child Male | P40: Black | Q40: African American | R40: New York | S40: - | T40: New York | U40: Fall 1783 | V40: Port Roseway | W40: Book of Negroes, British Headquarters Papers PRO 30/55/100; Loyalist evacuation shipping lists (1782–1784) | X40: Loyalist evacuation lists | Y40: Capt. Mowat | Z40: Black | AA40: - | AB40: - | AC40: - | AD40: United States | AG40: =IF(AD40="United States", IFERROR(INDEX(Sheet2!$C:$C, MATCH(AE40&AF40, Sheet2!$E:$E, 0)) & ", " & INDEX(Sheet2!$D:$D, MATCH(AE40&AF40, Sheet2!$E:$E, 0)), ""), "-")
...

Sheet Sheet2
A1: County | B1: State | C1: lat | D1: lng | E1: LookupKey | J1: AK
A2: Aleutians East | B2: AK | C2: 55.3669 | D2: -161.9805 | E2: AKAleutians East | J2: AL
A3: Aleutians West | B3: AK | C3: 52.7985 | D3: -106.5633 | E3: AKAleutians West | J3: AR
A4: Anchorage | B4: AK | C4: 61.1498 | D4: -149.1082 | E4: AKAnchorage | J4: AZ
A5: Bethel | B5: AK | C5: 60.9132 | D5: -159.8186 | E5: AKBethel | J5: CA
A6: Bristol Bay | B6: AK | C6: 58.7431 | D6: -156.7015 | E6: AKBristol Bay | J6: CO
A7: Chugach | B7: AK | C7: 60.7233 | D7: -145.7583 | E7: AKChugach | J7: CT
A8: Copper River | B8: AK | C8: 61.8855 | D8: -143.97 | E8: AKCopper River | J8: DC
A9: Denali | B9: AK | C9: 63.6714 | D9: -150.0118 | E9: AKDenali | J9: DE
A10: Dillingham | B10: AK | C10: 59.8003 | D10: -158.2346 | E10: AKDillingham | J10: FL
A11: Fairbanks North Star | B11: AK | C11: 64.8078 | D11: -146.5654 | E11: AKFairbanks North Star | J11: GA
A12: Haines | B12: AK | C12: 59.1186 | D12: -135.5007 | E12: AKHaines | J12: HI
A13: Hoonah-Angoon | B13: AK | C13: 58.287 | D13: -135.6393 | E13: AKHoonah-Angoon | J13: IA
... A51: Covington | B51: AL | C51: 31.2485 | D51: -86.4513 | E51: ALCovington | J51: WY
A52: Crenshaw | B52: AL | C52: 31.7315 | D52: -86.3136 | E52: ALCrenshaw
A53: Cullman | B53: AL | C53: 34.1319 | D53: -86.8676 | E53: ALCullman
A54: Dale | B54: AL | C54: 31.4318 | D54: -85.611 | E54: ALDale
A55: Dallas | B55: AL | C55: 32.326 | D55: -87.1065 | E55: ALDallas
A56: DeKalb | B56: AL | C56: 34.4598 | D56: -85.8041 | E56: ALDeKalb
A57: Elmore | B57: AL | C57: 32.5966 | D57: -86.1492 | E57: ALElmore
A58: Escambia | B58: AL | C58: 31.1261 | D58: -87.1615 | E58: ALEscambia
A59: Etowah | B59: AL | C59: 34.0453 | D59: -86.0348 | E59: ALEtowah
A60: Fayette | B60: AL | C60: 33.7212 | D60: -87.7388 | E60: ALFayette
A61: Franklin | B61: AL | C61: 34.4417 | D61: -87.8437 | E61: ALFranklin
A62: Geneva | B62: AL | C62: 31.095 | D62: -85.8391 | E62: ALGeneva
A63: Greene | B63: AL | C63: 32.8531 | D63: -87.9522 | E63: ALGreene
... A3145: Weston | B3145: WY | C3145: 43.8404 | D3145: -104.5677 | E3145: WYWeston
