Workbook

Sheet Main
A1: First_Name | B1: Surname | C1: Father_FirstName | D1: Father_Surname | E1: Mother_FirstName | F1: Mother_Surname | G1: Gender | H1: Age | I1: Birthdate | J1: Race | K1: Ethnicity | L1: Origin | M1: Extracted_City | N1: Extracted_County | O1: Extracted_State | P1: State | Q1: County | R1: Coordinates | S1: Origination_Port | T1: Origination_State | U1: Departure_Port | V1: Departure_Date | W1: Arrival_Port_City | X1: Arrival_County | Y1: Arrival_State | Z1: Primary_Source_1 | AA1: Primary_Source_2 | AB1: Notes | AC1: Country | AD1: ID | AE1: Ref_Page | AF1: Book | AG1: Ship_Name | AH1: Commander | AI1: Ship_Notes
A2: William | B2: Johnson | C2: - | D2: - | E2: - | F2: - | G2: Male | H2: 21 | I2: 1762 | J2: Black | K2: African American | L2: Black | M2: Ann County | N2: - | O2: Virginia | R2: =IFERROR(INDEX(Sheet2!$C:$C, MATCH(P2&Q2, Sheet2!$E:$E, 0)) & ", " & INDEX(Sheet2!$D:$D, MATCH(P2&Q2, Sheet2!$E:$E, 0)), "-") -> - | S2: Formerly slave to John Chapman of Princess Ann County | T2: Virginia | U2: - | V2: - | W2: River St. John's | Y2: Canada | Z2: - | AA2: - | AB2: William Johnson, 21, stout likely fellow, (Lt. Richard Holland). Formerly slave to John Chapman of Princess Ann County, Virginia; left him 4 years. | AD2: 744 | AE2: - | AF2: Book One Part One | AG2: 3 Friends | AH2: John Stewart | AI2: Sloop 3 Friends bound for River St. John's John Stewart, Master
A3: Sally | B3: her child | C3: - | D3: - | E3: Elizabeth | F3: Merrick | G3: Child Male | H3: 8 | I3: 1775 | J3: Black | K3: African American | L3: Black | M3: - | N3: - | O3: - | R3: =IFERROR(INDEX(Sheet2!$C:$C, MATCH(P3&Q3, Sheet2!$E:$E, 0)) & ", " & INDEX(Sheet2!$D:$D, MATCH(P3&Q3, Sheet2!$E:$E, 0)), "-") -> - | S3: - | T3: - | U3: - | V3: - | W3: River St. John's | Y3: Canada | Z3: - | AA3: - | AB3: Sally her child, 8 mo. | AD3: 746 | AE3: - | AF3: Book One Part One | AG3: 3 Friends | AH3: John Stewart | AI3: Sloop 3 Friends bound for River St. John's John Stewart, Master
A4: Elizabeth | B4: Merrick | C4: - | D4: - | E4: - | F4: - | G4: Female | H4: 27 | I4: 1756 | J4: Black | K4: African American | L4: Black | M4: Newtown | N4: - | O4: Long Island | R4: =IFERROR(INDEX(Sheet2!$C:$C, MATCH(P4&Q4, Sheet2!$E:$E, 0)) & ", " & INDEX(Sheet2!$D:$D, MATCH(P4&Q4, Sheet2!$E:$E, 0)), "-") -> - | S4: - | T4: - | U4: - | V4: - | W4: River St. John's | Y4: Canada | Z4: - | AA4: - | AB4: Elizabeth Merrick, 27, stout wench, M, (Luther Hatheway). Born free; served her time with Lambert Woodward of Newtown, Long Island. | AD4: 743 | AE4: - | AF4: Book One Part One | AG4: 3 Friends | AH4: John Stewart | AI4: Sloop 3 Friends bound for River St. John's John Stewart, Master
A5: Richard | B5: Merrick | C5: Tom | D5: Gunn | E5: - | F5: - | G5: Male | H5: 32 | I5: 1751 | J5: Black | K5: African American | L5: Black | M5: Springfield | N5: - | O5: Massachusetts | R5: =IFERROR(INDEX(Sheet2!$C:$C, MATCH(P5&Q5, Sheet2!$E:$E, 0)) & ", " & INDEX(Sheet2!$D:$D, MATCH(P5&Q5, Sheet2!$E:$E, 0)), "-") -> - | S5: - | T5: - | U5: - | V5: - | W5: River St. John's | Y5: Canada | Z5: - | AA5: - | AB5: Richard Merrick, 32, stout likely fellow, (Sam Wilson). Formerly slave to Samuel Merrick of Springfield, Massachusetts, who gave him his freedom & produced a Certificate dated 4 November 74, signed by Merrick, Philips & Dr. White. | AD5: 742 | AE5: - | AF5: Book One Part One | AG5: 3 Friends | AH5: John Stewart | AI5: Sloop 3 Friends bound for River St. John's John Stewart, Master
A6: Tom | B6: Gunn | C6: - | D6: - | E6: - | F6: - | G6: Male | H6: 43 | I6: 1740 | J6: Black | K6: African American | L6: Black | M6: Waterbury | N6: - | O6: Connecticut | R6: =IFERROR(INDEX(Sheet2!$C:$C, MATCH(P6&Q6, Sheet2!$E:$E, 0)) & ", " & INDEX(Sheet2!$D:$D, MATCH(P6&Q6, Sheet2!$E:$E, 0)), "-") -> - | S6: - | T6: - | U6: - | V6: - | W6: River St. John's | Y6: Canada | Z6: - | AA6: - | AB6: Tom Gunn, 43, stout, pockmarked, (Sam Wilson). Formerly slave to Enos Gunn of Waterbury, Connecticut. | AD6: 741 | AE6: - | AF6: Book One Part One | AG6: 3 Friends | AH6: John Stewart | AI6: Sloop 3 Friends bound for River St. John's John Stewart, Master
A7: Hannah | B7: and | C7: - | D7: - | E7: - | F7: - | G7: Child Female | H7: 16 | I7: 1767 | J7: Black | K7: African American | L7: Black | M7: - | N7: - | O7: Long Island | R7: =IFERROR(INDEX(Sheet2!$C:$C, MATCH(P7&Q7, Sheet2!$E:$E, 0)) & ", " & INDEX(Sheet2!$D:$D, MATCH(P7&Q7, Sheet2!$E:$E, 0)), "-") -> - | S7: - | T7: - | U7: - | V7: - | W7: River St. John's | Y7: Canada | Z7: - | AA7: - | AB7: Hannah and, 16, stout wench, (Lt. Richard Holland). Born free in Cow Neck, Long Island, lived with Caleb Merrill till within this last year. | AD7: 745 | AE7: - | AF7: Book One Part One | AG7: 3 Friends | AH7: John Stewart | AI7: Sloop 3 Friends bound for River St. John's John Stewart, Master
A8: 18 | B8: September | G8: Male | H8: 18 | I8: 1765 | J8: Black | K8: African American | L8: Black | M8: - | N8: - | O8: - | R8: =IFERROR(INDEX(Sheet2!$C:$C, MATCH(P8&Q8, Sheet2!$E:$E, 0)) & ", " & INDEX(Sheet2!$D:$D, MATCH(P8&Q8, Sheet2!$E:$E, 0)), "-") -> - | W8: Quebec John Wardell | Y8: Canada | AB8: 18 September | AD8: 2716 | AF8: Book One Part Two | AG8: 3 Sisters | AH8: - | AI8: 3 Sisters bound for Quebec John Wardell
A9: Cairo | B9: - | C9: - | D9: - | E9: - | F9: - | G9: Female | H9: 20 | I9: 1763 | J9: Black | K9: African American | L9: Black | M9: - | N9: - | O9: Cairo | R9: =IFERROR(INDEX(Sheet2!$C:$C, MATCH(P9&Q9, Sheet2!$E:$E, 0)) & ", " & INDEX(Sheet2!$D:$D, MATCH(P9&Q9, Sheet2!$E:$E, 0)), "-") -> - | S9: New York | T9: - | U9: New York | V9: Fall 1783 | W9: St. John's | Y9: Canada | Z9: Book of Negroes, British Headquarters Papers PRO 30/55/100; Loyalist evacuation shipping lists (1782–1784) | AA9: Loyalist evacuation lists | AB9: Cairo, 20, stout wench, (James Peters). Property of James Petes. | AD9: 2254 | AE9: 70 | AF9: Book Two | AG9: Alexander | AH9: Roger Alderson | AI9: Alexander bound for St. John's Roger Alderson
A10: Bella | B10: - | C10: - | D10: - | E10: - | F10: - | G10: Child Female | H10: 14 | I10: 1769 | J10: Black | K10: African American | L10: Black | M10: - | N10: - | O10: - | R10: =IFERROR(INDEX(Sheet2!$C:$C, MATCH(P10&Q10, Sheet2!$E:$E, 0)) & ", " & INDEX(Sheet2!$D:$D, MATCH(P10&Q10, Sheet2!$E:$E, 0)), "-") -> - | S10: New York | T10: - | U10: New York | V10: Fall 1783 | W10: St. John's | Y10: Canada | Z10: Book of Negroes, British Headquarters Papers PRO 30/55/100; Loyalist evacuation shipping lists (1782–1784) | AA10: Loyalist evacuation lists | AB10: Bella, 14, stout wench, (James Peters). Property of James Peters. | AD10: 2255 | AE10: 70 | AF10: Book Two | AG10: Alexander | AH10: Roger Alderson | AI10: Alexander bound for St. John's Roger Alderson
A11: Esther | B11: - | C11: - | D11: - | E11: - | F11: - | G11: Female | H11: 18 | I11: 1765 | J11: Black | K11: African American | L11: Black | M11: - | N11: - | O11: Esther | R11: =IFERROR(INDEX(Sheet2!$C:$C, MATCH(P11&Q11, Sheet2!$E:$E, 0)) & ", " & INDEX(Sheet2!$D:$D, MATCH(P11&Q11, Sheet2!$E:$E, 0)), "-") -> - | S11: New York | T11: - | U11: New York | V11: Fall 1783 | W11: St. John's | Y11: Canada | Z11: Book of Negroes, British Headquarters Papers PRO 30/55/100; Loyalist evacuation shipping lists (1782–1784) | AA11: Loyalist evacuation lists | AB11: Esther, 18, stout wench, M, (Bartholomew Cranell). Property of Bartholomew Crannell. | AD11: 2256 | AE11: 70 | AF11: Book Two | AG11: Alexander | AH11: Roger Alderson | AI11: Alexander bound for St. John's Roger Alderson
A12: Robert | B12: - | C12: - | D12: - | E12: - | F12: - | G12: Male | H12: 36 | I12: 1747 | J12: Black | K12: African American | L12: Black | M12: - | N12: - | O12: - | R12: =IFERROR(INDEX(Sheet2!$C:$C, MATCH(P12&Q12, Sheet2!$E:$E, 0)) & ", " & INDEX(Sheet2!$D:$D, MATCH(P12&Q12, Sheet2!$E:$E, 0)), "-") -> - | S12: New York | T12: - | U12: New York | V12: Fall 1783 | W12: St. John's | Y12: Canada | Z12: Book of Negroes, British Headquarters Papers PRO 30/55/100; Loyalist evacuation shipping lists (1782–1784) | AA12: Loyalist evacuation lists | AB12: Robert, 36, stout fellow, (Bartholomew Crannell). Formerly slave to Isaac Conklin, 9 Partners; left him 2 years ago. | AD12: 2258 | AE12: 70 | AF12: Book Two | AG12: Alexander | AH12: Roger Alderson | AI12: Alexander bound for St. John's Roger Alderson
A13: Pompey | B13: - | C13: - | D13: - | E13: - | F13: - | G13: Male | H13: 25 | I13: 1758 | J13: Black | K13: African American | L13: Black | M13: - | N13: - | O13: - | R13: =IFERROR(INDEX(Sheet2!$C:$C, MATCH(P13&Q13, Sheet2!$E:$E, 0)) & ", " & INDEX(Sheet2!$D:$D, MATCH(P13&Q13, Sheet2!$E:$E, 0)), "-") -> - | S13: New York | T13: - | U13: New York | V13: Fall 1783 | W13: St. John's | Y13: Canada | Z13: Book of Negroes, British Headquarters Papers PRO 30/55/100; Loyalist evacuation shipping lists (1782–1784) | AA13: Loyalist evacuation lists | AB13: Pompey, 25, stout fellow, on his own bottom. Born free. | AD13: 2259 | AE13: 70 | AF13: Book Two | AG13: Alexander | AH13: Roger Alderson | AI13: Alexander bound for St. John's Roger Alderson
A14: Sam | B14: - | C14: - | D14: - | E14: - | F14: - | G14: Male | H14: 35 | I14: 1748 | J14: Black | K14: African American | L14: Black | M14: - | N14: - | O14: - | R14: =IFERROR(INDEX(Sheet2!$C:$C, MATCH(P14&Q14, Sheet2!$E:$E, 0)) & ", " & INDEX(Sheet2!$D:$D, MATCH(P14&Q14, Sheet2!$E:$E, 0)), "-") -> - | S14: New York | T14: - | U14: New York | V14: Fall 1783 | W14: St. John's | Y14: Canada | Z14: Book of Negroes, British Headquarters Papers PRO 30/55/100; Loyalist evacuation shipping lists (1782–1784) | AA14: Loyalist evacuation lists | AB14: Sam, 35, (Bartholomew Cranell). Property of Bartholomew Crannell. | AD14: 2257 | AE14: 70 | AF14: Book Two | AG14: Alexander | AH14: Roger Alderson | AI14: Alexander bound for St. John's Roger Alderson
A15: Job | B15: State | G15: Male | H15: 24 | I15: 1759 | M15: - | N15: - | O15: - | R15: =IFERROR(INDEX(Sheet2!$C:$C, MATCH(P15&Q15, Sheet2!$E:$E, 0)) & ", " & INDEX(Sheet2!$D:$D, MATCH(P15&Q15, Sheet2!$E:$E, 0)), "-") -> - | S15: New York | U15: New York | V15: 16 Jun 1783 | W15: St. Johns | Y15: Canada | Z15: Book of Negroes, British Headquarters Papers PRO 30/55/100; Loyalist evacuation shipping lists (1782–1784) | AA15: Loyalist evacuation lists | AD15: 742 | AE15: 35 | AG15: Amities Production | AH15: Thomas Reid
A16: William | B16: Holchapan | G16: Male | H16: 40 | I16: 1743 | M16: - | N16: - | O16: - | R16: =IFERROR(INDEX(Sheet2!$C:$C, MATCH(P16&Q16, Sheet2!$E:$E, 0)) & ", " & INDEX(Sheet2!$D:$D, MATCH(P16&Q16, Sheet2!$E:$E, 0)), "-") -> - | S16: New York | U16: New York | V16: 16 Jun 1783 | W16: St. Johns | Y16: Canada | Z16: Book of Negroes, British Headquarters Papers PRO 30/55/100; Loyalist evacuation shipping lists (1782–1784) | AA16: Loyalist evacuation lists | AD16: 743 | AE16: 35 | AG16: Amities Production | AH16: Thomas Reid
A17: George | B17: State | G17: Male | H17: 25 | I17: 1758 | M17: - | N17: - | O17: - | R17: =IFERROR(INDEX(Sheet2!$C:$C, MATCH(P17&Q17, Sheet2!$E:$E, 0)) & ", " & INDEX(Sheet2!$D:$D, MATCH(P17&Q17, Sheet2!$E:$E, 0)), "-") -> - | S17: New York | U17: New York | V17: 16 Jun 1783 | W17: St. Johns | Y17: Canada | Z17: Book of Negroes, British Headquarters Papers PRO 30/55/100; Loyalist evacuation shipping lists (1782–1784) | AA17: Loyalist evacuation lists | AD17: 740 | AE17: 35 | AG17: Amities Production | AH17: Thomas Reid
A18: Mary | B18: State | G18: Female | H18: 21 | I18: 1762 | M18: - | N18: - | O18: - | R18: =IFERROR(INDEX(Sheet2!$C:$C, MATCH(P18&Q18, Sheet2!$E:$E, 0)) & ", " & INDEX(Sheet2!$D:$D, MATCH(P18&Q18, Sheet2!$E:$E, 0)), "-") -> - | S18: New York | U18: New York | V18: 16 Jun 1783 | W18: St. Johns | Y18: Canada | Z18: Book of Negroes, British Headquarters Papers PRO 30/55/100; Loyalist evacuation shipping lists (1782–1784) | AA18: Loyalist evacuation lists | AD18: 741 | AE18: 35 | AG18: Amities Production | AH18: Thomas Reid
A19: William | B19: Stepney | G19: Male | H19: 24 | I19: 1759 | M19: - | N19: - | O19: - | R19: =IFERROR(INDEX(Sheet2!$C:$C, MATCH(P19&Q19, Sheet2!$E:$E, 0)) & ", " & INDEX(Sheet2!$D:$D, MATCH(P19&Q19, Sheet2!$E:$E, 0)), "-") -> - | S19: New York | U19: New York | V19: 16 Jun 1783 | W19: St. Johns | Y19: Canada | Z19: Book of Negroes, British Headquarters Papers PRO 30/55/100; Loyalist evacuation shipping lists (1782–1784) | AA19: Loyalist evacuation lists | AD19: 739 | AE19: 35 | AG19: Amities Production | AH19: Thomas Reid
A20: William | B20: Holchapan | C20: - | D20: - | E20: - | F20: - | G20: Male | H20: 40 | I20: 1743 | J20: Black | K20: African American | L20: Black | M20: St. Paul's | N20: - | O20: London | R20: =IFERROR(INDEX(Sheet2!$C:$C, MATCH(P20&Q20, Sheet2!$E:$E, 0)) & ", " & INDEX(Sheet2!$D:$D, MATCH(P20&Q20, Sheet2!$E:$E, 0)), "-") -> - | S20: - | T20: - | U20: - | V20: - | W20: St. John's | Y20: Canada | Z20: - | AA20: - | AB20: William Holchapan, 40, stout fellow, M, (on his own bottom). Born free and baptized in the year 1779 in the Parish of St. Paul's, London. | AD20: 678 | AE20: - | AF20: Book One Part One | AG20: Amity's Production | AH20: Thomas Reid | AI20: Amity's Production bound for St. John's Thomas Reid, Master
A21: Job | B21: State | C21: - | D21: - | E21: - | F21: - | G21: Male | H21: 24 | I21: 1759 | J21: Black | K21: African American | L21: Black | M21: - | N21: - | O21: New York | R21: =IFERROR(INDEX(Sheet2!$C:$C, MATCH(P21&Q21, Sheet2!$E:$E, 0)) & ", " & INDEX(Sheet2!$D:$D, MATCH(P21&Q21, Sheet2!$E:$E, 0)), "-") -> - | S21: - | T21: New York | U21: - | V21: - | W21: St. John's | Y21: Canada | Z21: - | AA21: - | AB21: Job State, 24, stout fellow, M, (on his own bottom). Born free at New York. | AD21: 677 | AE21: - | AF21: Book One Part One | AG21: Amity's Production | AH21: Thomas Reid | AI21: Amity's Production bound for St. John's Thomas Reid, Master
A22: Mary | B22: State | C22: - | D22: - | E22: - | F22: - | G22: Male | H22: 21 | I22: 1762 | J22: Half Indian | K22: Mixed Race | L22: Mulatto | M22: - | N22: - | O22: Long Island | R22: =IFERROR(INDEX(Sheet2!$C:$C, MATCH(P22&Q22, Sheet2!$E:$E, 0)) & ", " & INDEX(Sheet2!$D:$D, MATCH(P22&Q22, Sheet2!$E:$E, 0)), "-") -> - | S22: - | T22: - | U22: - | V22: - | W22: St. John's | Y22: Canada | Z22: - | AA22: - | AB22: Mary State, 21, half Indian, (on her own bottom). Born free on Long Island. | AD22: 676 | AE22: - | AF22: Book One Part One | AG22: Amity's Production | AH22: Thomas Reid | AI22: Amity's Production bound for St. John's Thomas Reid, Master
A23: George | B23: State | C23: - | D23: - | E23: - | F23: - | G23: Male | H23: 25 | I23: 1758 | J23: Black | K23: African American | L23: Black | M23: - | N23: - | O23: New York | R23: =IFERROR(INDEX(Sheet2!$C:$C, MATCH(P23&Q23, Sheet2!$E:$E, 0)) & ", " & INDEX(Sheet2!$D:$D, MATCH(P23&Q23, Sheet2!$E:$E, 0)), "-") -> - | S23: - | T23: New York | U23: - | V23: - | W23: St. John's | Y23: Canada | Z23: - | AA23: - | AB23: George State, 25, stout fellow, M, (on his own bottom). Born free at New York. | AD23: 675 | AE23: - | AF23: Book One Part One | AG23: Amity's Production | AH23: Thomas Reid | AI23: Amity's Production bound for St. John's Thomas Reid, Master
A24: William | B24: Stepney | C24: - | D24: - | E24: - | F24: - | G24: Male | H24: 24 | I24: 1759 | J24: Black | K24: African American | L24: Black | M24: - | N24: - | O24: - | R24: =IFERROR(INDEX(Sheet2!$C:$C, MATCH(P24&Q24, Sheet2!$E:$E, 0)) & ", " & INDEX(Sheet2!$D:$D, MATCH(P24&Q24, Sheet2!$E:$E, 0)), "-") -> - | S24: - | T24: - | U24: - | V24: - | W24: St. John's | Y24: Canada | Z24: - | AA24: - | AB24: William Stepney, 24, stout fellow, B, (on his own bottom). Born free at St. Augustine. | AD24: 674 | AE24: - | AF24: Book One Part One | AG24: Amity's Production | AH24: Thomas Reid | AI24: Amity's Production bound for St. John's Thomas Reid, Master
A25: James | B25: Robertson | C25: - | D25: - | E25: - | F25: - | G25: Child Male | H25: 2½ | I25: - | J25: Black | K25: African American | L25: Black | M25: - | N25: - | O25: - | R25: =IFERROR(INDEX(Sheet2!$C:$C, MATCH(P25&Q25, Sheet2!$E:$E, 0)) & ", " & INDEX(Sheet2!$D:$D, MATCH(P25&Q25, Sheet2!$E:$E, 0)), "-") -> - | S25: New York | T25: - | U25: New York | V25: 8 Jul 1783 | W25: Port Roseway | Y25: Canada | Z25: Book of Negroes, British Headquarters Papers PRO 30/55/100; Loyalist evacuation shipping lists (1782–1784) | AA25: Loyalist evacuation lists | AB25: James Robertson, 2½, small boy, (Capt. Mowat). | AD25: 209 | AE25: 22 | AF25: Book One Part One | AG25: Ann | AH25: Joseph Clark | AI25: Ship Ann bound for Port Roseway Joseph Clark, Master
A26: Betsey | B26: Robertson | C26: - | D26: - | E26: Barbara | F26: Ogden | G26: Female | H26: 46 | I26: 1737 | J26: Black | K26: African American | L26: Black | M26: Portsmouth | N26: - | O26: Virginia | R26: =IFERROR(INDEX(Sheet2!$C:$C, MATCH(P26&Q26, Sheet2!$E:$E, 0)) & ", " & INDEX(Sheet2!$D:$D, MATCH(P26&Q26, Sheet2!$E:$E, 0)), "-") -> - | S26: New York | T26: Virginia | U26: New York | V26: Fall 1783 | W26: Port Roseway | Y26: Canada | Z26: Book of Negroes, British Headquarters Papers PRO 30/55/100; Loyalist evacuation shipping lists (1782–1784) | AA26: Loyalist evacuation lists | AB26: Betsey Robertson, 46, thin wench, (Capt. Mowat). Formerly slave to Captain Paul Layon, Portsmouth, Virginia; left him with her husband. | AD26: 208 | AE26: 22 | AF26: Book One Part One | AG26: Ann | AH26: Joseph Clark | AI26: Ship Ann bound for Port Roseway Joseph Clark, Master
A27: James | B27: Robertson | C27: - | D27: - | E27: - | F27: - | G27: Male | H27: 49 | I27: 1734 | J27: Black | K27: African American | L27: Black | M27: Portsmouth | N27: - | O27: Virginia | R27: =IFERROR(INDEX(Sheet2!$C:$C, MATCH(P27&Q27, Sheet2!$E:$E, 0)) & ", " & INDEX(Sheet2!$D:$D, MATCH(P27&Q27, Sheet2!$E:$E, 0)), "-") -> - | S27: New York | T27: Virginia | U27: New York | V27: 8 Jul 1783 | W27: Port Roseway | Y27: Canada | Z27: Book of Negroes, British Headquarters Papers PRO 30/55/100; Loyalist evacuation shipping lists (1782–1784) | AA27: Loyalist evacuation lists | AB27: James Robertson, 49, thin, pilot by order, (Capt. Mowat). Formerly slave to Captain Paul Layon, Portsmouth, Virginia; left him 4 years ago, employed as a pilot. | AD27: 207 | AE27: 22 | AF27: Book One Part One | AG27: Ann | AH27: Joseph Clark | AI27: Ship Ann bound for Port Roseway Joseph Clark, Master
A28: William | B28: - | C28: - | D28: - | E28: - | F28: - | G28: Child Male | H28: 14 | I28: 1769 | J28: Black | K28: African American | L28: Black | M28: Hugh Dunn | N28: New York | O28: Garrison | R28: =IFERROR(INDEX(Sheet2!$C:$C, MATCH(P28&Q28, Sheet2!$E:$E, 0)) & ", " & INDEX(Sheet2!$D:$D, MATCH(P28&Q28, Sheet2!$E:$E, 0)), "-") -> - | S28: New York | T28: New York | U28: New York | V28: Fall 1783 | W28: Port Roseway | Y28: Canada | Z28: Book of Negroes, British Headquarters Papers PRO 30/55/100; Loyalist evacuation shipping lists (1782–1784) | AA28: Loyalist evacuation lists | AB28: William, 14, fine boy. (John Anderson of Port Roseway, claimant.) John Anderson purchased from Hugh Dunn, New York; born nigh Stoney Point. Formerly the property of Edison, taken with a guard of the enemy by a party from the Garrison, 1779. | AD28: 239 | AE28: 22 | AF28: Book One Part One | AG28: Ann | AH28: Joseph Clark | AI28: Ship Ann bound for Port Roseway Joseph Clark, Master
A29: Joe | B29: Gold | C29: - | D29: - | E29: - | F29: - | G29: Male | H29: 30 | I29: 1753 | J29: Black | K29: African American | L29: Black | M29: Charlestown | N29: - | O29: South Carolina | R29: =IFERROR(INDEX(Sheet2!$C:$C, MATCH(P29&Q29, Sheet2!$E:$E, 0)) & ", " & INDEX(Sheet2!$D:$D, MATCH(P29&Q29, Sheet2!$E:$E, 0)), "-") -> - | S29: New York | T29: South Carolina | U29: New York | V29: Fall 1783 | W29: Port Roseway | Y29: Canada | Z29: Book of Negroes, British Headquarters Papers PRO 30/55/100; Loyalist evacuation shipping lists (1782–1784) | AA29: Loyalist evacuation lists | AB29: Joe Gold, 30, stout black, (Robert Turnbull). Formerly slave to Daniel Descan , about 14 miles from Charlestown, South Carolina; left him 4 years ago. | AD29: 240 | AE29: 23 | AF29: Book One Part One | AG29: Ann | AH29: Joseph Clark | AI29: Ship Ann bound for Port Roseway Joseph Clark, Master
A30: Effie | B30: Warner | C30: - | D30: - | E30: - | F30: - | G30: Child Female | H30: 33 | I30: 1750 | J30: Black | K30: African American | L30: Black | M30: - | N30: - | O30: Virginia | R30: =IFERROR(INDEX(Sheet2!$C:$C, MATCH(P30&Q30, Sheet2!$E:$E, 0)) & ", " & INDEX(Sheet2!$D:$D, MATCH(P30&Q30, Sheet2!$E:$E, 0)), "-") -> - | S30: Princess Ann | T30: Virginia | U30: - | V30: - | W30: Port Roseway | Y30: Canada | Z30: - | AA30: - | AB30: Effie Warner, 33, stout wench & boy 2 yrs, old, (William Hill). Formerly slave to John Matthews, Princess Ann, Virginia; left him 5 years ago. GBC. | AD30: 236 | AE30: - | AF30: Book One Part One | AG30: Ann | AH30: Joseph Clark | AI30: Ship Ann bound for Port Roseway Joseph Clark, Master
A31: Sukey | B31: her daughter | C31: - | D31: - | E31: Betsey | F31: his wife | G31: Child Female | H31: 12 | I31: 1771 | J31: Mulatto | K31: Mixed Race | L31: Mulatto | M31: Savannah | N31: - | O31: Georgia | R31: =IFERROR(INDEX(Sheet2!$C:$C, MATCH(P31&Q31, Sheet2!$E:$E, 0)) & ", " & INDEX(Sheet2!$D:$D, MATCH(P31&Q31, Sheet2!$E:$E, 0)), "-") -> - | S31: New York | T31: Georgia | U31: New York | V31: Fall 1783 | W31: Port Roseway | Y31: Canada | Z31: Book of Negroes, British Headquarters Papers PRO 30/55/100; Loyalist evacuation shipping lists (1782–1784) | AA31: Loyalist evacuation lists | AB31: Sukey her daughter, 12, thin mulatto girl, (Robert Turnbull). Formerly slave to Mrs. Harriet Crook, Savannah, Georgia; left that place 5 years ago. | AD31: 242 | AE31: 23 | AF31: Book One Part One | AG31: Ann | AH31: Joseph Clark | AI31: Ship Ann bound for Port Roseway Joseph Clark, Master
A32: James | B32: Jackson 50 | C32: - | D32: - | E32: - | F32: - | G32: Male | H32: 50 | I32: 1733 | J32: Black | K32: African American | L32: Black | M32: Norfolk | N32: - | O32: Virginia | R32: =IFERROR(INDEX(Sheet2!$C:$C, MATCH(P32&Q32, Sheet2!$E:$E, 0)) & ", " & INDEX(Sheet2!$D:$D, MATCH(P32&Q32, Sheet2!$E:$E, 0)), "-") -> - | S32: New York | T32: Virginia | U32: New York | V32: 8 Jul 1783 | W32: Port Roseway | Y32: Canada | Z32: Book of Negroes, British Headquarters Papers PRO 30/55/100; Loyalist evacuation shipping lists (1782–1784) | AA32: Loyalist evacuation lists | AB32: James Jackson 50, thin, goes as pilot (Capt. Mowat). Formerly slave to late Robert Tucker, Norfolk, Virginia; left him with Lord Dunmore when he left that country & was employed as a pilot. | AD32: 210 | AE32: 22 | AF32: Book One Part One | AG32: Ann | AH32: Joseph Clark | AI32: Ship Ann bound for Port Roseway Joseph Clark, Master
A33: Elizabeth | B33: Mitchell | C33: - | D33: - | E33: - | F33: - | G33: Child Female | H33: 13 | I33: 1770 | J33: Black | K33: African American | L33: Black | M33: Charlestown | N33: - | O33: South Carolina | R33: =IFERROR(INDEX(Sheet2!$C:$C, MATCH(P33&Q33, Sheet2!$E:$E, 0)) & ", " & INDEX(Sheet2!$D:$D, MATCH(P33&Q33, Sheet2!$E:$E, 0)), "-") -> - | S33: New York | T33: South Carolina | U33: New York | V33: Fall 1783 | W33: St. John's | Y33: Canada | Z33: Book of Negroes, British Headquarters Papers PRO 30/55/100; Loyalist evacuation shipping lists (1782–1784) | AA33: Loyalist evacuation lists | AB33: Elizabeth Mitchell, 13, stout girl, (Lt. Clows, Guides & Pioneers). Says she was born free near Charlestown, South Carolina; joined the Army in 1780. | AD33: 1946 | AE33: 61 | AF33: Book One Part Two | AG33: Ann | AH33: Clark | AI33: Ann bound for St. John's Clark
A34: Dick | B34: Vincent | C34: - | D34: - | E34: - | F34: - | G34: Child Male | H34: 10 | I34: 1773 | J34: Black | K34: African American | L34: Black | M34: - | N34: - | O34: East Chester | R34: =IFERROR(INDEX(Sheet2!$C:$C, MATCH(P34&Q34, Sheet2!$E:$E, 0)) & ", " & INDEX(Sheet2!$D:$D, MATCH(P34&Q34, Sheet2!$E:$E, 0)), "-") -> - | S34: New York | T34: - | U34: New York | V34: Fall 1783 | W34: St. John's | Y34: Canada | Z34: Book of Negroes, British Headquarters Papers PRO 30/55/100; Loyalist evacuation shipping lists (1782–1784) | AA34: Loyalist evacuation lists | AB34: Dick Vincent, 10, stout boy, (Ens. Vincent). Formerly slave to Charles Vincent, East Chester, grandfather to the Ensign who has delivered the boy to the said Ensign. | AD34: 1947 | AE34: 22 | AF34: Book One Part Two | AG34: Ann | AH34: Clark | AI34: Ann bound for St. John's Clark
A35: child of | B35: Abigail | G35: c | H35: 4 months | I35: - | M35: - | N35: - | O35: - | R35: =IFERROR(INDEX(Sheet2!$C:$C, MATCH(P35&Q35, Sheet2!$E:$E, 0)) & ", " & INDEX(Sheet2!$D:$D, MATCH(P35&Q35, Sheet2!$E:$E, 0)), "-") -> - | S35: New York | U35: New York | V35: Fall 1783 | W35: Port Roseway | Y35: Canada | Z35: Book of Negroes, British Headquarters Papers PRO 30/55/100; Loyalist evacuation shipping lists (1782–1784) | AA35: Loyalist evacuation lists | AD35: 250 | AE35: 22 | AG35: Ann | AH35: Joseph Clark
A36: Betsey his | B36: wife | G36: Female | H36: 33 | I36: 1750 | M36: - | N36: - | O36: - | R36: =IFERROR(INDEX(Sheet2!$C:$C, MATCH(P36&Q36, Sheet2!$E:$E, 0)) & ", " & INDEX(Sheet2!$D:$D, MATCH(P36&Q36, Sheet2!$E:$E, 0)), "-") -> - | S36: New York | U36: New York | V36: Fall 1783 | W36: Port Roseway | Y36: Canada | Z36: Book of Negroes, British Headquarters Papers PRO 30/55/100; Loyalist evacuation shipping lists (1782–1784) | AA36: Loyalist evacuation lists | AD36: 263 | AE36: 23 | AG36: Ann | AH36: Joseph Clark
A37: Sukey her | B37: daughter | G37: Child Female | H37: 12 | I37: 1771 | M37: - | N37: - | O37: - | R37: =IFERROR(INDEX(Sheet2!$C:$C, MATCH(P37&Q37, Sheet2!$E:$E, 0)) & ", " & INDEX(Sheet2!$D:$D, MATCH(P37&Q37, Sheet2!$E:$E, 0)), "-") -> - | S37: New York | U37: New York | V37: Fall 1783 | W37: Port Roseway | Y37: Canada | Z37: Book of Negroes, British Headquarters Papers PRO 30/55/100; Loyalist evacuation shipping lists (1782–1784) | AA37: Loyalist evacuation lists | AD37: 264 | AE37: 23 | AG37: Ann | AH37: Joseph Clark
A38: Betsey | B38: his wife | C38: - | D38: - | E38: - | F38: - | G38: Female | H38: 33 | I38: 1750 | J38: Mulatto | K38: Mixed Race | L38: Mulatto | M38: Savannah | N38: - | O38: Georgia | R38: =IFERROR(INDEX(Sheet2!$C:$C, MATCH(P38&Q38, Sheet2!$E:$E, 0)) & ", " & INDEX(Sheet2!$D:$D, MATCH(P38&Q38, Sheet2!$E:$E, 0)), "-") -> - | S38: New York | T38: Georgia | U38: New York | V38: Fall 1783 | W38: Port Roseway | Y38: Canada | Z38: Book of Negroes, British Headquarters Papers PRO 30/55/100; Loyalist evacuation shipping lists (1782–1784) | AA38: Loyalist evacuation lists | AB38: Betsey his wife, 33, stout mulatto wench, (Robert Turnbull). Formerly slave to Mrs. Harriet Crook, Savannah, Georgia; left that place 5 years ago. | AD38: 241 | AE38: 22 | AF38: Book One Part One | AG38: Ann | AH38: Joseph Clark | AI38: Ship Ann bound for Port Roseway Joseph Clark, Master
A39: Judith | B39: Jackson | C39: - | D39: - | E39: Betsey | F39: Robertson | G39: Female | H39: 24 | I39: 1759 | J39: Mulatto | K39: Mixed Race | L39: Mulatto | M39: - | N39: - | O39: - | R39: =IFERROR(INDEX(Sheet2!$C:$C, MATCH(P39&Q39, Sheet2!$E:$E, 0)) & ", " & INDEX(Sheet2!$D:$D, MATCH(P39&Q39, Sheet2!$E:$E, 0)), "-") -> - | S39: New York | T39: - | U39: New York | V39: Fall 1783 | W39: Port Roseway | Y39: Canada | Z39: Book of Negroes, British Headquarters Papers PRO 30/55/100; Loyalist evacuation shipping lists (1782–1784) | AA39: Loyalist evacuation lists | AB39: Judith Jackson, 24, thin wench, mulatto, (Capt. Mowat). Says she served her time to John Bell at Cape Fear and left that with the army of Sir H. Clinton in 1776. | AD39: 211 | AE39: 22 | AF39: Book One Part One | AG39: Ann | AH39: Joseph Clark | AI39: Ship Ann bound for Port Roseway Joseph Clark, Master
A40: Harry | B40: Jackson | C40: - | D40: - | E40: - | F40: - | G40: Child Male | H40: 8 | I40: 1775 | J40: Black | K40: African American | L40: Black | M40: - | N40: - | O40: - | R40: =IFERROR(INDEX(Sheet2!$C:$C, MATCH(P40&Q40, Sheet2!$E:$E, 0)) & ", " & INDEX(Sheet2!$D:$D, MATCH(P40&Q40, Sheet2!$E:$E, 0)), "-") -> - | S40: New York | T40: - | U40: New York | V40: Fall 1783 | W40: Port Roseway | Y40: Canada | Z40: Book of Negroes, British Headquarters Papers PRO 30/55/100; Loyalist evacuation shipping lists (1782–1784) | AA40: Loyalist evacuation lists | AB40: Harry Jackson, 8, good L boy, (Capt. Mowat). | AD40: 212 | AE40: 22 | AF40: Book One Part One | AG40: Ann | AH40: Joseph Clark | AI40: Ship Ann bound for Port Roseway Joseph Clark, Master
...

Sheet Sheet2
A1: County | B1: State | C1: lat | D1: lng | E1: LookupKey
A2: Aleutians East | B2: AK | C2: 55.3669 | D2: -161.9805 | E2: AKAleutians East
A3: Aleutians West | B3: AK | C3: 52.7985 | D3: -106.5633 | E3: AKAleutians West
A4: Anchorage | B4: AK | C4: 61.1498 | D4: -149.1082 | E4: AKAnchorage
A5: Bethel | B5: AK | C5: 60.9132 | D5: -159.8186 | E5: AKBethel
A6: Bristol Bay | B6: AK | C6: 58.7431 | D6: -156.7015 | E6: AKBristol Bay
A7: Chugach | B7: AK | C7: 60.7233 | D7: -145.7583 | E7: AKChugach
A8: Copper River | B8: AK | C8: 61.8855 | D8: -143.97 | E8: AKCopper River
A9: Denali | B9: AK | C9: 63.6714 | D9: -150.0118 | E9: AKDenali
A10: Dillingham | B10: AK | C10: 59.8003 | D10: -158.2346 | E10: AKDillingham
A11: Fairbanks North Star | B11: AK | C11: 64.8078 | D11: -146.5654 | E11: AKFairbanks North Star
A12: Haines | B12: AK | C12: 59.1186 | D12: -135.5007 | E12: AKHaines
A13: Hoonah-Angoon | B13: AK | C13: 58.287 | D13: -135.6393 | E13: AKHoonah-Angoon
... A3145: Weston | B3145: WY | C3145: 43.8404 | D3145: -104.5677 | E3145: WYWeston
