Workbook
Name S_AK: Sheet2!$A$2:$A$31
Name S_AL: Sheet2!$A$32:$A$98
Name S_AR: Sheet2!$A$99:$A$173
Name S_AZ: Sheet2!$A$174:$A$188
Name S_CA: Sheet2!$A$189:$A$246
Name S_CO: Sheet2!$A$247:$A$310
Name S_CT: Sheet2!$A$311:$A$319
Name S_DC: Sheet2!$A$320:$A$320
Name S_DE: Sheet2!$A$321:$A$323
Name S_FL: Sheet2!$A$324:$A$390
Name S_GA: Sheet2!$A$391:$A$549
Name S_HI: Sheet2!$A$550:$A$554
Name S_IA: Sheet2!$A$555:$A$653
Name S_ID: Sheet2!$A$654:$A$697
Name S_IL: Sheet2!$A$698:$A$799
Name S_IN: Sheet2!$A$800:$A$891
Name S_KS: Sheet2!$A$892:$A$996
Name S_KY: Sheet2!$A$997:$A$1116
Name S_LA: Sheet2!$A$1117:$A$1180
Name S_MA: Sheet2!$A$1181:$A$1194
Name S_MD: Sheet2!$A$1195:$A$1218
Name S_ME: Sheet2!$A$1219:$A$1234
Name S_MI: Sheet2!$A$1235:$A$1317
Name S_MN: Sheet2!$A$1318:$A$1404
Name S_MO: Sheet2!$A$1405:$A$1519
Name S_MS: Sheet2!$A$1520:$A$1601
Name S_MT: Sheet2!$A$1602:$A$1657
Name S_NC: Sheet2!$A$1658:$A$1757
Name S_ND: Sheet2!$A$1758:$A$1810
Name S_NE: Sheet2!$A$1811:$A$1903
Name S_NH: Sheet2!$A$1904:$A$1913
Name S_NJ: Sheet2!$A$1914:$A$1934
Name S_NM: Sheet2!$A$1935:$A$1967
Name S_NV: Sheet2!$A$1968:$A$1984
Name S_NY: Sheet2!$A$1985:$A$2046
Name S_OH: Sheet2!$A$2047:$A$2134
Name S_OK: Sheet2!$A$2135:$A$2211
Name S_OR: Sheet2!$A$2212:$A$2247
Name S_PA: Sheet2!$A$2248:$A$2314
Name S_RI: Sheet2!$A$2315:$A$2319
Name S_SC: Sheet2!$A$2320:$A$2365
Name S_SD: Sheet2!$A$2366:$A$2431
Name S_TN: Sheet2!$A$2432:$A$2526
Name S_TX: Sheet2!$A$2527:$A$2780
Name S_UT: Sheet2!$A$2781:$A$2809
Name S_VA: Sheet2!$A$2810:$A$2942
Name S_VT: Sheet2!$A$2943:$A$2956
Name S_WA: Sheet2!$A$2957:$A$2995
Name S_WI: Sheet2!$A$2996:$A$3067
Name S_WV: Sheet2!$A$3068:$A$3122
Name S_WY: Sheet2!$A$3123:$A$3145

Sheet Member Report
A1: First Name | B1: Last Name | C1: State | D1: Contact Member # | E1: Email | F1: Contact Membership Type | G1: Gen 1: Birth Date | H1: City, County, State | I1: State | J1: County | K1: Coordinates | L1: Coordinate | M1: Race | N1: Ethnicity | O1: Military Service | P1: Branch | Q1: War | R1: Gen 1: Death Date | S1: City, County, State | T1: State | V1: Coordinates | X1: Coordinate | Y1: Documentation | Z1: Gen 1: Marriage Date | AA1: City, County, State | AB1: Coordinate | AC1: Gen 1: Spouse First Name | AD1: Gen 1: Spouse Surname/Maiden Name | AE1: Spouse Gen 1: Birth Date | AF1: City, County, State | AG1: Race | AH1: Ethnicity | AI1: Coordinate | AJ1: Spouse Gen 1: Death Date | AK1: City, County, State | AL1: Coordinate | AM1: Race | AN1: Ethnicity | AO1: Gen 2: Father's: First Name | AP1: Gen 2: Father's Surname | AQ1: Gen 2: Father's Birth Date | AR1: City, County, State | AS1: Coordinate | AT1: Race | AU1: Ethnicity | AW1: Military Service | AX1: Branch | AY1: War | AZ1: Gen 2: Father's Death Date | BA1: City, County, State | BB1: Coordinate | BC1: Gen 2: Father, Mother's Marriage Date | BD1: City, County, State | BE1: Coordinate | BF1: Gen 2: Mother's First Name | BG1: Gen 2: Mother's Surname/Maiden Name | BH1: Gen 2: Mother's Birth Date | BI1: City, County, State | BJ1: Coordinate | BK1: Gen 2: Mother's Death Date | BL1: City, County, State | BM1: Coordinate | BN1: Race | BO1: Documentation | BP1: Gen 3 Father: First Name | BQ1: Gen 3: Father Surname | BR1: Gen 3: Father's Birth Date | BS1: City, County, State | BT1: Coordinate | BU1: Race | BV1: Ethnicity | BW1: Military Service | BX1: Branch | BY1: War | BZ1: Gen 3: Father's Death Date | CA1: City, County, State | CB1: Coordinate | CC1: Gen 3: Father, Mother's Marriage Date | CD1: City, County, State | CE1: Coordinate | CF1: Race | CG1: Ethnicity | CH1: Military Service | CI1: Branch | CJ1: War | CK1: Gen 3: Mother's First Name | CL1: Gen 3: Mother's Surname/Maiden Name | CM1: Alias Name | CN1: Gen 3: Mother's Birth Date | CO1: City, County, State | CP1: Gen 3: Mother's Death Date | CQ1: City, County, State | CR1: Coordinate | CS1: Race | CT1: Ethnicity | CU1: Documentation | CV1: Gen 4 Father: First Name | CW1: Gen 4: Father Surname | CX1: Gen 4: Father's Birth Date | CY1: City, County, State | CZ1: Coordinate | DA1: Race | DB1: Ethnicity | DC1: Military Service | DD1: Branch | DE1: War | DF1: Gen 4: Father's Death Date | DG1: City, County, State | DH1: Coordinate | DI1: Gen 4: Father, Mother's Marriage Date | DJ1: City, County, State | DK1: Coordinate | DL1: Gen 4: Mother's First Name | DM1: Gen 4: Mother's Surname/Maiden Name | DN1: Gen 4: Mother's Birth Date | DO1: City, County, State | DP1: Coordinate | DQ1: Gen 4: Mother's Death Date | DR1: City, County, State | DS1: Coordinate | DT1: Race | DU1: Ethnicity | DV1: Documentation | DW1: Gen 5 Father: First Name | DX1: Gen 5: Father Surname | DY1: Gen 5: Father's Birth Date | DZ1: City, County, State | EA1: Coordinate | EB1: Race | EC1: Ethnicity | ED1: Military Service | EE1: Branch | EF1: War | EG1: Gen 5: Father's Death Date | EH1: City, County, State | EI1: Coordinate | EJ1: Gen 5: Father, Mother's Marriage Date | EK1: City, County, State | EL1: Coordinate | EM1: Gen 5: Mother's First Name | EN1: Gen 5: Mother's Surname/Maiden Name | EO1: Alias Name | EP1: Gen 5: Mother's Birth Date | EQ1: City, County, State | ER1: Coordinate | ES1: Gen 5: Mother's Death Date | ET1: City, County, State | EU1: Coordinate | EV1: Race | EW1: Ethnicity | EX1: Documentation | EY1: Gen 6 Father: First Name | EZ1: Gen 6: Father Surname | FA1: Alias Name | FB1: Gen 6: Father's Birth Date | FC1: City, County, State | FD1: Coordinate | FE1: Race | FF1: Ethnicity | FG1: Gen 6: Father's Death Date | FH1: City, County, State | FI1: Coordinate | FJ1: Gen 6: Father, Mother's Marriage Date | FK1: City, County, State | FL1: Coordinate | FM1: Gen 6: Mother's First Name | FN1: Gen 6: Mother's Surname/Maiden Name | FO1: Alias Name | FP1: Gen 6: Mother's Birth Date | FQ1: City, County, State | FR1: Coordinate | FS1: Gen 6: Mother's Death Date | FT1: City, County, State | FU1: Coordinate | FV1: Race | FW1: Ethnicty | FX1: Documentation | FY1: Gen 7 Father: First Name | FZ1: Gen 7: Father Surname | GA1: Alias Name | GB1: Gen 7: Father's Birth Date | GC1: City, County, State | GD1: Coordinate | GE1: Race | GF1: Ethnicity | GG1: Gen 7: Father's Death Date | GH1: City, County, State | GI1: Coordinate | GJ1: Race | GK1: Ethnicity | GL1: Gen 7: Father, Mother's Marriage Date | GM1: City, County, State | GN1: Coordinate | GO1: Gen 7: Mother's First Name | GP1: Gen 7: Mother's Surname/Maiden Name | GQ1: Alias Name | GR1: Gen 7: Mother's Birth Date | GS1: City, County, State | GT1: Coordinate | GU1: Gen 7: Mother's Death Date | GV1: City, County, State | GW1: Coordinate | GX1: Documentation | GY1: Gen 8 Father: First Name | GZ1: Gen 8: Father Surname | HA1: Alias Name | HB1: Gen 8: Father's Birth Date | HC1: City, County, State | HD1: Coordinate | HE1: Race | HF1: Ethnicity | HG1: Military Service | HH1: Branch | HI1: War | HJ1: Gen 8: Father's Death Date | HK1: City, County, State | HL1: Coordinate | HM1: Gen 8: Father, Mother's Marriage Date | HN1: City, County, State | HO1: Coordinate | HP1: Gen 8: Mother's First Name | HQ1: Gen 8: Mother's Surname/Maiden Name | HR1: Alias Name | HS1: Gen 8: Mother's Birth Date | HT1: City, County, State | HU1: Coordinate | HV1: Gen 8: Mother's Death Date | HW1: City, County, State | HX1: Coordinate | HY1: Documentation | HZ1: Gen 9 Father: First Name | IA1: Gen 9: Father Surname | IB1: Alias Name | IC1: Gen 9: Father's Birth Date | ID1: City, County, State | IE1: Coordinate | IF1: Race | IG1: Ethnicity | IH1: Military Service | II1: Branch | IJ1: War | IK1: Gen 9: Father's Death Date | IL1: City, County, State | IM1: Coordinate | IN1: Gen 9: Father, Mother's Marriage Date | IO1: City, County, State | IP1: Coordinate | IQ1: Gen 9: Mother's First Name | IR1: Gen 9: Mother's Surname/Maiden Name | IS1: Alias Name | IT1: Gen 9: Mother's Birth Date | IU1: City, County, State | IV1: Coordinate | IW1: Gen 9: Mother's Death Date | IX1: City, County, State | IY1: Coordinate | IZ1: Documentation | JA1: Gen 10 Father: First Name | JB1: Gen 10: Father Surname | JC1: Alias Name | JD1: Gen 10: Father's Birth Date | JE1: City, County, State | JF1: Coordinate | JG1: Race | JH1: Ethnicity | JI1: Military Service | JJ1: Branch | JK1: War | JL1: Gen 10: Father's Death Date | JM1: City, County, State | JN1: Coordinate | JO1: Gen 10: Father, Mother's Marriage Date | JP1: City, County, State | JQ1: Coordinate | JR1: Gen 10: Mother's First Name | JS1: Gen 10: Mother's Surname/Maiden Name | JT1: Alias Name | JU1: Gen 10: Mother's Birth Date | JV1: City, County, State | JW1: Coordinate | JX1: Gen 10: Mother's Death Date | JY1: City, County, State | JZ1: Coordinate | KA1: Documentation
A2: Ric | B2: Murphy | C2: No | D2: - | E2: VA | F2: 100001 | G2: ricmurphy1@aol.com | H2: Founding Member | I2: 22479 | J2: Boston, Suffolk, MA | K2: MA | L2: Suffolk | M2: =IFERROR(VLOOKUP(K2&"-"&L2, Sheet2!$E:$F, 2, FALSE), "") -> 42.3329, -71.0735 | N2: AZ | O2: Norfolk | Q2: 42_21_37_N_71_3_28_W | R2: Black | S2: Afrrican American | T2: No | V2: - | AA2: =IFERROR(VLOOKUP(Y2&"-"&Z2, Sheet2!$E:$F, 2, FALSE), "") | AB2: MA | AC2: Norfolk | AD2: 42.1603, -71.2118 | AL2: =IFERROR(VLOOKUP(AJ2&"-"&AK2, Sheet2!$E:$F, 2, FALSE), "") | AP2: No | AQ2: - | AV2: =IFERROR(VLOOKUP(AT2&"-"&AU2, Sheet2!$E:$F, 2, FALSE), "") | BD2: =IFERROR(VLOOKUP(BB2&"-"&BC2, Sheet2!$E:$F, 2, FALSE), "") | BF2: Record Copy NSSAR #165111, Add ACN 51405 and Record Copy NSDAR # 672791, Add. Vol. 1043 | BG2: Robert | BH2: Murphy | BI2: 9951 | BJ2: No | BK2: - | BL2: Boston, Suffolk, MA | BM2: 42_21_37_N_71_3_28_W | BP2: =IFERROR(VLOOKUP(BN2&"-"&BO2, Sheet2!$E:$F, 2, FALSE), "") | BT2: No | BV2: - | BW2: 3, 3, 1966 | BX2: Milton, Norfolk, MA | BY2: 42°15′00″N 71°04′00″W | CB2: =IFERROR(VLOOKUP(BZ2&"-"&CA2, Sheet2!$E:$F, 2, FALSE), "") | CC2: 18635 | CD2: Brockton, Plymouth, MA | CE2: 42°05′00″N 71°01′08″W | CH2: =IFERROR(VLOOKUP(CF2&"-"&CG2, Sheet2!$E:$F, 2, FALSE), "") | CI2: Joan | CJ2: Cornwall | CK2: 3, 3, 1929 | CL2: No | CM2: - | CN2: Brockton, Plymouth, MA | CO2: 42°05′00″N 71°01′08″W | CR2: =IFERROR(VLOOKUP(CP2&"-"&CQ2, Sheet2!$E:$F, 2, FALSE), "") | CX2: =IFERROR(VLOOKUP(CV2&"-"&CW2, Sheet2!$E:$F, 2, FALSE), "") | CZ2: Record Copy NSSAR #165111, Add ACN 51405 and Record Copy NSDAR # 672791, Add. Vol. 1043 | DA2: Harold | DB2: Cornwall | DC2: 1, 1, 1901 | DD2: No | DE2: - | DF2: Brockton, Plymouth, MA | DJ2: =IFERROR(VLOOKUP(DH2&"-"&DI2, Sheet2!$E:$F, 2, FALSE), "") | DM2: No | DO2: - | DP2: 11, 8, 1991 | DQ2: Brockton, Plymouth, MA | DR2: 42°05′00″N 71°01′08″W | DU2: =IFERROR(VLOOKUP(DS2&"-"&DT2, Sheet2!$E:$F, 2, FALSE), "") | DV2: 7, 11, 1924 | DW2: Brockton, Plymouth, MA | DX2: 42°05′00″N 71°01′08″W | EA2: =IFERROR(VLOOKUP(DY2&"-"&DZ2, Sheet2!$E:$F, 2, FALSE), "") | ED2: No | EF2: - | EG2: Marie | EH2: Howell | EJ2: No | EK2: - | EL2: 2577 | EM2: Brockton, Plymouth, MA | EN2: 3, 1, 2022 | EQ2: =IFERROR(VLOOKUP(EO2&"-"&EP2, Sheet2!$E:$F, 2, FALSE), "") | ER2: Brockton, Plymouth, MA | ES2: 42°05′00″N 71°01′08″W | EV2: =IFERROR(VLOOKUP(ET2&"-"&EU2, Sheet2!$E:$F, 2, FALSE), "") | EY2: Record Copy NSSAR #165111, Add ACN 51405 and Record Copy NSDAR # 672791, Add. Vol. 1043 | EZ2: Benjamin | FA2: CORNWALL | FB2: 06 Oct 1869 | FC2: No | FD2: - | FE2: Boston, Suffolk, MA | FF2: 42_21_37_N_71_3_28_W | FI2: =IFERROR(VLOOKUP(FG2&"-"&FH2, Sheet2!$E:$F, 2, FALSE), "") | FL2: No | FN2: - | FO2: 6680 | FP2: Brockton, Plymouth, MA | FQ2: 42°05′00″N 71°01′08″W | FT2: =IFERROR(VLOOKUP(FR2&"-"&FS2, Sheet2!$E:$F, 2, FALSE), "") | FU2: 2, 18, 1901 | FV2: Brockton, Plymouth, MA | FW2: 42°05′00″N 71°01′08″W | FZ2: =IFERROR(VLOOKUP(FX2&"-"&FY2, Sheet2!$E:$F, 2, FALSE), "") | GA2: Grace | GB2: Jackson | GC2: 25 Mar 1877 | GD2: No | GE2: - | GF2: Huntington, Suffolk, NY | GG2: 40°51′36″N 73°21′8″W | GJ2: =IFERROR(VLOOKUP(GH2&"-"&GI2, Sheet2!$E:$F, 2, FALSE), "") | GK2: 2, 24, 1946 | GL2: Brockton, Plymouth, MA | GM2: 42°05′00″N 71°01′08″W | GP2: =IFERROR(VLOOKUP(GN2&"-"&GO2, Sheet2!$E:$F, 2, FALSE), "") | GS2: Record Copy NSSAR #165111, Add ACN 51405 and Record Copy NSDAR # 672791, Add. Vol. 1043 | GT2: William | GU2: Cornwall | GV2: 12 Nov 1844 | GW2: No | GX2: - | GY2: Brockton, Plymouth, MA | GZ2: 42°05′00″N 71°01′08″W | HC2: =IFERROR(VLOOKUP(HA2&"-"&HB2, Sheet2!$E:$F, 2, FALSE), "") | HF2: No | HH2: - | HI2: 8, 21, 1926 | HJ2: Bridgewater, Plymouth, MA | HK2: 41_59_25_N_70_58_32_W | HN2: =IFERROR(VLOOKUP(HL2&"-"&HM2, Sheet2!$E:$F, 2, FALSE), "") | HO2: 22 Nov 1866 | HP2: Taunton, Bristol, MA | HT2: =IFERROR(VLOOKUP(HR2&"-"&HS2, Sheet2!$E:$F, 2, FALSE), "") | HU2: Martha | HV2: Hill | HX2: No | HY2: - | HZ2: ---- 1842 | IA2: Cambridge, Middlesex, MA | IE2: =IFERROR(VLOOKUP(IC2&"-"&ID2, Sheet2!$E:$F, 2, FALSE), "") | IF2: 2823 | IG2: Bridgewater, Plymouth, MA | IH2: 41_59_25_N_70_58_32_W | IK2: =IFERROR(VLOOKUP(II2&"-"&IJ2, Sheet2!$E:$F, 2, FALSE), "") | IN2: Record Copy NSSAR #165111, Add ACN 51405 and Record Copy NSDAR # 672791, Add. Vol. 1043 | IO2: Flushing | IP2: Cornwall | IR2: No | IS2: - | IT2: 25 Dec 1801 | IU2: St. Johns Parish, News Bruniswick, Canada | IY2: =IFERROR(VLOOKUP(IW2&"-"&IX2, Sheet2!$E:$F, 2, FALSE), "") | JB2: 19 Aug 1888 | JC2: Bridgewater, Plymouth, MA | JD2: 41_59_25_N_70_58_32_W | JG2: =IFERROR(VLOOKUP(JE2&"-"&JF2, Sheet2!$E:$F, 2, FALSE), "") | JH2: 10 May 1817 | JI2: Bridgewater, Plymouth, MA | JJ2: 41_59_25_N_70_58_32_W | JM2: =IFERROR(VLOOKUP(JK2&"-"&JL2, Sheet2!$E:$F, 2, FALSE), "") | JN2: Harriet | JO2: BROOKER | JQ2: No | JR2: - | JS2: 586 | JT2: Bridgewater, Plymouth, MA | JU2: 41_59_25_N_70_58_32_W | JX2: =IFERROR(VLOOKUP(JV2&"-"&JW2, Sheet2!$E:$F, 2, FALSE), "") | JY2: 19 Apr 1840 | JZ2: Brockton, Plymouth, MA | KD2: =IFERROR(VLOOKUP(KB2&"-"&KC2, Sheet2!$E:$F, 2, FALSE), "") | KG2: Record Copy NSSAR #165111, Add ACN 51405 and Record Copy NSDAR # 672791, Add. Vol. 1043 | KH2: Samuel Stanley | KI2: Brooker | KJ2: Bruker | KK2: No | KL2: - | KM2: 12 May 1795 | KN2: Bridgewater, Plymouth, MA | KR2: =IFERROR(VLOOKUP(KP2&"-"&KQ2, Sheet2!$E:$F, 2, FALSE), "") | KU2: 26 Feb 1838 | KV2: Boston, Suffolk, MA | KW2: 42_21_37_N_71_3_28_W | KZ2: =IFERROR(VLOOKUP(KX2&"-"&KY2, Sheet2!$E:$F, 2, FALSE), "") | LA2: Black | LB2: African American | LC2: 18 Oct 1818 | LD2: Boston, Suffolk, MA | LE2: 42_21_37_N_71_3_28_W | LH2: =IFERROR(VLOOKUP(LF2&"-"&LG2, Sheet2!$E:$F, 2, FALSE), "") | LI2: Philinda | LJ2: Russell | LK2: Lender | LL2: No | LM2: - | LN2: 21 Jan 1799 | LO2: Beverly, Essex, MA | LS2: =IFERROR(VLOOKUP(LQ2&"-"&LR2, Sheet2!$E:$F, 2, FALSE), "") | LT2: 23 Apr 1848 | LU2: Tauton, Bristol, MA | LY2: =IFERROR(VLOOKUP(LW2&"-"&LX2, Sheet2!$E:$F, 2, FALSE), "") | LZ2: Record Copy NSSAR #165111, Add ACN 51405 and Record Copy NSDAR # 672791, Add. Vol. 1043 | MA2: Caesar | MB2: Russell | MD2: No | ME2: - | MF2: 1756 | MK2: =IFERROR(VLOOKUP(MI2&"-"&MJ2, Sheet2!$E:$F, 2, FALSE), "") | MN2: No | MP2: - | MQ2: 20 Oct 1861 | MR2: Tauton, Bristol, MA | MV2: =IFERROR(VLOOKUP(MT2&"-"&MU2, Sheet2!$E:$F, 2, FALSE), "") | NB2: =IFERROR(VLOOKUP(MZ2&"-"&NA2, Sheet2!$E:$F, 2, FALSE), "") | NC2: Sally | ND2: Richardson | NF2: No | NG2: - | NM2: =IFERROR(VLOOKUP(NK2&"-"&NL2, Sheet2!$E:$F, 2, FALSE), "") | NS2: =IFERROR(VLOOKUP(NQ2&"-"&NR2, Sheet2!$E:$F, 2, FALSE), "") | NT2: Record Copy NSSAR #165111, Add ACN 51405 and Record Copy NSDAR # 672791, Add. Vol. 1043 | NX2: No | NY2: - | OE2: =IFERROR(VLOOKUP(OC2&"-"&OD2, Sheet2!$E:$F, 2, FALSE), "") | OH2: No | OJ2: - | OP2: =IFERROR(VLOOKUP(ON2&"-"&OO2, Sheet2!$E:$F, 2, FALSE), "") | OV2: =IFERROR(VLOOKUP(OT2&"-"&OU2, Sheet2!$E:$F, 2, FALSE), "") | OZ2: No | PA2: - | PG2: =IFERROR(VLOOKUP(PE2&"-"&PF2, Sheet2!$E:$F, 2, FALSE), "") | PM2: =IFERROR(VLOOKUP(PK2&"-"&PL2, Sheet2!$E:$F, 2, FALSE), "") | PN2: Record Copy NSSAR #165111, Add ACN 51405 and Record Copy NSDAR # 672791, Add. Vol. 1043 | PR2: No | PS2: - | PY2: =IFERROR(VLOOKUP(PW2&"-"&PX2, Sheet2!$E:$F, 2, FALSE), "") | QB2: No | QD2: - | QJ2: =IFERROR(VLOOKUP(QH2&"-"&QI2, Sheet2!$E:$F, 2, FALSE), "") | QP2: =IFERROR(VLOOKUP(QN2&"-"&QO2, Sheet2!$E:$F, 2, FALSE), "") | QT2: No | QU2: - | RA2: =IFERROR(VLOOKUP(QY2&"-"&QZ2, Sheet2!$E:$F, 2, FALSE), "") | RG2: =IFERROR(VLOOKUP(RE2&"-"&RF2, Sheet2!$E:$F, 2, FALSE), "") | RH2: Record Copy NSSAR #165111, Add ACN 51405 and Record Copy NSDAR # 672791, Add. Vol. 1043
A3: Douglas | B3: Cornwall | C3: No | D3: - | E3: CA | F3: 100002 | G3: dcornwall@outlook.com | H3: Founding Member | M3: =IFERROR(VLOOKUP(K3&"-"&L3, Sheet2!$E:$F, 2, FALSE), "") | N3: CA | O3: Norfolk | P3: 42.1603, -71.2118 | T3: No | V3: - | AA3: =IFERROR(VLOOKUP(Y3&"-"&Z3, Sheet2!$E:$F, 2, FALSE), "") | AB3: MA | AC3: Norfolk | AD3: 42.1603, -71.2118 | AE3: Norfolk | AL3: =IFERROR(VLOOKUP(AJ3&"-"&AK3, Sheet2!$E:$F, 2, FALSE), "") | AP3: No | AQ3: - | AV3: =IFERROR(VLOOKUP(AT3&"-"&AU3, Sheet2!$E:$F, 2, FALSE), "") | BD3: =IFERROR(VLOOKUP(BB3&"-"&BC3, Sheet2!$E:$F, 2, FALSE), "") | BJ3: No | BK3: - | BP3: =IFERROR(VLOOKUP(BN3&"-"&BO3, Sheet2!$E:$F, 2, FALSE), "") | BT3: No | BV3: - | CB3: =IFERROR(VLOOKUP(BZ3&"-"&CA3, Sheet2!$E:$F, 2, FALSE), "") | CH3: =IFERROR(VLOOKUP(CF3&"-"&CG3, Sheet2!$E:$F, 2, FALSE), "") | CL3: No | CM3: - | CR3: =IFERROR(VLOOKUP(CP3&"-"&CQ3, Sheet2!$E:$F, 2, FALSE), "") | CX3: =IFERROR(VLOOKUP(CV3&"-"&CW3, Sheet2!$E:$F, 2, FALSE), "") | DD3: No | DE3: - | DJ3: =IFERROR(VLOOKUP(DH3&"-"&DI3, Sheet2!$E:$F, 2, FALSE), "") | DM3: No | DO3: - | DU3: =IFERROR(VLOOKUP(DS3&"-"&DT3, Sheet2!$E:$F, 2, FALSE), "") | EA3: =IFERROR(VLOOKUP(DY3&"-"&DZ3, Sheet2!$E:$F, 2, FALSE), "") | ED3: No | EF3: - | EJ3: No | EK3: - | EQ3: =IFERROR(VLOOKUP(EO3&"-"&EP3, Sheet2!$E:$F, 2, FALSE), "") | EV3: =IFERROR(VLOOKUP(ET3&"-"&EU3, Sheet2!$E:$F, 2, FALSE), "") | FC3: No | FD3: - | FI3: =IFERROR(VLOOKUP(FG3&"-"&FH3, Sheet2!$E:$F, 2, FALSE), "") | FL3: No | FN3: - | FT3: =IFERROR(VLOOKUP(FR3&"-"&FS3, Sheet2!$E:$F, 2, FALSE), "") | FZ3: =IFERROR(VLOOKUP(FX3&"-"&FY3, Sheet2!$E:$F, 2, FALSE), "") | GD3: No | GE3: - | GJ3: =IFERROR(VLOOKUP(GH3&"-"&GI3, Sheet2!$E:$F, 2, FALSE), "") | GP3: =IFERROR(VLOOKUP(GN3&"-"&GO3, Sheet2!$E:$F, 2, FALSE), "") | GW3: No | GX3: - | HC3: =IFERROR(VLOOKUP(HA3&"-"&HB3, Sheet2!$E:$F, 2, FALSE), "") | HF3: No | HH3: - | HN3: =IFERROR(VLOOKUP(HL3&"-"&HM3, Sheet2!$E:$F, 2, FALSE), "") | HT3: =IFERROR(VLOOKUP(HR3&"-"&HS3, Sheet2!$E:$F, 2, FALSE), "") | HX3: No | HY3: - | IE3: =IFERROR(VLOOKUP(IC3&"-"&ID3, Sheet2!$E:$F, 2, FALSE), "") | IK3: =IFERROR(VLOOKUP(II3&"-"&IJ3, Sheet2!$E:$F, 2, FALSE), "") | IR3: No | IS3: - | IY3: =IFERROR(VLOOKUP(IW3&"-"&IX3, Sheet2!$E:$F, 2, FALSE), "") | JG3: =IFERROR(VLOOKUP(JE3&"-"&JF3, Sheet2!$E:$F, 2, FALSE), "") | JM3: =IFERROR(VLOOKUP(JK3&"-"&JL3, Sheet2!$E:$F, 2, FALSE), "") | JQ3: No | JR3: - | JX3: =IFERROR(VLOOKUP(JV3&"-"&JW3, Sheet2!$E:$F, 2, FALSE), "") | KD3: =IFERROR(VLOOKUP(KB3&"-"&KC3, Sheet2!$E:$F, 2, FALSE), "") | KK3: No | KL3: - | KR3: =IFERROR(VLOOKUP(KP3&"-"&KQ3, Sheet2!$E:$F, 2, FALSE), "") | KZ3: =IFERROR(VLOOKUP(KX3&"-"&KY3, Sheet2!$E:$F, 2, FALSE), "") | LH3: =IFERROR(VLOOKUP(LF3&"-"&LG3, Sheet2!$E:$F, 2, FALSE), "") | LL3: No | LM3: - | LS3: =IFERROR(VLOOKUP(LQ3&"-"&LR3, Sheet2!$E:$F, 2, FALSE), "") | LY3: =IFERROR(VLOOKUP(LW3&"-"&LX3, Sheet2!$E:$F, 2, FALSE), "") | MD3: No | ME3: - | MK3: =IFERROR(VLOOKUP(MI3&"-"&MJ3, Sheet2!$E:$F, 2, FALSE), "") | MN3: No | MP3: - | MV3: =IFERROR(VLOOKUP(MT3&"-"&MU3, Sheet2!$E:$F, 2, FALSE), "") | NB3: =IFERROR(VLOOKUP(MZ3&"-"&NA3, Sheet2!$E:$F, 2, FALSE), "") | NF3: No | NG3: - | NM3: =IFERROR(VLOOKUP(NK3&"-"&NL3, Sheet2!$E:$F, 2, FALSE), "") | NS3: =IFERROR(VLOOKUP(NQ3&"-"&NR3, Sheet2!$E:$F, 2, FALSE), "") | NX3: No | NY3: - | OE3: =IFERROR(VLOOKUP(OC3&"-"&OD3, Sheet2!$E:$F, 2, FALSE), "") | OH3: No | OJ3: - | OP3: =IFERROR(VLOOKUP(ON3&"-"&OO3, Sheet2!$E:$F, 2, FALSE), "") | OV3: =IFERROR(VLOOKUP(OT3&"-"&OU3, Sheet2!$E:$F, 2, FALSE), "") | OZ3: No | PA3: - | PG3: =IFERROR(VLOOKUP(PE3&"-"&PF3, Sheet2!$E:$F, 2, FALSE), "") | PM3: =IFERROR(VLOOKUP(PK3&"-"&PL3, Sheet2!$E:$F, 2, FALSE), "") | PR3: No | PS3: - | PY3: =IFERROR(VLOOKUP(PW3&"-"&PX3, Sheet2!$E:$F, 2, FALSE), "") | QB3: No | QD3: - | QJ3: =IFERROR(VLOOKUP(QH3&"-"&QI3, Sheet2!$E:$F, 2, FALSE), "") | QP3: =IFERROR(VLOOKUP(QN3&"-"&QO3, Sheet2!$E:$F, 2, FALSE), "") | QT3: No | QU3: - | RA3: =IFERROR(VLOOKUP(QY3&"-"&QZ3, Sheet2!$E:$F, 2, FALSE), "") | RG3: =IFERROR(VLOOKUP(RE3&"-"&RF3, Sheet2!$E:$F, 2, FALSE), "")
A4: Shelley | B4: Murphy | C4: No | D4: - | E4: VA | F4: 100003 | G4: shelleyviola@gmail.com | H4: Founding Member | M4: =IFERROR(VLOOKUP(K4&"-"&L4, Sheet2!$E:$F, 2, FALSE), "") | N4: AZ | O4: Norfolk | P4: 42.1603, -71.2118 | T4: No | V4: - | AA4: =IFERROR(VLOOKUP(Y4&"-"&Z4, Sheet2!$E:$F, 2, FALSE), "") | AB4: MA | AC4: Suffolk | AD4: 42.3329, -71.0735 | AL4: =IFERROR(VLOOKUP(AJ4&"-"&AK4, Sheet2!$E:$F, 2, FALSE), "") | AP4: No | AQ4: - | AV4: =IFERROR(VLOOKUP(AT4&"-"&AU4, Sheet2!$E:$F, 2, FALSE), "") | BD4: =IFERROR(VLOOKUP(BB4&"-"&BC4, Sheet2!$E:$F, 2, FALSE), "") | BJ4: No | BK4: - | BP4: =IFERROR(VLOOKUP(BN4&"-"&BO4, Sheet2!$E:$F, 2, FALSE), "") | BT4: No | BV4: - | CB4: =IFERROR(VLOOKUP(BZ4&"-"&CA4, Sheet2!$E:$F, 2, FALSE), "") | CH4: =IFERROR(VLOOKUP(CF4&"-"&CG4, Sheet2!$E:$F, 2, FALSE), "") | CL4: No | CM4: - | CR4: =IFERROR(VLOOKUP(CP4&"-"&CQ4, Sheet2!$E:$F, 2, FALSE), "") | CX4: =IFERROR(VLOOKUP(CV4&"-"&CW4, Sheet2!$E:$F, 2, FALSE), "") | DD4: No | DE4: - | DJ4: =IFERROR(VLOOKUP(DH4&"-"&DI4, Sheet2!$E:$F, 2, FALSE), "") | DM4: No | DO4: - | DU4: =IFERROR(VLOOKUP(DS4&"-"&DT4, Sheet2!$E:$F, 2, FALSE), "") | EA4: =IFERROR(VLOOKUP(DY4&"-"&DZ4, Sheet2!$E:$F, 2, FALSE), "") | ED4: No | EF4: - | EJ4: No | EK4: - | EQ4: =IFERROR(VLOOKUP(EO4&"-"&EP4, Sheet2!$E:$F, 2, FALSE), "") | EV4: =IFERROR(VLOOKUP(ET4&"-"&EU4, Sheet2!$E:$F, 2, FALSE), "") | FC4: No | FD4: - | FI4: =IFERROR(VLOOKUP(FG4&"-"&FH4, Sheet2!$E:$F, 2, FALSE), "") | FL4: No | FN4: - | FT4: =IFERROR(VLOOKUP(FR4&"-"&FS4, Sheet2!$E:$F, 2, FALSE), "") | FZ4: =IFERROR(VLOOKUP(FX4&"-"&FY4, Sheet2!$E:$F, 2, FALSE), "") | GD4: No | GE4: - | GJ4: =IFERROR(VLOOKUP(GH4&"-"&GI4, Sheet2!$E:$F, 2, FALSE), "") | GP4: =IFERROR(VLOOKUP(GN4&"-"&GO4, Sheet2!$E:$F, 2, FALSE), "") | GW4: No | GX4: - | HC4: =IFERROR(VLOOKUP(HA4&"-"&HB4, Sheet2!$E:$F, 2, FALSE), "") | HF4: No | HH4: - | HN4: =IFERROR(VLOOKUP(HL4&"-"&HM4, Sheet2!$E:$F, 2, FALSE), "") | HT4: =IFERROR(VLOOKUP(HR4&"-"&HS4, Sheet2!$E:$F, 2, FALSE), "") | HX4: No | HY4: - | IE4: =IFERROR(VLOOKUP(IC4&"-"&ID4, Sheet2!$E:$F, 2, FALSE), "") | IK4: =IFERROR(VLOOKUP(II4&"-"&IJ4, Sheet2!$E:$F, 2, FALSE), "") | IR4: No | IS4: - | IY4: =IFERROR(VLOOKUP(IW4&"-"&IX4, Sheet2!$E:$F, 2, FALSE), "") | JG4: =IFERROR(VLOOKUP(JE4&"-"&JF4, Sheet2!$E:$F, 2, FALSE), "") | JM4: =IFERROR(VLOOKUP(JK4&"-"&JL4, Sheet2!$E:$F, 2, FALSE), "") | JQ4: No | JR4: - | JX4: =IFERROR(VLOOKUP(JV4&"-"&JW4, Sheet2!$E:$F, 2, FALSE), "") | KD4: =IFERROR(VLOOKUP(KB4&"-"&KC4, Sheet2!$E:$F, 2, FALSE), "") | KK4: No | KL4: - | KR4: =IFERROR(VLOOKUP(KP4&"-"&KQ4, Sheet2!$E:$F, 2, FALSE), "") | KZ4: =IFERROR(VLOOKUP(KX4&"-"&KY4, Sheet2!$E:$F, 2, FALSE), "") | LH4: =IFERROR(VLOOKUP(LF4&"-"&LG4, Sheet2!$E:$F, 2, FALSE), "") | LL4: No | LM4: - | LS4: =IFERROR(VLOOKUP(LQ4&"-"&LR4, Sheet2!$E:$F, 2, FALSE), "") | LY4: =IFERROR(VLOOKUP(LW4&"-"&LX4, Sheet2!$E:$F, 2, FALSE), "") | MD4: No | ME4: - | MK4: =IFERROR(VLOOKUP(MI4&"-"&MJ4, Sheet2!$E:$F, 2, FALSE), "") | MN4: No | MP4: - | MV4: =IFERROR(VLOOKUP(MT4&"-"&MU4, Sheet2!$E:$F, 2, FALSE), "") | NB4: =IFERROR(VLOOKUP(MZ4&"-"&NA4, Sheet2!$E:$F, 2, FALSE), "") | NF4: No | NG4: - | NM4: =IFERROR(VLOOKUP(NK4&"-"&NL4, Sheet2!$E:$F, 2, FALSE), "") | NS4: =IFERROR(VLOOKUP(NQ4&"-"&NR4, Sheet2!$E:$F, 2, FALSE), "") | NX4: No | NY4: - | OE4: =IFERROR(VLOOKUP(OC4&"-"&OD4, Sheet2!$E:$F, 2, FALSE), "") | OH4: No | OJ4: - | OP4: =IFERROR(VLOOKUP(ON4&"-"&OO4, Sheet2!$E:$F, 2, FALSE), "") | OV4: =IFERROR(VLOOKUP(OT4&"-"&OU4, Sheet2!$E:$F, 2, FALSE), "") | OZ4: No | PA4: - | PG4: =IFERROR(VLOOKUP(PE4&"-"&PF4, Sheet2!$E:$F, 2, FALSE), "") | PM4: =IFERROR(VLOOKUP(PK4&"-"&PL4, Sheet2!$E:$F, 2, FALSE), "") | PR4: No | PS4: - | PY4: =IFERROR(VLOOKUP(PW4&"-"&PX4, Sheet2!$E:$F, 2, FALSE), "") | QB4: No | QD4: - | QJ4: =IFERROR(VLOOKUP(QH4&"-"&QI4, Sheet2!$E:$F, 2, FALSE), "") | QP4: =IFERROR(VLOOKUP(QN4&"-"&QO4, Sheet2!$E:$F, 2, FALSE), "") | QT4: No | QU4: - | RA4: =IFERROR(VLOOKUP(QY4&"-"&QZ4, Sheet2!$E:$F, 2, FALSE), "") | RG4: =IFERROR(VLOOKUP(RE4&"-"&RF4, Sheet2!$E:$F, 2, FALSE), "")
A5: Joyce | B5: Mosley | C5: No | D5: - | E5: PA | F5: 100005 | G5: joycemos355@gmail.com | H5: Founding Member | M5: =IFERROR(VLOOKUP(K5&"-"&L5, Sheet2!$E:$F, 2, FALSE), "") | N5: IL | O5: Norfolk | P5: 42.1603, -71.2118 | T5: No | V5: - | AA5: =IFERROR(VLOOKUP(Y5&"-"&Z5, Sheet2!$E:$F, 2, FALSE), "") | AB5: MA | AL5: =IFERROR(VLOOKUP(AJ5&"-"&AK5, Sheet2!$E:$F, 2, FALSE), "") | AP5: No | AQ5: - | AV5: =IFERROR(VLOOKUP(AT5&"-"&AU5, Sheet2!$E:$F, 2, FALSE), "") | BD5: =IFERROR(VLOOKUP(BB5&"-"&BC5, Sheet2!$E:$F, 2, FALSE), "") | BJ5: No | BK5: - | BP5: =IFERROR(VLOOKUP(BN5&"-"&BO5, Sheet2!$E:$F, 2, FALSE), "") | BT5: No | BV5: - | CB5: =IFERROR(VLOOKUP(BZ5&"-"&CA5, Sheet2!$E:$F, 2, FALSE), "") | CH5: =IFERROR(VLOOKUP(CF5&"-"&CG5, Sheet2!$E:$F, 2, FALSE), "") | CL5: No | CM5: - | CR5: =IFERROR(VLOOKUP(CP5&"-"&CQ5, Sheet2!$E:$F, 2, FALSE), "") | CX5: =IFERROR(VLOOKUP(CV5&"-"&CW5, Sheet2!$E:$F, 2, FALSE), "") | DD5: No | DE5: - | DJ5: =IFERROR(VLOOKUP(DH5&"-"&DI5, Sheet2!$E:$F, 2, FALSE), "") | DM5: No | DO5: - | DU5: =IFERROR(VLOOKUP(DS5&"-"&DT5, Sheet2!$E:$F, 2, FALSE), "") | EA5: =IFERROR(VLOOKUP(DY5&"-"&DZ5, Sheet2!$E:$F, 2, FALSE), "") | ED5: No | EF5: - | EJ5: No | EK5: - | EQ5: =IFERROR(VLOOKUP(EO5&"-"&EP5, Sheet2!$E:$F, 2, FALSE), "") | EV5: =IFERROR(VLOOKUP(ET5&"-"&EU5, Sheet2!$E:$F, 2, FALSE), "") | FC5: No | FD5: - | FI5: =IFERROR(VLOOKUP(FG5&"-"&FH5, Sheet2!$E:$F, 2, FALSE), "") | FL5: No | FN5: - | FT5: =IFERROR(VLOOKUP(FR5&"-"&FS5, Sheet2!$E:$F, 2, FALSE), "") | FZ5: =IFERROR(VLOOKUP(FX5&"-"&FY5, Sheet2!$E:$F, 2, FALSE), "") | GD5: No | GE5: - | GJ5: =IFERROR(VLOOKUP(GH5&"-"&GI5, Sheet2!$E:$F, 2, FALSE), "") | GP5: =IFERROR(VLOOKUP(GN5&"-"&GO5, Sheet2!$E:$F, 2, FALSE), "") | GW5: No | GX5: - | HC5: =IFERROR(VLOOKUP(HA5&"-"&HB5, Sheet2!$E:$F, 2, FALSE), "") | HF5: No | HH5: - | HN5: =IFERROR(VLOOKUP(HL5&"-"&HM5, Sheet2!$E:$F, 2, FALSE), "") | HT5: =IFERROR(VLOOKUP(HR5&"-"&HS5, Sheet2!$E:$F, 2, FALSE), "") | HX5: No | HY5: - | IE5: =IFERROR(VLOOKUP(IC5&"-"&ID5, Sheet2!$E:$F, 2, FALSE), "") | IK5: =IFERROR(VLOOKUP(II5&"-"&IJ5, Sheet2!$E:$F, 2, FALSE), "") | IR5: No | IS5: - | IY5: =IFERROR(VLOOKUP(IW5&"-"&IX5, Sheet2!$E:$F, 2, FALSE), "") | JG5: =IFERROR(VLOOKUP(JE5&"-"&JF5, Sheet2!$E:$F, 2, FALSE), "") | JM5: =IFERROR(VLOOKUP(JK5&"-"&JL5, Sheet2!$E:$F, 2, FALSE), "") | JQ5: No | JR5: - | JX5: =IFERROR(VLOOKUP(JV5&"-"&JW5, Sheet2!$E:$F, 2, FALSE), "") | KD5: =IFERROR(VLOOKUP(KB5&"-"&KC5, Sheet2!$E:$F, 2, FALSE), "") | KK5: No | KL5: - | KR5: =IFERROR(VLOOKUP(KP5&"-"&KQ5, Sheet2!$E:$F, 2, FALSE), "") | KZ5: =IFERROR(VLOOKUP(KX5&"-"&KY5, Sheet2!$E:$F, 2, FALSE), "") | LH5: =IFERROR(VLOOKUP(LF5&"-"&LG5, Sheet2!$E:$F, 2, FALSE), "") | LL5: No | LM5: - | LS5: =IFERROR(VLOOKUP(LQ5&"-"&LR5, Sheet2!$E:$F, 2, FALSE), "") | LY5: =IFERROR(VLOOKUP(LW5&"-"&LX5, Sheet2!$E:$F, 2, FALSE), "") | MD5: No | ME5: - | MK5: =IFERROR(VLOOKUP(MI5&"-"&MJ5, Sheet2!$E:$F, 2, FALSE), "") | MN5: No | MP5: - | MV5: =IFERROR(VLOOKUP(MT5&"-"&MU5, Sheet2!$E:$F, 2, FALSE), "") | NB5: =IFERROR(VLOOKUP(MZ5&"-"&NA5, Sheet2!$E:$F, 2, FALSE), "") | NF5: No | NG5: - | NM5: =IFERROR(VLOOKUP(NK5&"-"&NL5, Sheet2!$E:$F, 2, FALSE), "") | NS5: =IFERROR(VLOOKUP(NQ5&"-"&NR5, Sheet2!$E:$F, 2, FALSE), "") | NX5: No | NY5: - | OE5: =IFERROR(VLOOKUP(OC5&"-"&OD5, Sheet2!$E:$F, 2, FALSE), "") | OH5: No | OJ5: - | OP5: =IFERROR(VLOOKUP(ON5&"-"&OO5, Sheet2!$E:$F, 2, FALSE), "") | OV5: =IFERROR(VLOOKUP(OT5&"-"&OU5, Sheet2!$E:$F, 2, FALSE), "") | OZ5: No | PA5: - | PG5: =IFERROR(VLOOKUP(PE5&"-"&PF5, Sheet2!$E:$F, 2, FALSE), "") | PM5: =IFERROR(VLOOKUP(PK5&"-"&PL5, Sheet2!$E:$F, 2, FALSE), "") | PR5: No | PS5: - | PY5: =IFERROR(VLOOKUP(PW5&"-"&PX5, Sheet2!$E:$F, 2, FALSE), "") | QB5: No | QD5: - | QJ5: =IFERROR(VLOOKUP(QH5&"-"&QI5, Sheet2!$E:$F, 2, FALSE), "") | QP5: =IFERROR(VLOOKUP(QN5&"-"&QO5, Sheet2!$E:$F, 2, FALSE), "") | QT5: No | QU5: - | RA5: =IFERROR(VLOOKUP(QY5&"-"&QZ5, Sheet2!$E:$F, 2, FALSE), "") | RG5: =IFERROR(VLOOKUP(RE5&"-"&RF5, Sheet2!$E:$F, 2, FALSE), "")
A6: Dean | B6: Henry | C6: No | D6: - | E6: PA | F6: 100006 | G6: deanhenry@comcast.net | H6: Founding Member | M6: =IFERROR(VLOOKUP(K6&"-"&L6, Sheet2!$E:$F, 2, FALSE), "") | N6: IL | O6: Norfolk | P6: 42.1603, -71.2118 | T6: No | V6: - | AA6: =IFERROR(VLOOKUP(Y6&"-"&Z6, Sheet2!$E:$F, 2, FALSE), "") | AB6: MA | AL6: =IFERROR(VLOOKUP(AJ6&"-"&AK6, Sheet2!$E:$F, 2, FALSE), "") | AP6: No | AQ6: - | AV6: =IFERROR(VLOOKUP(AT6&"-"&AU6, Sheet2!$E:$F, 2, FALSE), "") | BD6: =IFERROR(VLOOKUP(BB6&"-"&BC6, Sheet2!$E:$F, 2, FALSE), "") | BJ6: No | BK6: - | BP6: =IFERROR(VLOOKUP(BN6&"-"&BO6, Sheet2!$E:$F, 2, FALSE), "") | BT6: No | BV6: - | CB6: =IFERROR(VLOOKUP(BZ6&"-"&CA6, Sheet2!$E:$F, 2, FALSE), "") | CH6: =IFERROR(VLOOKUP(CF6&"-"&CG6, Sheet2!$E:$F, 2, FALSE), "") | CL6: No | CM6: - | CR6: =IFERROR(VLOOKUP(CP6&"-"&CQ6, Sheet2!$E:$F, 2, FALSE), "") | CX6: =IFERROR(VLOOKUP(CV6&"-"&CW6, Sheet2!$E:$F, 2, FALSE), "") | DD6: No | DE6: - | DJ6: =IFERROR(VLOOKUP(DH6&"-"&DI6, Sheet2!$E:$F, 2, FALSE), "") | DM6: No | DO6: - | DU6: =IFERROR(VLOOKUP(DS6&"-"&DT6, Sheet2!$E:$F, 2, FALSE), "") | EA6: =IFERROR(VLOOKUP(DY6&"-"&DZ6, Sheet2!$E:$F, 2, FALSE), "") | ED6: No | EF6: - | EJ6: No | EK6: - | EQ6: =IFERROR(VLOOKUP(EO6&"-"&EP6, Sheet2!$E:$F, 2, FALSE), "") | EV6: =IFERROR(VLOOKUP(ET6&"-"&EU6, Sheet2!$E:$F, 2, FALSE), "") | FC6: No | FD6: - | FI6: =IFERROR(VLOOKUP(FG6&"-"&FH6, Sheet2!$E:$F, 2, FALSE), "") | FL6: No | FN6: - | FT6: =IFERROR(VLOOKUP(FR6&"-"&FS6, Sheet2!$E:$F, 2, FALSE), "") | FZ6: =IFERROR(VLOOKUP(FX6&"-"&FY6, Sheet2!$E:$F, 2, FALSE), "") | GD6: No | GE6: - | GJ6: =IFERROR(VLOOKUP(GH6&"-"&GI6, Sheet2!$E:$F, 2, FALSE), "") | GP6: =IFERROR(VLOOKUP(GN6&"-"&GO6, Sheet2!$E:$F, 2, FALSE), "") | GW6: No | GX6: - | HC6: =IFERROR(VLOOKUP(HA6&"-"&HB6, Sheet2!$E:$F, 2, FALSE), "") | HF6: No | HH6: - | HN6: =IFERROR(VLOOKUP(HL6&"-"&HM6, Sheet2!$E:$F, 2, FALSE), "") | HT6: =IFERROR(VLOOKUP(HR6&"-"&HS6, Sheet2!$E:$F, 2, FALSE), "") | HX6: No | HY6: - | IE6: =IFERROR(VLOOKUP(IC6&"-"&ID6, Sheet2!$E:$F, 2, FALSE), "") | IK6: =IFERROR(VLOOKUP(II6&"-"&IJ6, Sheet2!$E:$F, 2, FALSE), "") | IR6: No | IS6: - | IY6: =IFERROR(VLOOKUP(IW6&"-"&IX6, Sheet2!$E:$F, 2, FALSE), "") | JG6: =IFERROR(VLOOKUP(JE6&"-"&JF6, Sheet2!$E:$F, 2, FALSE), "") | JM6: =IFERROR(VLOOKUP(JK6&"-"&JL6, Sheet2!$E:$F, 2, FALSE), "") | JQ6: No | JR6: - | JX6: =IFERROR(VLOOKUP(JV6&"-"&JW6, Sheet2!$E:$F, 2, FALSE), "") | KD6: =IFERROR(VLOOKUP(KB6&"-"&KC6, Sheet2!$E:$F, 2, FALSE), "") | KK6: No | KL6: - | KR6: =IFERROR(VLOOKUP(KP6&"-"&KQ6, Sheet2!$E:$F, 2, FALSE), "") | KZ6: =IFERROR(VLOOKUP(KX6&"-"&KY6, Sheet2!$E:$F, 2, FALSE), "") | LH6: =IFERROR(VLOOKUP(LF6&"-"&LG6, Sheet2!$E:$F, 2, FALSE), "") | LL6: No | LM6: - | LS6: =IFERROR(VLOOKUP(LQ6&"-"&LR6, Sheet2!$E:$F, 2, FALSE), "") | LY6: =IFERROR(VLOOKUP(LW6&"-"&LX6, Sheet2!$E:$F, 2, FALSE), "") | MD6: No | ME6: - | MK6: =IFERROR(VLOOKUP(MI6&"-"&MJ6, Sheet2!$E:$F, 2, FALSE), "") | MN6: No | MP6: - | MV6: =IFERROR(VLOOKUP(MT6&"-"&MU6, Sheet2!$E:$F, 2, FALSE), "") | NB6: =IFERROR(VLOOKUP(MZ6&"-"&NA6, Sheet2!$E:$F, 2, FALSE), "") | NF6: No | NG6: - | NM6: =IFERROR(VLOOKUP(NK6&"-"&NL6, Sheet2!$E:$F, 2, FALSE), "") | NS6: =IFERROR(VLOOKUP(NQ6&"-"&NR6, Sheet2!$E:$F, 2, FALSE), "") | NX6: No | NY6: - | OE6: =IFERROR(VLOOKUP(OC6&"-"&OD6, Sheet2!$E:$F, 2, FALSE), "") | OH6: No | OJ6: - | OP6: =IFERROR(VLOOKUP(ON6&"-"&OO6, Sheet2!$E:$F, 2, FALSE), "") | OV6: =IFERROR(VLOOKUP(OT6&"-"&OU6, Sheet2!$E:$F, 2, FALSE), "") | OZ6: No | PA6: - | PG6: =IFERROR(VLOOKUP(PE6&"-"&PF6, Sheet2!$E:$F, 2, FALSE), "") | PM6: =IFERROR(VLOOKUP(PK6&"-"&PL6, Sheet2!$E:$F, 2, FALSE), "") | PR6: No | PS6: - | PY6: =IFERROR(VLOOKUP(PW6&"-"&PX6, Sheet2!$E:$F, 2, FALSE), "") | QB6: No | QD6: - | QJ6: =IFERROR(VLOOKUP(QH6&"-"&QI6, Sheet2!$E:$F, 2, FALSE), "") | QP6: =IFERROR(VLOOKUP(QN6&"-"&QO6, Sheet2!$E:$F, 2, FALSE), "") | QT6: No | QU6: - | RA6: =IFERROR(VLOOKUP(QY6&"-"&QZ6, Sheet2!$E:$F, 2, FALSE), "") | RG6: =IFERROR(VLOOKUP(RE6&"-"&RF6, Sheet2!$E:$F, 2, FALSE), "")
A7: Cynthia | B7: Goins-Hoelscher | C7: No | D7: - | E7: TX | F7: 100007 | G7: Cynditha@hotmail.com | H7: Founding Member | M7: =IFERROR(VLOOKUP(K7&"-"&L7, Sheet2!$E:$F, 2, FALSE), "") | N7: IL | O7: Norfolk | P7: 42.1603, -71.2118 | T7: No | AA7: =IFERROR(VLOOKUP(Y7&"-"&Z7, Sheet2!$E:$F, 2, FALSE), "") | AB7: MA | AL7: =IFERROR(VLOOKUP(AJ7&"-"&AK7, Sheet2!$E:$F, 2, FALSE), "") | AP7: No | AQ7: - | AV7: =IFERROR(VLOOKUP(AT7&"-"&AU7, Sheet2!$E:$F, 2, FALSE), "") | BD7: =IFERROR(VLOOKUP(BB7&"-"&BC7, Sheet2!$E:$F, 2, FALSE), "") | BJ7: No | BK7: - | BP7: =IFERROR(VLOOKUP(BN7&"-"&BO7, Sheet2!$E:$F, 2, FALSE), "") | BT7: No | CB7: =IFERROR(VLOOKUP(BZ7&"-"&CA7, Sheet2!$E:$F, 2, FALSE), "") | CH7: =IFERROR(VLOOKUP(CF7&"-"&CG7, Sheet2!$E:$F, 2, FALSE), "") | CL7: No | CM7: - | CR7: =IFERROR(VLOOKUP(CP7&"-"&CQ7, Sheet2!$E:$F, 2, FALSE), "") | CX7: =IFERROR(VLOOKUP(CV7&"-"&CW7, Sheet2!$E:$F, 2, FALSE), "") | DD7: No | DE7: - | DJ7: =IFERROR(VLOOKUP(DH7&"-"&DI7, Sheet2!$E:$F, 2, FALSE), "") | DM7: No | DU7: =IFERROR(VLOOKUP(DS7&"-"&DT7, Sheet2!$E:$F, 2, FALSE), "") | EA7: =IFERROR(VLOOKUP(DY7&"-"&DZ7, Sheet2!$E:$F, 2, FALSE), "") | ED7: No | EJ7: No | EK7: - | EQ7: =IFERROR(VLOOKUP(EO7&"-"&EP7, Sheet2!$E:$F, 2, FALSE), "") | EV7: =IFERROR(VLOOKUP(ET7&"-"&EU7, Sheet2!$E:$F, 2, FALSE), "") | FC7: No | FD7: - | FI7: =IFERROR(VLOOKUP(FG7&"-"&FH7, Sheet2!$E:$F, 2, FALSE), "") | FL7: No | FT7: =IFERROR(VLOOKUP(FR7&"-"&FS7, Sheet2!$E:$F, 2, FALSE), "") | FZ7: =IFERROR(VLOOKUP(FX7&"-"&FY7, Sheet2!$E:$F, 2, FALSE), "") | GD7: No | GE7: - | GJ7: =IFERROR(VLOOKUP(GH7&"-"&GI7, Sheet2!$E:$F, 2, FALSE), "") | GP7: =IFERROR(VLOOKUP(GN7&"-"&GO7, Sheet2!$E:$F, 2, FALSE), "") | GW7: No | GX7: - | HC7: =IFERROR(VLOOKUP(HA7&"-"&HB7, Sheet2!$E:$F, 2, FALSE), "") | HF7: No | HN7: =IFERROR(VLOOKUP(HL7&"-"&HM7, Sheet2!$E:$F, 2, FALSE), "") | HT7: =IFERROR(VLOOKUP(HR7&"-"&HS7, Sheet2!$E:$F, 2, FALSE), "") | HX7: No | HY7: - | IE7: =IFERROR(VLOOKUP(IC7&"-"&ID7, Sheet2!$E:$F, 2, FALSE), "") | IK7: =IFERROR(VLOOKUP(II7&"-"&IJ7, Sheet2!$E:$F, 2, FALSE), "") | IR7: No | IS7: - | IY7: =IFERROR(VLOOKUP(IW7&"-"&IX7, Sheet2!$E:$F, 2, FALSE), "") | JG7: =IFERROR(VLOOKUP(JE7&"-"&JF7, Sheet2!$E:$F, 2, FALSE), "") | JM7: =IFERROR(VLOOKUP(JK7&"-"&JL7, Sheet2!$E:$F, 2, FALSE), "") | JQ7: No | JR7: - | JX7: =IFERROR(VLOOKUP(JV7&"-"&JW7, Sheet2!$E:$F, 2, FALSE), "") | KD7: =IFERROR(VLOOKUP(KB7&"-"&KC7, Sheet2!$E:$F, 2, FALSE), "") | KK7: No | KL7: - | KR7: =IFERROR(VLOOKUP(KP7&"-"&KQ7, Sheet2!$E:$F, 2, FALSE), "") | KZ7: =IFERROR(VLOOKUP(KX7&"-"&KY7, Sheet2!$E:$F, 2, FALSE), "") | LH7: =IFERROR(VLOOKUP(LF7&"-"&LG7, Sheet2!$E:$F, 2, FALSE), "") | LL7: No | LM7: - | LS7: =IFERROR(VLOOKUP(LQ7&"-"&LR7, Sheet2!$E:$F, 2, FALSE), "") | LY7: =IFERROR(VLOOKUP(LW7&"-"&LX7, Sheet2!$E:$F, 2, FALSE), "") | MD7: No | ME7: - | MK7: =IFERROR(VLOOKUP(MI7&"-"&MJ7, Sheet2!$E:$F, 2, FALSE), "") | MN7: No | MV7: =IFERROR(VLOOKUP(MT7&"-"&MU7, Sheet2!$E:$F, 2, FALSE), "") | NB7: =IFERROR(VLOOKUP(MZ7&"-"&NA7, Sheet2!$E:$F, 2, FALSE), "") | NF7: No | NG7: - | NM7: =IFERROR(VLOOKUP(NK7&"-"&NL7, Sheet2!$E:$F, 2, FALSE), "") | NS7: =IFERROR(VLOOKUP(NQ7&"-"&NR7, Sheet2!$E:$F, 2, FALSE), "") | NX7: No | NY7: - | OE7: =IFERROR(VLOOKUP(OC7&"-"&OD7, Sheet2!$E:$F, 2, FALSE), "") | OH7: No | OP7: =IFERROR(VLOOKUP(ON7&"-"&OO7, Sheet2!$E:$F, 2, FALSE), "") | OV7: =IFERROR(VLOOKUP(OT7&"-"&OU7, Sheet2!$E:$F, 2, FALSE), "") | OZ7: No | PA7: - | PG7: =IFERROR(VLOOKUP(PE7&"-"&PF7, Sheet2!$E:$F, 2, FALSE), "") | PM7: =IFERROR(VLOOKUP(PK7&"-"&PL7, Sheet2!$E:$F, 2, FALSE), "") | PR7: No | PS7: - | PY7: =IFERROR(VLOOKUP(PW7&"-"&PX7, Sheet2!$E:$F, 2, FALSE), "") | QB7: No | QJ7: =IFERROR(VLOOKUP(QH7&"-"&QI7, Sheet2!$E:$F, 2, FALSE), "") | QP7: =IFERROR(VLOOKUP(QN7&"-"&QO7, Sheet2!$E:$F, 2, FALSE), "") | QT7: No | QU7: - | RA7: =IFERROR(VLOOKUP(QY7&"-"&QZ7, Sheet2!$E:$F, 2, FALSE), "") | RG7: =IFERROR(VLOOKUP(RE7&"-"&RF7, Sheet2!$E:$F, 2, FALSE), "")
A8: Andre | B8: Kearns | C8: No | D8: - | E8: DC | F8: 100008 | G8: andrekearnsdc@gmail.com | H8: Founding Member | M8: =IFERROR(VLOOKUP(K8&"-"&L8, Sheet2!$E:$F, 2, FALSE), "") | N8: IL | O8: Norfolk | P8: 42.1603, -71.2118 | T8: No | AA8: =IFERROR(VLOOKUP(Y8&"-"&Z8, Sheet2!$E:$F, 2, FALSE), "") | AB8: MA | AL8: =IFERROR(VLOOKUP(AJ8&"-"&AK8, Sheet2!$E:$F, 2, FALSE), "") | AP8: No | AQ8: - | AV8: =IFERROR(VLOOKUP(AT8&"-"&AU8, Sheet2!$E:$F, 2, FALSE), "") | BD8: =IFERROR(VLOOKUP(BB8&"-"&BC8, Sheet2!$E:$F, 2, FALSE), "") | BJ8: No | BK8: - | BP8: =IFERROR(VLOOKUP(BN8&"-"&BO8, Sheet2!$E:$F, 2, FALSE), "") | BT8: No | CB8: =IFERROR(VLOOKUP(BZ8&"-"&CA8, Sheet2!$E:$F, 2, FALSE), "") | CH8: =IFERROR(VLOOKUP(CF8&"-"&CG8, Sheet2!$E:$F, 2, FALSE), "") | CL8: No | CM8: - | CR8: =IFERROR(VLOOKUP(CP8&"-"&CQ8, Sheet2!$E:$F, 2, FALSE), "") | CX8: =IFERROR(VLOOKUP(CV8&"-"&CW8, Sheet2!$E:$F, 2, FALSE), "") | DD8: No | DE8: - | DJ8: =IFERROR(VLOOKUP(DH8&"-"&DI8, Sheet2!$E:$F, 2, FALSE), "") | DM8: No | DU8: =IFERROR(VLOOKUP(DS8&"-"&DT8, Sheet2!$E:$F, 2, FALSE), "") | EA8: =IFERROR(VLOOKUP(DY8&"-"&DZ8, Sheet2!$E:$F, 2, FALSE), "") | ED8: No | EJ8: No | EK8: - | EQ8: =IFERROR(VLOOKUP(EO8&"-"&EP8, Sheet2!$E:$F, 2, FALSE), "") | EV8: =IFERROR(VLOOKUP(ET8&"-"&EU8, Sheet2!$E:$F, 2, FALSE), "") | FC8: No | FD8: - | FI8: =IFERROR(VLOOKUP(FG8&"-"&FH8, Sheet2!$E:$F, 2, FALSE), "") | FL8: No | FT8: =IFERROR(VLOOKUP(FR8&"-"&FS8, Sheet2!$E:$F, 2, FALSE), "") | FZ8: =IFERROR(VLOOKUP(FX8&"-"&FY8, Sheet2!$E:$F, 2, FALSE), "") | GD8: No | GE8: - | GJ8: =IFERROR(VLOOKUP(GH8&"-"&GI8, Sheet2!$E:$F, 2, FALSE), "") | GP8: =IFERROR(VLOOKUP(GN8&"-"&GO8, Sheet2!$E:$F, 2, FALSE), "") | GW8: No | GX8: - | HC8: =IFERROR(VLOOKUP(HA8&"-"&HB8, Sheet2!$E:$F, 2, FALSE), "") | HF8: No | HN8: =IFERROR(VLOOKUP(HL8&"-"&HM8, Sheet2!$E:$F, 2, FALSE), "") | HT8: =IFERROR(VLOOKUP(HR8&"-"&HS8, Sheet2!$E:$F, 2, FALSE), "") | HX8: No | HY8: - | IE8: =IFERROR(VLOOKUP(IC8&"-"&ID8, Sheet2!$E:$F, 2, FALSE), "") | IK8: =IFERROR(VLOOKUP(II8&"-"&IJ8, Sheet2!$E:$F, 2, FALSE), "") | IR8: No | IS8: - | IY8: =IFERROR(VLOOKUP(IW8&"-"&IX8, Sheet2!$E:$F, 2, FALSE), "") | JG8: =IFERROR(VLOOKUP(JE8&"-"&JF8, Sheet2!$E:$F, 2, FALSE), "") | JM8: =IFERROR(VLOOKUP(JK8&"-"&JL8, Sheet2!$E:$F, 2, FALSE), "") | JQ8: No | JR8: - | JX8: =IFERROR(VLOOKUP(JV8&"-"&JW8, Sheet2!$E:$F, 2, FALSE), "") | KD8: =IFERROR(VLOOKUP(KB8&"-"&KC8, Sheet2!$E:$F, 2, FALSE), "") | KK8: No | KL8: - | KR8: =IFERROR(VLOOKUP(KP8&"-"&KQ8, Sheet2!$E:$F, 2, FALSE), "") | KZ8: =IFERROR(VLOOKUP(KX8&"-"&KY8, Sheet2!$E:$F, 2, FALSE), "") | LH8: =IFERROR(VLOOKUP(LF8&"-"&LG8, Sheet2!$E:$F, 2, FALSE), "") | LL8: No | LM8: - | LS8: =IFERROR(VLOOKUP(LQ8&"-"&LR8, Sheet2!$E:$F, 2, FALSE), "") | LY8: =IFERROR(VLOOKUP(LW8&"-"&LX8, Sheet2!$E:$F, 2, FALSE), "") | MD8: No | ME8: - | MK8: =IFERROR(VLOOKUP(MI8&"-"&MJ8, Sheet2!$E:$F, 2, FALSE), "") | MN8: No | MV8: =IFERROR(VLOOKUP(MT8&"-"&MU8, Sheet2!$E:$F, 2, FALSE), "") | NB8: =IFERROR(VLOOKUP(MZ8&"-"&NA8, Sheet2!$E:$F, 2, FALSE), "") | NF8: No | NG8: - | NM8: =IFERROR(VLOOKUP(NK8&"-"&NL8, Sheet2!$E:$F, 2, FALSE), "") | NS8: =IFERROR(VLOOKUP(NQ8&"-"&NR8, Sheet2!$E:$F, 2, FALSE), "") | NX8: No | NY8: - | OE8: =IFERROR(VLOOKUP(OC8&"-"&OD8, Sheet2!$E:$F, 2, FALSE), "") | OH8: No | OP8: =IFERROR(VLOOKUP(ON8&"-"&OO8, Sheet2!$E:$F, 2, FALSE), "") | OV8: =IFERROR(VLOOKUP(OT8&"-"&OU8, Sheet2!$E:$F, 2, FALSE), "") | OZ8: No | PA8: - | PG8: =IFERROR(VLOOKUP(PE8&"-"&PF8, Sheet2!$E:$F, 2, FALSE), "") | PM8: =IFERROR(VLOOKUP(PK8&"-"&PL8, Sheet2!$E:$F, 2, FALSE), "") | PR8: No | PS8: - | PY8: =IFERROR(VLOOKUP(PW8&"-"&PX8, Sheet2!$E:$F, 2, FALSE), "") | QB8: No | QJ8: =IFERROR(VLOOKUP(QH8&"-"&QI8, Sheet2!$E:$F, 2, FALSE), "") | QP8: =IFERROR(VLOOKUP(QN8&"-"&QO8, Sheet2!$E:$F, 2, FALSE), "") | QT8: No | QU8: - | RA8: =IFERROR(VLOOKUP(QY8&"-"&QZ8, Sheet2!$E:$F, 2, FALSE), "") | RG8: =IFERROR(VLOOKUP(RE8&"-"&RF8, Sheet2!$E:$F, 2, FALSE), "")
A9: Stephani | B9: Miller | C9: No | D9: - | E9: FL | F9: 100009 | G9: dsmillertime84@aol.com | H9: Founding Member | M9: =IFERROR(VLOOKUP(K9&"-"&L9, Sheet2!$E:$F, 2, FALSE), "") | N9: IL | O9: Norfolk | P9: 42.1603, -71.2118 | T9: No | AA9: =IFERROR(VLOOKUP(Y9&"-"&Z9, Sheet2!$E:$F, 2, FALSE), "") | AB9: MA | AL9: =IFERROR(VLOOKUP(AJ9&"-"&AK9, Sheet2!$E:$F, 2, FALSE), "") | AP9: No | AQ9: - | AV9: =IFERROR(VLOOKUP(AT9&"-"&AU9, Sheet2!$E:$F, 2, FALSE), "") | BD9: =IFERROR(VLOOKUP(BB9&"-"&BC9, Sheet2!$E:$F, 2, FALSE), "") | BJ9: No | BK9: - | BP9: =IFERROR(VLOOKUP(BN9&"-"&BO9, Sheet2!$E:$F, 2, FALSE), "") | BT9: No | CB9: =IFERROR(VLOOKUP(BZ9&"-"&CA9, Sheet2!$E:$F, 2, FALSE), "") | CH9: =IFERROR(VLOOKUP(CF9&"-"&CG9, Sheet2!$E:$F, 2, FALSE), "") | CL9: No | CM9: - | CR9: =IFERROR(VLOOKUP(CP9&"-"&CQ9, Sheet2!$E:$F, 2, FALSE), "") | CX9: =IFERROR(VLOOKUP(CV9&"-"&CW9, Sheet2!$E:$F, 2, FALSE), "") | DD9: No | DE9: - | DJ9: =IFERROR(VLOOKUP(DH9&"-"&DI9, Sheet2!$E:$F, 2, FALSE), "") | DM9: No | DU9: =IFERROR(VLOOKUP(DS9&"-"&DT9, Sheet2!$E:$F, 2, FALSE), "") | EA9: =IFERROR(VLOOKUP(DY9&"-"&DZ9, Sheet2!$E:$F, 2, FALSE), "") | ED9: No | EJ9: No | EK9: - | EQ9: =IFERROR(VLOOKUP(EO9&"-"&EP9, Sheet2!$E:$F, 2, FALSE), "") | EV9: =IFERROR(VLOOKUP(ET9&"-"&EU9, Sheet2!$E:$F, 2, FALSE), "") | FC9: No | FD9: - | FI9: =IFERROR(VLOOKUP(FG9&"-"&FH9, Sheet2!$E:$F, 2, FALSE), "") | FL9: No | FT9: =IFERROR(VLOOKUP(FR9&"-"&FS9, Sheet2!$E:$F, 2, FALSE), "") | FZ9: =IFERROR(VLOOKUP(FX9&"-"&FY9, Sheet2!$E:$F, 2, FALSE), "") | GD9: No | GE9: - | GJ9: =IFERROR(VLOOKUP(GH9&"-"&GI9, Sheet2!$E:$F, 2, FALSE), "") | GP9: =IFERROR(VLOOKUP(GN9&"-"&GO9, Sheet2!$E:$F, 2, FALSE), "") | GW9: No | GX9: - | HC9: =IFERROR(VLOOKUP(HA9&"-"&HB9, Sheet2!$E:$F, 2, FALSE), "") | HF9: No | HN9: =IFERROR(VLOOKUP(HL9&"-"&HM9, Sheet2!$E:$F, 2, FALSE), "") | HT9: =IFERROR(VLOOKUP(HR9&"-"&HS9, Sheet2!$E:$F, 2, FALSE), "") | HX9: No | HY9: - | IE9: =IFERROR(VLOOKUP(IC9&"-"&ID9, Sheet2!$E:$F, 2, FALSE), "") | IK9: =IFERROR(VLOOKUP(II9&"-"&IJ9, Sheet2!$E:$F, 2, FALSE), "") | IR9: No | IS9: - | IY9: =IFERROR(VLOOKUP(IW9&"-"&IX9, Sheet2!$E:$F, 2, FALSE), "") | JG9: =IFERROR(VLOOKUP(JE9&"-"&JF9, Sheet2!$E:$F, 2, FALSE), "") | JM9: =IFERROR(VLOOKUP(JK9&"-"&JL9, Sheet2!$E:$F, 2, FALSE), "") | JQ9: No | JR9: - | JX9: =IFERROR(VLOOKUP(JV9&"-"&JW9, Sheet2!$E:$F, 2, FALSE), "") | KD9: =IFERROR(VLOOKUP(KB9&"-"&KC9, Sheet2!$E:$F, 2, FALSE), "") | KK9: No | KL9: - | KR9: =IFERROR(VLOOKUP(KP9&"-"&KQ9, Sheet2!$E:$F, 2, FALSE), "") | KZ9: =IFERROR(VLOOKUP(KX9&"-"&KY9, Sheet2!$E:$F, 2, FALSE), "") | LH9: =IFERROR(VLOOKUP(LF9&"-"&LG9, Sheet2!$E:$F, 2, FALSE), "") | LL9: No | LM9: - | LS9: =IFERROR(VLOOKUP(LQ9&"-"&LR9, Sheet2!$E:$F, 2, FALSE), "") | LY9: =IFERROR(VLOOKUP(LW9&"-"&LX9, Sheet2!$E:$F, 2, FALSE), "") | MD9: No | ME9: - | MK9: =IFERROR(VLOOKUP(MI9&"-"&MJ9, Sheet2!$E:$F, 2, FALSE), "") | MN9: No | MV9: =IFERROR(VLOOKUP(MT9&"-"&MU9, Sheet2!$E:$F, 2, FALSE), "") | NB9: =IFERROR(VLOOKUP(MZ9&"-"&NA9, Sheet2!$E:$F, 2, FALSE), "") | NF9: No | NG9: - | NM9: =IFERROR(VLOOKUP(NK9&"-"&NL9, Sheet2!$E:$F, 2, FALSE), "") | NS9: =IFERROR(VLOOKUP(NQ9&"-"&NR9, Sheet2!$E:$F, 2, FALSE), "") | NX9: No | NY9: - | OE9: =IFERROR(VLOOKUP(OC9&"-"&OD9, Sheet2!$E:$F, 2, FALSE), "") | OH9: No | OP9: =IFERROR(VLOOKUP(ON9&"-"&OO9, Sheet2!$E:$F, 2, FALSE), "") | OV9: =IFERROR(VLOOKUP(OT9&"-"&OU9, Sheet2!$E:$F, 2, FALSE), "") | OZ9: No | PA9: - | PG9: =IFERROR(VLOOKUP(PE9&"-"&PF9, Sheet2!$E:$F, 2, FALSE), "") | PM9: =IFERROR(VLOOKUP(PK9&"-"&PL9, Sheet2!$E:$F, 2, FALSE), "") | PR9: No | PS9: - | PY9: =IFERROR(VLOOKUP(PW9&"-"&PX9, Sheet2!$E:$F, 2, FALSE), "") | QB9: No | QJ9: =IFERROR(VLOOKUP(QH9&"-"&QI9, Sheet2!$E:$F, 2, FALSE), "") | QP9: =IFERROR(VLOOKUP(QN9&"-"&QO9, Sheet2!$E:$F, 2, FALSE), "") | QT9: No | QU9: - | RA9: =IFERROR(VLOOKUP(QY9&"-"&QZ9, Sheet2!$E:$F, 2, FALSE), "") | RG9: =IFERROR(VLOOKUP(RE9&"-"&RF9, Sheet2!$E:$F, 2, FALSE), "")
A10: Laurie | B10: Constantino | C10: No | D10: - | E10: WA | F10: 100010 | G10: lhconstantino@gmail.com | H10: Founding Member | M10: =IFERROR(VLOOKUP(K10&"-"&L10, Sheet2!$E:$F, 2, FALSE), "") | N10: IL | O10: Norfolk | P10: 42.1603, -71.2118 | T10: No | AA10: =IFERROR(VLOOKUP(Y10&"-"&Z10, Sheet2!$E:$F, 2, FALSE), "") | AB10: MA | AL10: =IFERROR(VLOOKUP(AJ10&"-"&AK10, Sheet2!$E:$F, 2, FALSE), "") | AP10: No | AQ10: - | AV10: =IFERROR(VLOOKUP(AT10&"-"&AU10, Sheet2!$E:$F, 2, FALSE), "") | BD10: =IFERROR(VLOOKUP(BB10&"-"&BC10, Sheet2!$E:$F, 2, FALSE), "") | BJ10: No | BK10: - | BP10: =IFERROR(VLOOKUP(BN10&"-"&BO10, Sheet2!$E:$F, 2, FALSE), "") | BT10: No | CB10: =IFERROR(VLOOKUP(BZ10&"-"&CA10, Sheet2!$E:$F, 2, FALSE), "") | CH10: =IFERROR(VLOOKUP(CF10&"-"&CG10, Sheet2!$E:$F, 2, FALSE), "") | CL10: No | CM10: - | CR10: =IFERROR(VLOOKUP(CP10&"-"&CQ10, Sheet2!$E:$F, 2, FALSE), "") | CX10: =IFERROR(VLOOKUP(CV10&"-"&CW10, Sheet2!$E:$F, 2, FALSE), "") | DD10: No | DE10: - | DJ10: =IFERROR(VLOOKUP(DH10&"-"&DI10, Sheet2!$E:$F, 2, FALSE), "") | DM10: No | DU10: =IFERROR(VLOOKUP(DS10&"-"&DT10, Sheet2!$E:$F, 2, FALSE), "") | EA10: =IFERROR(VLOOKUP(DY10&"-"&DZ10, Sheet2!$E:$F, 2, FALSE), "") | ED10: No | EJ10: No | EK10: - | EQ10: =IFERROR(VLOOKUP(EO10&"-"&EP10, Sheet2!$E:$F, 2, FALSE), "") | EV10: =IFERROR(VLOOKUP(ET10&"-"&EU10, Sheet2!$E:$F, 2, FALSE), "") | FC10: No | FD10: - | FI10: =IFERROR(VLOOKUP(FG10&"-"&FH10, Sheet2!$E:$F, 2, FALSE), "") | FL10: No | FT10: =IFERROR(VLOOKUP(FR10&"-"&FS10, Sheet2!$E:$F, 2, FALSE), "") | FZ10: =IFERROR(VLOOKUP(FX10&"-"&FY10, Sheet2!$E:$F, 2, FALSE), "") | GD10: No | GE10: - | GJ10: =IFERROR(VLOOKUP(GH10&"-"&GI10, Sheet2!$E:$F, 2, FALSE), "") | GP10: =IFERROR(VLOOKUP(GN10&"-"&GO10, Sheet2!$E:$F, 2, FALSE), "") | GW10: No | GX10: - | HC10: =IFERROR(VLOOKUP(HA10&"-"&HB10, Sheet2!$E:$F, 2, FALSE), "") | HF10: No | HN10: =IFERROR(VLOOKUP(HL10&"-"&HM10, Sheet2!$E:$F, 2, FALSE), "") | HT10: =IFERROR(VLOOKUP(HR10&"-"&HS10, Sheet2!$E:$F, 2, FALSE), "") | HX10: No | HY10: - | IE10: =IFERROR(VLOOKUP(IC10&"-"&ID10, Sheet2!$E:$F, 2, FALSE), "") | IK10: =IFERROR(VLOOKUP(II10&"-"&IJ10, Sheet2!$E:$F, 2, FALSE), "") | IR10: No | IS10: - | IY10: =IFERROR(VLOOKUP(IW10&"-"&IX10, Sheet2!$E:$F, 2, FALSE), "") | JG10: =IFERROR(VLOOKUP(JE10&"-"&JF10, Sheet2!$E:$F, 2, FALSE), "") | JM10: =IFERROR(VLOOKUP(JK10&"-"&JL10, Sheet2!$E:$F, 2, FALSE), "") | JQ10: No | JR10: - | JX10: =IFERROR(VLOOKUP(JV10&"-"&JW10, Sheet2!$E:$F, 2, FALSE), "") | KD10: =IFERROR(VLOOKUP(KB10&"-"&KC10, Sheet2!$E:$F, 2, FALSE), "") | KK10: No | KL10: - | KR10: =IFERROR(VLOOKUP(KP10&"-"&KQ10, Sheet2!$E:$F, 2, FALSE), "") | KZ10: =IFERROR(VLOOKUP(KX10&"-"&KY10, Sheet2!$E:$F, 2, FALSE), "") | LH10: =IFERROR(VLOOKUP(LF10&"-"&LG10, Sheet2!$E:$F, 2, FALSE), "") | LL10: No | LM10: - | LS10: =IFERROR(VLOOKUP(LQ10&"-"&LR10, Sheet2!$E:$F, 2, FALSE), "") | LY10: =IFERROR(VLOOKUP(LW10&"-"&LX10, Sheet2!$E:$F, 2, FALSE), "") | MD10: No | ME10: - | MK10: =IFERROR(VLOOKUP(MI10&"-"&MJ10, Sheet2!$E:$F, 2, FALSE), "") | MN10: No | MV10: =IFERROR(VLOOKUP(MT10&"-"&MU10, Sheet2!$E:$F, 2, FALSE), "") | NB10: =IFERROR(VLOOKUP(MZ10&"-"&NA10, Sheet2!$E:$F, 2, FALSE), "") | NF10: No | NG10: - | NM10: =IFERROR(VLOOKUP(NK10&"-"&NL10, Sheet2!$E:$F, 2, FALSE), "") | NS10: =IFERROR(VLOOKUP(NQ10&"-"&NR10, Sheet2!$E:$F, 2, FALSE), "") | NX10: No | NY10: - | OE10: =IFERROR(VLOOKUP(OC10&"-"&OD10, Sheet2!$E:$F, 2, FALSE), "") | OH10: No | OP10: =IFERROR(VLOOKUP(ON10&"-"&OO10, Sheet2!$E:$F, 2, FALSE), "") | OV10: =IFERROR(VLOOKUP(OT10&"-"&OU10, Sheet2!$E:$F, 2, FALSE), "") | OZ10: No | PA10: - | PG10: =IFERROR(VLOOKUP(PE10&"-"&PF10, Sheet2!$E:$F, 2, FALSE), "") | PM10: =IFERROR(VLOOKUP(PK10&"-"&PL10, Sheet2!$E:$F, 2, FALSE), "") | PR10: No | PS10: - | PY10: =IFERROR(VLOOKUP(PW10&"-"&PX10, Sheet2!$E:$F, 2, FALSE), "") | QB10: No | QJ10: =IFERROR(VLOOKUP(QH10&"-"&QI10, Sheet2!$E:$F, 2, FALSE), "") | QP10: =IFERROR(VLOOKUP(QN10&"-"&QO10, Sheet2!$E:$F, 2, FALSE), "") | QT10: No | QU10: - | RA10: =IFERROR(VLOOKUP(QY10&"-"&QZ10, Sheet2!$E:$F, 2, FALSE), "") | RG10: =IFERROR(VLOOKUP(RE10&"-"&RF10, Sheet2!$E:$F, 2, FALSE), "")
A11: Gigi | B11: Best-Richardson | C11: No | D11: - | E11: FL | F11: 100011 | G11: bradlcmuseum@gmail.com | H11: Founding Member | M11: =IFERROR(VLOOKUP(K11&"-"&L11, Sheet2!$E:$F, 2, FALSE), "") | N11: IL | O11: Norfolk | P11: 42.1603, -71.2118 | T11: No | AA11: =IFERROR(VLOOKUP(Y11&"-"&Z11, Sheet2!$E:$F, 2, FALSE), "") | AB11: MA | AL11: =IFERROR(VLOOKUP(AJ11&"-"&AK11, Sheet2!$E:$F, 2, FALSE), "") | AP11: No | AQ11: - | AV11: =IFERROR(VLOOKUP(AT11&"-"&AU11, Sheet2!$E:$F, 2, FALSE), "") | BD11: =IFERROR(VLOOKUP(BB11&"-"&BC11, Sheet2!$E:$F, 2, FALSE), "") | BJ11: No | BK11: - | BP11: =IFERROR(VLOOKUP(BN11&"-"&BO11, Sheet2!$E:$F, 2, FALSE), "") | BT11: No | CB11: =IFERROR(VLOOKUP(BZ11&"-"&CA11, Sheet2!$E:$F, 2, FALSE), "") | CH11: =IFERROR(VLOOKUP(CF11&"-"&CG11, Sheet2!$E:$F, 2, FALSE), "") | CL11: No | CM11: - | CR11: =IFERROR(VLOOKUP(CP11&"-"&CQ11, Sheet2!$E:$F, 2, FALSE), "") | CX11: =IFERROR(VLOOKUP(CV11&"-"&CW11, Sheet2!$E:$F, 2, FALSE), "") | DD11: No | DE11: - | DJ11: =IFERROR(VLOOKUP(DH11&"-"&DI11, Sheet2!$E:$F, 2, FALSE), "") | DM11: No | DU11: =IFERROR(VLOOKUP(DS11&"-"&DT11, Sheet2!$E:$F, 2, FALSE), "") | EA11: =IFERROR(VLOOKUP(DY11&"-"&DZ11, Sheet2!$E:$F, 2, FALSE), "") | ED11: No | EJ11: No | EK11: - | EQ11: =IFERROR(VLOOKUP(EO11&"-"&EP11, Sheet2!$E:$F, 2, FALSE), "") | EV11: =IFERROR(VLOOKUP(ET11&"-"&EU11, Sheet2!$E:$F, 2, FALSE), "") | FC11: No | FD11: - | FI11: =IFERROR(VLOOKUP(FG11&"-"&FH11, Sheet2!$E:$F, 2, FALSE), "") | FL11: No | FT11: =IFERROR(VLOOKUP(FR11&"-"&FS11, Sheet2!$E:$F, 2, FALSE), "") | FZ11: =IFERROR(VLOOKUP(FX11&"-"&FY11, Sheet2!$E:$F, 2, FALSE), "") | GD11: No | GE11: - | GJ11: =IFERROR(VLOOKUP(GH11&"-"&GI11, Sheet2!$E:$F, 2, FALSE), "") | GP11: =IFERROR(VLOOKUP(GN11&"-"&GO11, Sheet2!$E:$F, 2, FALSE), "") | GW11: No | GX11: - | HC11: =IFERROR(VLOOKUP(HA11&"-"&HB11, Sheet2!$E:$F, 2, FALSE), "") | HF11: No | HN11: =IFERROR(VLOOKUP(HL11&"-"&HM11, Sheet2!$E:$F, 2, FALSE), "") | HT11: =IFERROR(VLOOKUP(HR11&"-"&HS11, Sheet2!$E:$F, 2, FALSE), "") | HX11: No | HY11: - | IE11: =IFERROR(VLOOKUP(IC11&"-"&ID11, Sheet2!$E:$F, 2, FALSE), "") | IK11: =IFERROR(VLOOKUP(II11&"-"&IJ11, Sheet2!$E:$F, 2, FALSE), "") | IR11: No | IS11: - | IY11: =IFERROR(VLOOKUP(IW11&"-"&IX11, Sheet2!$E:$F, 2, FALSE), "") | JG11: =IFERROR(VLOOKUP(JE11&"-"&JF11, Sheet2!$E:$F, 2, FALSE), "") | JM11: =IFERROR(VLOOKUP(JK11&"-"&JL11, Sheet2!$E:$F, 2, FALSE), "") | JQ11: No | JR11: - | JX11: =IFERROR(VLOOKUP(JV11&"-"&JW11, Sheet2!$E:$F, 2, FALSE), "") | KD11: =IFERROR(VLOOKUP(KB11&"-"&KC11, Sheet2!$E:$F, 2, FALSE), "") | KK11: No | KL11: - | KR11: =IFERROR(VLOOKUP(KP11&"-"&KQ11, Sheet2!$E:$F, 2, FALSE), "") | KZ11: =IFERROR(VLOOKUP(KX11&"-"&KY11, Sheet2!$E:$F, 2, FALSE), "") | LH11: =IFERROR(VLOOKUP(LF11&"-"&LG11, Sheet2!$E:$F, 2, FALSE), "") | LL11: No | LM11: - | LS11: =IFERROR(VLOOKUP(LQ11&"-"&LR11, Sheet2!$E:$F, 2, FALSE), "") | LY11: =IFERROR(VLOOKUP(LW11&"-"&LX11, Sheet2!$E:$F, 2, FALSE), "") | MD11: No | ME11: - | MK11: =IFERROR(VLOOKUP(MI11&"-"&MJ11, Sheet2!$E:$F, 2, FALSE), "") | MN11: No | MV11: =IFERROR(VLOOKUP(MT11&"-"&MU11, Sheet2!$E:$F, 2, FALSE), "") | NB11: =IFERROR(VLOOKUP(MZ11&"-"&NA11, Sheet2!$E:$F, 2, FALSE), "") | NF11: No | NG11: - | NM11: =IFERROR(VLOOKUP(NK11&"-"&NL11, Sheet2!$E:$F, 2, FALSE), "") | NS11: =IFERROR(VLOOKUP(NQ11&"-"&NR11, Sheet2!$E:$F, 2, FALSE), "") | NX11: No | NY11: - | OE11: =IFERROR(VLOOKUP(OC11&"-"&OD11, Sheet2!$E:$F, 2, FALSE), "") | OH11: No | OP11: =IFERROR(VLOOKUP(ON11&"-"&OO11, Sheet2!$E:$F, 2, FALSE), "") | OV11: =IFERROR(VLOOKUP(OT11&"-"&OU11, Sheet2!$E:$F, 2, FALSE), "") | OZ11: No | PA11: - | PG11: =IFERROR(VLOOKUP(PE11&"-"&PF11, Sheet2!$E:$F, 2, FALSE), "") | PM11: =IFERROR(VLOOKUP(PK11&"-"&PL11, Sheet2!$E:$F, 2, FALSE), "") | PR11: No | PS11: - | PY11: =IFERROR(VLOOKUP(PW11&"-"&PX11, Sheet2!$E:$F, 2, FALSE), "") | QB11: No | QJ11: =IFERROR(VLOOKUP(QH11&"-"&QI11, Sheet2!$E:$F, 2, FALSE), "") | QP11: =IFERROR(VLOOKUP(QN11&"-"&QO11, Sheet2!$E:$F, 2, FALSE), "") | QT11: No | QU11: - | RA11: =IFERROR(VLOOKUP(QY11&"-"&QZ11, Sheet2!$E:$F, 2, FALSE), "") | RG11: =IFERROR(VLOOKUP(RE11&"-"&RF11, Sheet2!$E:$F, 2, FALSE), "")
